No shift: True
Running {'topology': 'E2', 'Lx': 1, 'Ly': 1, 'Lz': 1, 'x0': array([0., 0., 0.]), 'beta': 90, 'alpha': 90, 'gamma': 0, 'c_l_accuracy': 0.99, 'l_max': 20, 'do_polarization': False, 'A_s': 2e-09, 'n_s': 0.965, 'number_of_a_lm_realizations': 1}
Shape of transfer function from CAMB: (3, 169, 2853)

Finding k_max as a function of ell
  0%|          | 0/19 [00:00<?, ?it/s] 11%|█         | 2/19 [00:00<00:01, 15.84it/s] 26%|██▋       | 5/19 [00:00<00:00, 20.81it/s] 42%|████▏     | 8/19 [00:00<00:00, 22.44it/s] 58%|█████▊    | 11/19 [00:00<00:00, 23.20it/s] 74%|███████▎  | 14/19 [00:00<00:00, 23.65it/s] 89%|████████▉ | 17/19 [00:00<00:00, 23.94it/s]100%|██████████| 19/19 [00:00<00:00, 23.10it/s]
Done. k_max for TT ell_max = 0.02270755150739349 k_max for EE ell_max = 0.08519435485389171
Eigenmode 1: 198
Eigenmode 2: 4179528
E2 Final num of elements: 4179528 Minimum k_amp 0.0002272416186438812 n_x_max 200 n_z_max 400
Size of tilde xi: 127.55 MB.
Shape tilde xi: (4179528, 2) 

Time to get list of k, phi, theta: 4.654702663421631 seconds
Getting repeated theta and k elements
Ratio of unique theta: 0.14293049358683566
Ratio of unique |k|: 0.004380159673532513
Time to get unique k and theta: 1.0332512855529785 seconds

Getting transfer functions
  0%|          | 0/18307 [00:00<?, ?it/s]  1%|▏         | 264/18307 [00:00<00:07, 2564.88it/s]  3%|▎         | 528/18307 [00:00<00:07, 2509.72it/s]  5%|▍         | 840/18307 [00:00<00:06, 2731.39it/s]  6%|▌         | 1114/18307 [00:00<00:06, 2598.05it/s]  8%|▊         | 1392/18307 [00:00<00:06, 2629.81it/s]  9%|▉         | 1656/18307 [00:00<00:06, 2533.10it/s] 10%|█         | 1920/18307 [00:00<00:06, 2557.04it/s] 12%|█▏        | 2184/18307 [00:00<00:06, 2570.31it/s] 14%|█▎        | 2472/18307 [00:00<00:05, 2639.86it/s] 15%|█▌        | 2760/18307 [00:01<00:05, 2666.49it/s] 17%|█▋        | 3048/18307 [00:01<00:05, 2656.71it/s] 18%|█▊        | 3314/18307 [00:01<00:05, 2651.13it/s] 20%|█▉        | 3648/18307 [00:01<00:05, 2755.34it/s] 22%|██▏       | 3960/18307 [00:01<00:05, 2726.76it/s] 23%|██▎       | 4233/18307 [00:01<00:05, 2683.97it/s] 25%|██▍       | 4512/18307 [00:01<00:05, 2711.87it/s] 26%|██▋       | 4824/18307 [00:01<00:04, 2814.03it/s] 29%|██▊       | 5256/18307 [00:01<00:04, 3177.28it/s] 31%|███       | 5664/18307 [00:02<00:03, 3424.27it/s] 33%|███▎      | 6007/18307 [00:02<00:03, 3409.97it/s] 35%|███▍      | 6384/18307 [00:02<00:03, 3494.66it/s] 37%|███▋      | 6792/18307 [00:02<00:03, 3634.65it/s] 39%|███▉      | 7200/18307 [00:02<00:03, 3678.69it/s] 42%|████▏     | 7608/18307 [00:02<00:02, 3667.93it/s] 44%|████▍     | 8016/18307 [00:02<00:02, 3775.37it/s] 46%|████▌     | 8400/18307 [00:02<00:02, 3762.77it/s] 48%|████▊     | 8784/18307 [00:02<00:02, 3768.88it/s] 50%|█████     | 9168/18307 [00:02<00:02, 3768.78it/s] 52%|█████▏    | 9600/18307 [00:03<00:02, 3915.22it/s] 55%|█████▍    | 9992/18307 [00:03<00:02, 3843.70it/s] 57%|█████▋    | 10377/18307 [00:03<00:02, 3805.65it/s] 59%|█████▉    | 10776/18307 [00:03<00:02, 3746.03it/s] 61%|██████    | 11184/18307 [00:03<00:01, 3787.90it/s] 63%|██████▎   | 11592/18307 [00:03<00:01, 3850.10it/s] 66%|██████▌   | 12024/18307 [00:03<00:01, 3943.95it/s] 68%|██████▊   | 12419/18307 [00:03<00:01, 3882.36it/s] 70%|███████   | 12816/18307 [00:03<00:01, 3844.65it/s] 72%|███████▏  | 13201/18307 [00:03<00:01, 3780.34it/s] 74%|███████▍  | 13584/18307 [00:04<00:01, 3772.94it/s] 77%|███████▋  | 14040/18307 [00:04<00:01, 3877.30it/s] 79%|███████▉  | 14496/18307 [00:04<00:00, 4052.08it/s] 82%|████████▏ | 14952/18307 [00:04<00:00, 4186.09it/s] 84%|████████▍ | 15372/18307 [00:04<00:00, 3781.29it/s] 86%|████████▌ | 15758/18307 [00:04<00:00, 3762.75it/s] 88%|████████▊ | 16140/18307 [00:04<00:00, 3725.69it/s] 90%|█████████ | 16560/18307 [00:04<00:00, 3840.32it/s] 93%|█████████▎| 16947/18307 [00:04<00:00, 3773.73it/s] 95%|█████████▍| 17327/18307 [00:05<00:00, 3766.96it/s] 97%|█████████▋| 17736/18307 [00:05<00:00, 3849.65it/s] 99%|█████████▉| 18144/18307 [00:05<00:00, 3883.29it/s]100%|██████████| 18307/18307 [00:05<00:00, 3448.19it/s]
Size of transfer function: 2.93 MB. 

Size of integrand: 61.6 MB. Time to calculate integrand: 0.2691636085510254 s

Getting spherical harmonics
  0%|          | 0/597382 [00:00<?, ?it/s]  1%|          | 4668/597382 [00:00<00:17, 34332.34it/s]  1%|▏         | 8102/597382 [00:00<00:21, 27026.25it/s]  2%|▏         | 10838/597382 [00:00<00:24, 23785.01it/s]  2%|▏         | 13226/597382 [00:00<00:28, 20499.70it/s]  3%|▎         | 15560/597382 [00:00<00:29, 19801.75it/s]  3%|▎         | 17894/597382 [00:00<00:31, 18447.17it/s]  3%|▎         | 19746/597382 [00:00<00:31, 18335.95it/s]  4%|▎         | 21784/597382 [00:01<00:35, 16287.59it/s]  4%|▍         | 23442/597382 [00:01<00:36, 15820.29it/s]  4%|▍         | 25674/597382 [00:01<00:34, 16540.63it/s]  5%|▍         | 28008/597382 [00:01<00:31, 17869.73it/s]  5%|▌         | 30342/597382 [00:01<00:30, 18576.53it/s]  5%|▌         | 32676/597382 [00:01<00:31, 17680.81it/s]  6%|▌         | 35010/597382 [00:01<00:31, 18071.76it/s]  6%|▌         | 36836/597382 [00:01<00:31, 17567.87it/s]  6%|▋         | 38602/597382 [00:02<00:33, 16717.01it/s]  7%|▋         | 40279/597382 [00:02<00:33, 16556.91it/s]  7%|▋         | 41937/597382 [00:02<00:34, 16251.93it/s]  7%|▋         | 43568/597382 [00:02<00:36, 15157.30it/s]  8%|▊         | 45124/597382 [00:02<00:36, 15103.54it/s]  8%|▊         | 47458/597382 [00:02<00:37, 14701.61it/s]  8%|▊         | 49014/597382 [00:02<00:37, 14448.03it/s]  8%|▊         | 50570/597382 [00:02<00:40, 13583.04it/s]  9%|▊         | 52126/597382 [00:03<00:42, 12791.29it/s]  9%|▉         | 53682/597382 [00:03<00:42, 12931.76it/s]  9%|▉         | 55238/597382 [00:03<00:41, 12941.95it/s] 10%|▉         | 56794/597382 [00:03<00:41, 13076.03it/s] 10%|▉         | 58350/597382 [00:03<00:42, 12729.52it/s] 10%|█         | 59906/597382 [00:03<00:41, 13020.54it/s] 10%|█         | 61462/597382 [00:03<00:41, 12783.33it/s] 11%|█         | 63018/597382 [00:03<00:43, 12206.38it/s] 11%|█         | 64574/597382 [00:04<00:44, 12022.41it/s] 11%|█         | 66130/597382 [00:04<00:44, 12006.61it/s] 11%|█▏        | 67686/597382 [00:04<00:44, 11940.71it/s] 12%|█▏        | 70020/597382 [00:04<00:40, 12909.81it/s] 12%|█▏        | 71576/597382 [00:04<00:42, 12445.93it/s] 12%|█▏        | 73132/597382 [00:04<00:43, 12122.01it/s] 13%|█▎        | 74688/597382 [00:04<00:46, 11349.19it/s] 13%|█▎        | 76244/597382 [00:05<00:44, 11787.45it/s] 13%|█▎        | 77800/597382 [00:05<00:46, 11087.43it/s] 13%|█▎        | 80134/597382 [00:05<00:40, 12624.22it/s] 14%|█▎        | 81690/597382 [00:05<00:40, 12603.64it/s] 14%|█▍        | 83246/597382 [00:05<00:39, 13148.92it/s] 14%|█▍        | 84802/597382 [00:05<00:39, 12911.92it/s] 14%|█▍        | 86358/597382 [00:05<00:42, 12006.56it/s] 15%|█▍        | 87914/597382 [00:05<00:40, 12560.47it/s] 15%|█▍        | 89470/597382 [00:06<00:42, 12042.58it/s] 15%|█▌        | 91026/597382 [00:06<00:45, 11037.22it/s] 15%|█▌        | 92582/597382 [00:06<00:43, 11573.12it/s] 16%|█▌        | 94138/597382 [00:06<00:44, 11333.03it/s] 16%|█▌        | 95694/597382 [00:06<00:44, 11316.52it/s] 16%|█▋        | 97250/597382 [00:06<00:41, 12148.61it/s] 17%|█▋        | 98806/597382 [00:06<00:40, 12323.87it/s] 17%|█▋        | 101140/597382 [00:07<00:37, 13119.53it/s] 17%|█▋        | 102696/597382 [00:07<00:37, 13259.27it/s] 17%|█▋        | 104252/597382 [00:07<00:35, 13728.06it/s] 18%|█▊        | 105809/597382 [00:07<00:34, 14207.07it/s] 18%|█▊        | 107364/597382 [00:07<00:34, 14377.01it/s] 18%|█▊        | 108920/597382 [00:07<00:34, 14118.69it/s] 18%|█▊        | 110476/597382 [00:07<00:33, 14396.30it/s] 19%|█▉        | 112810/597382 [00:07<00:32, 14752.96it/s] 19%|█▉        | 115144/597382 [00:08<00:34, 14153.92it/s] 20%|█▉        | 117478/597382 [00:08<00:32, 14945.49it/s] 20%|█▉        | 119034/597382 [00:08<00:32, 14880.56it/s] 20%|██        | 120590/597382 [00:08<00:32, 14612.26it/s] 20%|██        | 122146/597382 [00:08<00:34, 13891.45it/s] 21%|██        | 123702/597382 [00:08<00:34, 13927.50it/s] 21%|██        | 125258/597382 [00:08<00:34, 13708.00it/s] 21%|██        | 126814/597382 [00:08<00:35, 13385.51it/s] 21%|██▏       | 128370/597382 [00:08<00:34, 13774.74it/s] 22%|██▏       | 129926/597382 [00:09<00:32, 14216.76it/s] 22%|██▏       | 131482/597382 [00:09<00:32, 14235.13it/s] 22%|██▏       | 133038/597382 [00:09<00:32, 14487.67it/s] 23%|██▎       | 134594/597382 [00:09<00:32, 14108.46it/s] 23%|██▎       | 136150/597382 [00:09<00:32, 14157.94it/s] 23%|██▎       | 137706/597382 [00:09<00:32, 14078.19it/s] 23%|██▎       | 140040/597382 [00:09<00:30, 15101.84it/s] 24%|██▎       | 141596/597382 [00:09<00:31, 14566.86it/s] 24%|██▍       | 143152/597382 [00:10<00:33, 13501.29it/s] 24%|██▍       | 145486/597382 [00:10<00:33, 13615.98it/s] 25%|██▍       | 147042/597382 [00:10<00:34, 13108.86it/s] 25%|██▍       | 148598/597382 [00:10<00:33, 13347.82it/s] 25%|██▌       | 150154/597382 [00:10<00:32, 13868.14it/s] 25%|██▌       | 151710/597382 [00:10<00:32, 13804.29it/s] 26%|██▌       | 153266/597382 [00:10<00:34, 12868.51it/s] 26%|██▌       | 154822/597382 [00:10<00:34, 12927.70it/s] 26%|██▌       | 156378/597382 [00:11<00:33, 12971.13it/s] 26%|██▋       | 157934/597382 [00:11<00:36, 12046.88it/s] 27%|██▋       | 159490/597382 [00:11<00:37, 11648.32it/s] 27%|██▋       | 161046/597382 [00:11<00:39, 10966.99it/s] 27%|██▋       | 162602/597382 [00:11<00:39, 11091.14it/s] 27%|██▋       | 164158/597382 [00:11<00:38, 11364.93it/s] 28%|██▊       | 166492/597382 [00:11<00:34, 12568.43it/s] 28%|██▊       | 168048/597382 [00:12<00:35, 12048.72it/s] 29%|██▊       | 170382/597382 [00:12<00:32, 13262.27it/s] 29%|██▉       | 171938/597382 [00:12<00:31, 13572.00it/s] 29%|██▉       | 173494/597382 [00:12<00:32, 13097.93it/s] 29%|██▉       | 175050/597382 [00:12<00:33, 12500.33it/s] 30%|██▉       | 176606/597382 [00:12<00:33, 12722.87it/s] 30%|██▉       | 178162/597382 [00:12<00:32, 12763.37it/s] 30%|███       | 179718/597382 [00:12<00:32, 12791.24it/s] 30%|███       | 181274/597382 [00:13<00:34, 11942.55it/s] 31%|███       | 183608/597382 [00:13<00:31, 13123.04it/s] 31%|███       | 185164/597382 [00:13<00:31, 13109.76it/s] 31%|███▏      | 186720/597382 [00:13<00:34, 11877.51it/s] 32%|███▏      | 188276/597382 [00:13<00:36, 11244.09it/s] 32%|███▏      | 189832/597382 [00:13<00:37, 10867.47it/s] 32%|███▏      | 191388/597382 [00:13<00:37, 10938.43it/s] 32%|███▏      | 192944/597382 [00:14<00:36, 11058.36it/s] 33%|███▎      | 194500/597382 [00:14<00:35, 11240.49it/s] 33%|███▎      | 196056/597382 [00:14<00:34, 11549.83it/s] 33%|███▎      | 198390/597382 [00:14<00:31, 12863.85it/s] 33%|███▎      | 199946/597382 [00:14<00:29, 13412.30it/s] 34%|███▎      | 201502/597382 [00:14<00:28, 13665.09it/s] 34%|███▍      | 203836/597382 [00:14<00:28, 13870.41it/s] 34%|███▍      | 205392/597382 [00:14<00:27, 14108.66it/s] 35%|███▍      | 206948/597382 [00:15<00:29, 13420.70it/s] 35%|███▌      | 209282/597382 [00:15<00:26, 14527.62it/s] 35%|███▌      | 210839/597382 [00:15<00:26, 14784.41it/s] 36%|███▌      | 212394/597382 [00:15<00:26, 14671.71it/s] 36%|███▌      | 214728/597382 [00:15<00:24, 15774.60it/s] 36%|███▌      | 216301/597382 [00:15<00:24, 15517.85it/s] 36%|███▋      | 217847/597382 [00:15<00:25, 14600.59it/s] 37%|███▋      | 219396/597382 [00:15<00:27, 13933.99it/s] 37%|███▋      | 220952/597382 [00:16<00:27, 13501.16it/s] 37%|███▋      | 223286/597382 [00:16<00:25, 14535.71it/s] 38%|███▊      | 224842/597382 [00:16<00:28, 13286.58it/s] 38%|███▊      | 226398/597382 [00:16<00:27, 13576.77it/s] 38%|███▊      | 227954/597382 [00:16<00:27, 13432.51it/s] 39%|███▊      | 230288/597382 [00:16<00:26, 13691.65it/s] 39%|███▉      | 231844/597382 [00:16<00:25, 14072.96it/s] 39%|███▉      | 233400/597382 [00:16<00:26, 13886.26it/s] 39%|███▉      | 234956/597382 [00:17<00:26, 13581.89it/s] 40%|███▉      | 236512/597382 [00:17<00:25, 13985.57it/s] 40%|███▉      | 238068/597382 [00:17<00:27, 12978.70it/s] 40%|████      | 239624/597382 [00:17<00:27, 12942.89it/s] 40%|████      | 241180/597382 [00:17<00:28, 12708.52it/s] 41%|████      | 242736/597382 [00:17<00:28, 12355.21it/s] 41%|████      | 244292/597382 [00:17<00:28, 12590.64it/s] 41%|████      | 245848/597382 [00:17<00:29, 11972.66it/s] 41%|████▏     | 247404/597382 [00:18<00:27, 12669.74it/s] 42%|████▏     | 249738/597382 [00:18<00:25, 13598.99it/s] 42%|████▏     | 251294/597382 [00:18<00:25, 13359.18it/s] 42%|████▏     | 252850/597382 [00:18<00:26, 13060.76it/s] 43%|████▎     | 254406/597382 [00:18<00:26, 12941.40it/s] 43%|████▎     | 255962/597382 [00:18<00:27, 12468.56it/s] 43%|████▎     | 257518/597382 [00:18<00:28, 11850.89it/s] 43%|████▎     | 259074/597382 [00:19<00:29, 11574.22it/s] 44%|████▎     | 260630/597382 [00:19<00:27, 12118.41it/s] 44%|████▍     | 262186/597382 [00:19<00:26, 12782.53it/s] 44%|████▍     | 263742/597382 [00:19<00:26, 12743.54it/s] 45%|████▍     | 266076/597382 [00:19<00:24, 13373.80it/s] 45%|████▍     | 267632/597382 [00:19<00:26, 12296.66it/s] 45%|████▌     | 269188/597382 [00:19<00:27, 12123.71it/s] 45%|████▌     | 270744/597382 [00:19<00:29, 11257.77it/s] 46%|████▌     | 272300/597382 [00:20<00:27, 11938.38it/s] 46%|████▌     | 273856/597382 [00:20<00:25, 12687.70it/s] 46%|████▌     | 275412/597382 [00:20<00:25, 12585.51it/s] 46%|████▋     | 276968/597382 [00:20<00:26, 11973.82it/s] 47%|████▋     | 279302/597382 [00:20<00:24, 13179.33it/s] 47%|████▋     | 280626/597382 [00:20<00:24, 13001.32it/s] 47%|████▋     | 282414/597382 [00:20<00:23, 13174.42it/s] 48%|████▊     | 284748/597382 [00:21<00:23, 13262.51it/s] 48%|████▊     | 287082/597382 [00:21<00:22, 14094.07it/s] 48%|████▊     | 288638/597382 [00:21<00:23, 13051.08it/s] 49%|████▊     | 290972/597382 [00:21<00:22, 13436.80it/s] 49%|████▉     | 292528/597382 [00:21<00:23, 12748.87it/s] 49%|████▉     | 294862/597382 [00:21<00:21, 13826.41it/s] 50%|████▉     | 296418/597382 [00:21<00:23, 12954.58it/s] 50%|████▉     | 297974/597382 [00:22<00:23, 12561.25it/s] 50%|█████     | 300308/597382 [00:22<00:20, 14837.83it/s] 51%|█████     | 301864/597382 [00:22<00:20, 14654.80it/s] 51%|█████     | 303420/597382 [00:22<00:20, 14479.70it/s] 51%|█████     | 304976/597382 [00:22<00:20, 14422.06it/s] 51%|█████▏    | 306532/597382 [00:22<00:20, 13872.19it/s] 52%|█████▏    | 308088/597382 [00:22<00:22, 13136.36it/s] 52%|█████▏    | 309644/597382 [00:22<00:22, 12592.17it/s] 52%|█████▏    | 311200/597382 [00:22<00:21, 13176.47it/s] 52%|█████▏    | 312756/597382 [00:23<00:22, 12519.84it/s] 53%|█████▎    | 315090/597382 [00:23<00:20, 13546.16it/s] 53%|█████▎    | 316646/597382 [00:23<00:20, 13768.59it/s] 53%|█████▎    | 318202/597382 [00:23<00:20, 13406.13it/s] 54%|█████▎    | 319758/597382 [00:23<00:20, 13246.89it/s] 54%|█████▍    | 321314/597382 [00:23<00:21, 13100.09it/s] 54%|█████▍    | 322870/597382 [00:23<00:21, 13026.07it/s] 54%|█████▍    | 325204/597382 [00:24<00:20, 13583.14it/s] 55%|█████▍    | 326760/597382 [00:24<00:21, 12484.38it/s] 55%|█████▌    | 329094/597382 [00:24<00:19, 14024.93it/s] 55%|█████▌    | 330650/597382 [00:24<00:19, 13581.26it/s] 56%|█████▌    | 332206/597382 [00:24<00:18, 13962.07it/s] 56%|█████▌    | 333762/597382 [00:24<00:18, 14117.57it/s] 56%|█████▌    | 335318/597382 [00:24<00:20, 12865.12it/s] 56%|█████▋    | 336874/597382 [00:24<00:21, 12362.23it/s] 57%|█████▋    | 338430/597382 [00:25<00:20, 12563.50it/s] 57%|█████▋    | 340764/597382 [00:25<00:19, 13242.16it/s] 57%|█████▋    | 342320/597382 [00:25<00:20, 12434.27it/s] 58%|█████▊    | 343876/597382 [00:25<00:19, 13038.52it/s] 58%|█████▊    | 345432/597382 [00:25<00:19, 12901.08it/s] 58%|█████▊    | 346988/597382 [00:25<00:22, 11042.75it/s] 58%|█████▊    | 348544/597382 [00:25<00:21, 11797.54it/s] 59%|█████▊    | 350100/597382 [00:25<00:20, 12317.37it/s] 59%|█████▉    | 351656/597382 [00:26<00:19, 12592.92it/s] 59%|█████▉    | 353212/597382 [00:26<00:19, 12430.01it/s] 59%|█████▉    | 354768/597382 [00:26<00:20, 11816.48it/s] 60%|█████▉    | 356324/597382 [00:26<00:20, 11727.81it/s] 60%|█████▉    | 357880/597382 [00:26<00:21, 11395.33it/s] 60%|██████    | 359436/597382 [00:26<00:21, 11131.67it/s] 60%|██████    | 360992/597382 [00:26<00:19, 12028.29it/s] 61%|██████    | 362548/597382 [00:27<00:19, 12037.93it/s] 61%|██████    | 364104/597382 [00:27<00:20, 11614.05it/s] 61%|██████    | 365660/597382 [00:27<00:19, 12044.90it/s] 61%|██████▏   | 367216/597382 [00:27<00:20, 11168.56it/s] 62%|██████▏   | 369550/597382 [00:27<00:18, 11998.84it/s] 62%|██████▏   | 371106/597382 [00:27<00:18, 12514.47it/s] 62%|██████▏   | 372662/597382 [00:27<00:17, 12695.31it/s] 63%|██████▎   | 374218/597382 [00:27<00:16, 13237.01it/s] 63%|██████▎   | 375774/597382 [00:28<00:18, 12050.31it/s] 63%|██████▎   | 377330/597382 [00:28<00:17, 12855.87it/s] 63%|██████▎   | 378886/597382 [00:28<00:17, 12764.33it/s] 64%|██████▎   | 380442/597382 [00:28<00:17, 12761.01it/s] 64%|██████▍   | 382776/597382 [00:28<00:15, 13595.18it/s] 64%|██████▍   | 384332/597382 [00:28<00:16, 12967.02it/s] 65%|██████▍   | 385888/597382 [00:28<00:16, 13211.71it/s] 65%|██████▍   | 387444/597382 [00:29<00:16, 12954.66it/s] 65%|██████▌   | 389000/597382 [00:29<00:15, 13579.06it/s] 65%|██████▌   | 390556/597382 [00:29<00:15, 13428.27it/s] 66%|██████▌   | 392112/597382 [00:29<00:15, 13288.99it/s] 66%|██████▌   | 393668/597382 [00:29<00:15, 13060.51it/s] 66%|██████▌   | 395224/597382 [00:29<00:15, 13364.10it/s] 66%|██████▋   | 396780/597382 [00:29<00:15, 12885.51it/s] 67%|██████▋   | 398336/597382 [00:29<00:14, 13408.19it/s] 67%|██████▋   | 400670/597382 [00:29<00:13, 14623.04it/s] 67%|██████▋   | 402226/597382 [00:30<00:13, 14030.63it/s] 68%|██████▊   | 403782/597382 [00:30<00:14, 13583.44it/s] 68%|██████▊   | 405338/597382 [00:30<00:14, 13110.72it/s] 68%|██████▊   | 406894/597382 [00:30<00:14, 13230.14it/s] 68%|██████▊   | 408450/597382 [00:30<00:15, 12591.65it/s] 69%|██████▊   | 410006/597382 [00:30<00:14, 13242.11it/s] 69%|██████▉   | 412340/597382 [00:30<00:13, 13794.82it/s] 69%|██████▉   | 414674/597382 [00:30<00:12, 15069.46it/s] 70%|██████▉   | 416230/597382 [00:31<00:12, 14475.35it/s] 70%|██████▉   | 417786/597382 [00:31<00:12, 14351.18it/s] 70%|███████   | 419342/597382 [00:31<00:12, 14222.49it/s] 70%|███████   | 420898/597382 [00:31<00:13, 13471.85it/s] 71%|███████   | 422454/597382 [00:31<00:13, 13421.96it/s] 71%|███████   | 424010/597382 [00:31<00:12, 13555.92it/s] 71%|███████   | 425566/597382 [00:31<00:12, 13618.81it/s] 71%|███████▏  | 427122/597382 [00:31<00:13, 12911.58it/s] 72%|███████▏  | 428678/597382 [00:32<00:12, 13543.38it/s] 72%|███████▏  | 430234/597382 [00:32<00:13, 12746.66it/s] 72%|███████▏  | 431790/597382 [00:32<00:12, 13101.85it/s] 73%|███████▎  | 433346/597382 [00:32<00:12, 12678.87it/s] 73%|███████▎  | 434902/597382 [00:32<00:13, 12458.51it/s] 73%|███████▎  | 436458/597382 [00:32<00:12, 13016.83it/s] 73%|███████▎  | 438014/597382 [00:32<00:12, 13200.03it/s] 74%|███████▎  | 439570/597382 [00:32<00:12, 12995.00it/s] 74%|███████▍  | 441126/597382 [00:33<00:11, 13087.99it/s] 74%|███████▍  | 442682/597382 [00:33<00:11, 13183.79it/s] 74%|███████▍  | 444238/597382 [00:33<00:11, 13118.26it/s] 75%|███████▍  | 445794/597382 [00:33<00:11, 13375.95it/s] 75%|███████▍  | 447350/597382 [00:33<00:11, 12824.54it/s] 75%|███████▌  | 448906/597382 [00:33<00:10, 13537.56it/s] 75%|███████▌  | 450462/597382 [00:33<00:10, 13642.38it/s] 76%|███████▌  | 452018/597382 [00:33<00:11, 13127.79it/s] 76%|███████▌  | 453574/597382 [00:33<00:10, 13452.11it/s] 76%|███████▌  | 455130/597382 [00:34<00:11, 12905.21it/s] 76%|███████▋  | 456686/597382 [00:34<00:10, 13254.64it/s] 77%|███████▋  | 458242/597382 [00:34<00:10, 13724.72it/s] 77%|███████▋  | 459798/597382 [00:34<00:10, 13630.15it/s] 77%|███████▋  | 461354/597382 [00:34<00:10, 13277.02it/s] 77%|███████▋  | 462910/597382 [00:34<00:11, 12056.05it/s] 78%|███████▊  | 464466/597382 [00:34<00:10, 12689.08it/s] 78%|███████▊  | 466022/597382 [00:34<00:09, 13307.20it/s] 78%|███████▊  | 467578/597382 [00:35<00:10, 12600.11it/s] 79%|███████▊  | 469134/597382 [00:35<00:10, 12739.63it/s] 79%|███████▉  | 470690/597382 [00:35<00:09, 13301.59it/s] 79%|███████▉  | 472246/597382 [00:35<00:09, 12968.46it/s] 79%|███████▉  | 473802/597382 [00:35<00:09, 12498.97it/s] 80%|███████▉  | 476136/597382 [00:35<00:08, 13541.43it/s] 80%|███████▉  | 477692/597382 [00:35<00:09, 12211.08it/s] 80%|████████  | 480026/597382 [00:35<00:08, 13150.40it/s] 81%|████████  | 481582/597382 [00:36<00:08, 13103.95it/s] 81%|████████  | 483916/597382 [00:36<00:08, 13626.56it/s] 81%|████████▏ | 485472/597382 [00:36<00:08, 13816.66it/s] 82%|████████▏ | 487028/597382 [00:36<00:08, 12750.36it/s] 82%|████████▏ | 488584/597382 [00:36<00:08, 12358.69it/s] 82%|████████▏ | 490140/597382 [00:36<00:09, 11904.72it/s] 82%|████████▏ | 491696/597382 [00:36<00:08, 12647.06it/s] 83%|████████▎ | 493253/597382 [00:36<00:07, 13377.82it/s] 83%|████████▎ | 494808/597382 [00:37<00:07, 13353.20it/s] 83%|████████▎ | 496364/597382 [00:37<00:07, 12725.65it/s] 83%|████████▎ | 497920/597382 [00:37<00:07, 12858.62it/s] 84%|████████▎ | 500254/597382 [00:37<00:07, 13789.82it/s] 84%|████████▍ | 501810/597382 [00:37<00:06, 13683.89it/s] 84%|████████▍ | 503366/597382 [00:37<00:06, 13846.40it/s] 85%|████████▍ | 504922/597382 [00:37<00:06, 13617.09it/s] 85%|████████▍ | 506478/597382 [00:37<00:06, 13000.71it/s] 85%|████████▌ | 508034/597382 [00:38<00:07, 12710.27it/s] 85%|████████▌ | 509590/597382 [00:38<00:06, 12943.61it/s] 86%|████████▌ | 511146/597382 [00:38<00:06, 13211.06it/s] 86%|████████▌ | 512702/597382 [00:38<00:06, 12132.79it/s] 86%|████████▌ | 514258/597382 [00:38<00:07, 11730.45it/s] 86%|████████▋ | 515814/597382 [00:38<00:06, 12187.41it/s] 87%|████████▋ | 517050/597382 [00:38<00:06, 12011.09it/s] 87%|████████▋ | 518926/597382 [00:39<00:06, 12596.56it/s] 87%|████████▋ | 520482/597382 [00:39<00:06, 12288.57it/s] 88%|████████▊ | 522816/597382 [00:39<00:05, 13232.26it/s] 88%|████████▊ | 524372/597382 [00:39<00:05, 13070.64it/s] 88%|████████▊ | 525928/597382 [00:39<00:05, 12861.75it/s] 88%|████████▊ | 527484/597382 [00:39<00:05, 12771.05it/s] 89%|████████▊ | 529040/597382 [00:39<00:05, 12857.21it/s] 89%|████████▉ | 530596/597382 [00:39<00:04, 13375.06it/s] 89%|████████▉ | 532930/597382 [00:40<00:04, 13527.40it/s] 89%|████████▉ | 534486/597382 [00:40<00:04, 13262.82it/s] 90%|████████▉ | 536820/597382 [00:40<00:04, 13806.04it/s] 90%|█████████ | 538376/597382 [00:40<00:04, 13934.72it/s] 91%|█████████ | 540710/597382 [00:40<00:03, 14500.92it/s] 91%|█████████ | 543044/597382 [00:40<00:03, 15604.35it/s] 91%|█████████▏| 545378/597382 [00:40<00:03, 15971.83it/s] 92%|█████████▏| 546975/597382 [00:40<00:03, 15095.33it/s] 92%|█████████▏| 548479/597382 [00:41<00:03, 14129.20it/s] 92%|█████████▏| 549886/597382 [00:41<00:03, 13745.27it/s] 92%|█████████▏| 551252/597382 [00:41<00:03, 13486.03it/s] 93%|█████████▎| 552803/597382 [00:41<00:03, 14020.83it/s] 93%|█████████▎| 554206/597382 [00:41<00:03, 13507.48it/s] 93%|█████████▎| 555558/597382 [00:41<00:03, 11635.87it/s] 93%|█████████▎| 557048/597382 [00:41<00:03, 11804.92it/s] 94%|█████████▎| 558604/597382 [00:41<00:03, 12261.47it/s] 94%|█████████▍| 560160/597382 [00:42<00:02, 12946.72it/s] 94%|█████████▍| 561716/597382 [00:42<00:02, 12298.17it/s] 94%|█████████▍| 563272/597382 [00:42<00:02, 11562.11it/s] 95%|█████████▍| 564828/597382 [00:42<00:02, 11349.25it/s] 95%|█████████▍| 566384/597382 [00:42<00:02, 10873.04it/s] 95%|█████████▌| 567940/597382 [00:42<00:02, 11230.06it/s] 95%|█████████▌| 569496/597382 [00:42<00:02, 11268.53it/s] 96%|█████████▌| 571052/597382 [00:43<00:02, 11394.75it/s] 96%|█████████▌| 573386/597382 [00:43<00:01, 12595.63it/s] 96%|█████████▌| 574942/597382 [00:43<00:01, 13220.72it/s] 97%|█████████▋| 576498/597382 [00:43<00:01, 13733.91it/s] 97%|█████████▋| 578054/597382 [00:43<00:01, 13573.14it/s] 97%|█████████▋| 579610/597382 [00:43<00:01, 13002.60it/s] 97%|█████████▋| 581944/597382 [00:43<00:01, 12857.69it/s] 98%|█████████▊| 584278/597382 [00:43<00:00, 13924.14it/s] 98%|█████████▊| 585834/597382 [00:44<00:00, 14011.82it/s] 98%|█████████▊| 587391/597382 [00:44<00:00, 14392.70it/s] 99%|█████████▊| 589724/597382 [00:44<00:00, 14331.73it/s] 99%|█████████▉| 592058/597382 [00:44<00:00, 14571.44it/s] 99%|█████████▉| 594392/597382 [00:44<00:00, 14880.90it/s]100%|█████████▉| 596726/597382 [00:44<00:00, 15122.68it/s]100%|██████████| 597382/597382 [00:44<00:00, 13332.67it/s]
The spherical harmonics array is 526.41 MB 


**************
Done with all preprocessing
**************

Time to pre-process with l_max=20 and accuracy=0.99: 70.25538110733032 seconds

***********
Calculating a_lm realizations
***********

  0%|          | 0/1 [00:00<?, ?it/s]100%|██████████| 1/1 [00:09<00:00,  9.38s/it]100%|██████████| 1/1 [00:09<00:00,  9.38s/it]

Calculating covariance matrix
  0%|          | 0/4179528 [00:00<?, ?it/s]  0%|          | 0/4179528 [00:00<?, ?it/s]Only calculating diagonal
  0%|          | 0/4179528 [00:00<?, ?it/s]  0%|          | 0/4179528 [00:00<?, ?it/s]  0%|          | 0/4179528 [00:00<?, ?it/s]  0%|          | 0/4179528 [00:00<?, ?it/s]  0%|          | 0/4179528 [00:00<?, ?it/s]  0%|          | 0/4179528 [00:00<?, ?it/s]  1%|▏         | 55580/4179528 [00:00<01:12, 56633.06it/s]  2%|▏         | 101976/4179528 [00:01<00:43, 94234.81it/s]  3%|▎         | 145679/4179528 [00:01<00:32, 123152.73it/s]  4%|▍         | 187119/4179528 [00:01<00:27, 145775.76it/s]  5%|▌         | 228188/4179528 [00:01<00:23, 164835.45it/s]  6%|▋         | 266054/4179528 [00:01<00:21, 179155.84it/s]  7%|▋         | 307228/4179528 [00:01<00:19, 193753.03it/s]  8%|▊         | 344076/4179528 [00:01<00:18, 204038.32it/s]  9%|▉         | 377640/4179528 [00:01<00:17, 211321.35it/s] 10%|▉         | 411270/4179528 [00:01<00:17, 217862.55it/s] 11%|█         | 445401/4179528 [00:01<00:16, 223991.21it/s] 11%|█▏        | 478821/4179528 [00:02<00:16, 229188.53it/s] 12%|█▏        | 510320/4179528 [00:02<00:15, 233031.10it/s] 13%|█▎        | 543300/4179528 [00:02<00:15, 237183.92it/s] 14%|█▎        | 574052/4179528 [00:02<00:15, 240052.83it/s] 14%|█▍        | 604444/4179528 [00:02<00:14, 242547.87it/s] 15%|█▌        | 636917/4179528 [00:02<00:14, 245649.29it/s] 16%|█▌        | 666333/4179528 [00:02<00:14, 247386.15it/s] 17%|█▋        | 696013/4179528 [00:02<00:13, 249090.20it/s] 17%|█▋        | 726545/4179528 [00:02<00:13, 250970.17it/s] 18%|█▊        | 757055/4179528 [00:02<00:13, 252717.90it/s] 19%|█▉        | 785551/4179528 [00:03<00:13, 253700.23it/s] 19%|█▉        | 814143/4179528 [00:03<00:13, 254652.45it/s] 20%|██        | 842822/4179528 [00:03<00:13, 255568.71it/s] 21%|██        | 871440/4179528 [00:03<00:12, 256416.80it/s] 22%|██▏       | 900285/4179528 [00:03<00:12, 257279.33it/s] 22%|██▏       | 929322/4179528 [00:03<00:12, 258146.75it/s] 23%|██▎       | 958320/4179528 [00:03<00:12, 258958.08it/s] 24%|██▎       | 987668/4179528 [00:03<00:12, 259817.42it/s] 24%|██▍       | 1015714/4179528 [00:03<00:12, 260299.57it/s] 25%|██▍       | 1043545/4179528 [00:04<00:12, 260703.00it/s] 26%|██▌       | 1071398/4179528 [00:04<00:11, 261093.09it/s] 26%|██▋       | 1098955/4179528 [00:04<00:11, 261394.01it/s] 27%|██▋       | 1126702/4179528 [00:04<00:11, 261723.49it/s] 28%|██▊       | 1154310/4179528 [00:04<00:11, 262009.68it/s] 28%|██▊       | 1181912/4179528 [00:04<00:11, 262278.81it/s] 29%|██▉       | 1208353/4179528 [00:04<00:11, 262284.99it/s] 30%|██▉       | 1234763/4179528 [00:04<00:11, 262284.26it/s] 30%|███       | 1261613/4179528 [00:04<00:11, 262374.02it/s] 31%|███       | 1288369/4179528 [00:04<00:11, 262440.92it/s] 31%|███▏      | 1315377/4179528 [00:05<00:10, 262554.05it/s] 32%|███▏      | 1342312/4179528 [00:05<00:10, 262651.95it/s] 33%|███▎      | 1369518/4179528 [00:05<00:10, 262795.42it/s] 33%|███▎      | 1396262/4179528 [00:05<00:10, 262848.01it/s] 34%|███▍      | 1423291/4179528 [00:05<00:10, 262952.50it/s] 35%|███▍      | 1450346/4179528 [00:05<00:10, 263055.70it/s] 35%|███▌      | 1477489/4179528 [00:05<00:10, 263170.73it/s] 36%|███▌      | 1504687/4179528 [00:05<00:10, 263292.92it/s] 37%|███▋      | 1529052/4179528 [00:05<00:10, 262923.10it/s] 37%|███▋      | 1555070/4179528 [00:05<00:09, 262844.56it/s] 38%|███▊      | 1581664/4179528 [00:06<00:09, 262865.38it/s] 38%|███▊      | 1608381/4179528 [00:06<00:09, 262905.55it/s] 39%|███▉      | 1635218/4179528 [00:06<00:09, 262962.84it/s] 40%|███▉      | 1662105/4179528 [00:06<00:09, 263025.82it/s] 40%|████      | 1689153/4179528 [00:06<00:09, 263113.40it/s] 41%|████      | 1714267/4179528 [00:06<00:09, 262901.55it/s] 42%|████▏     | 1739417/4179528 [00:06<00:09, 262700.42it/s] 42%|████▏     | 1765538/4179528 [00:06<00:09, 262649.95it/s] 43%|████▎     | 1792047/4179528 [00:06<00:09, 262658.59it/s] 43%|████▎     | 1817723/4179528 [00:06<00:08, 262531.82it/s] 44%|████▍     | 1844623/4179528 [00:07<00:08, 262590.61it/s] 45%|████▍     | 1870203/4179528 [00:07<00:08, 262468.60it/s] 45%|████▌     | 1894878/4179528 [00:07<00:08, 262222.90it/s] 46%|████▌     | 1920816/4179528 [00:07<00:08, 262158.44it/s] 47%|████▋     | 1947181/4179528 [00:07<00:08, 262154.77it/s] 47%|████▋     | 1973918/4179528 [00:07<00:08, 262198.98it/s] 48%|████▊     | 2000635/4179528 [00:07<00:08, 262239.79it/s] 48%|████▊     | 2026828/4179528 [00:07<00:08, 262211.79it/s] 49%|████▉     | 2050511/4179528 [00:07<00:08, 261863.47it/s] 50%|████▉     | 2077347/4179528 [00:07<00:08, 261921.44it/s] 50%|█████     | 2103859/4179528 [00:08<00:07, 261938.57it/s] 51%|█████     | 2130626/4179528 [00:08<00:07, 261986.58it/s] 52%|█████▏    | 2157330/4179528 [00:08<00:07, 262025.27it/s] 52%|█████▏    | 2183411/4179528 [00:08<00:07, 261987.13it/s] 53%|█████▎    | 2207470/4179528 [00:08<00:07, 261712.21it/s] 53%|█████▎    | 2233486/4179528 [00:08<00:07, 261672.01it/s] 54%|█████▍    | 2259967/4179528 [00:08<00:07, 261686.32it/s] 55%|█████▍    | 2286172/4179528 [00:08<00:07, 261665.06it/s] 55%|█████▌    | 2313116/4179528 [00:08<00:07, 261731.32it/s] 56%|█████▌    | 2337903/4179528 [00:08<00:07, 261555.22it/s] 57%|█████▋    | 2363096/4179528 [00:09<00:06, 261427.81it/s] 57%|█████▋    | 2389335/4179528 [00:09<00:06, 261418.00it/s] 58%|█████▊    | 2415859/4179528 [00:09<00:06, 261439.55it/s] 58%|█████▊    | 2442758/4179528 [00:09<00:06, 261500.29it/s] 59%|█████▉    | 2469757/4179528 [00:09<00:06, 261571.00it/s] 60%|█████▉    | 2495107/4179528 [00:09<00:06, 261467.24it/s] 60%|██████    | 2520088/4179528 [00:09<00:06, 261326.22it/s] 61%|██████    | 2546286/4179528 [00:09<00:06, 261313.59it/s] 62%|██████▏   | 2572921/4179528 [00:09<00:06, 261345.47it/s] 62%|██████▏   | 2599877/4179528 [00:09<00:06, 261409.76it/s] 63%|██████▎   | 2626937/4179528 [00:10<00:05, 261482.04it/s] 64%|██████▎   | 2654124/4179528 [00:10<00:05, 261566.41it/s] 64%|██████▍   | 2680061/4179528 [00:10<00:05, 261527.15it/s] 65%|██████▍   | 2705164/4179528 [00:10<00:05, 261407.07it/s] 65%|██████▌   | 2730787/4179528 [00:10<00:05, 261339.66it/s] 66%|██████▌   | 2757670/4179528 [00:10<00:05, 261392.79it/s] 67%|██████▋   | 2784728/4179528 [00:10<00:05, 261460.98it/s] 67%|██████▋   | 2811828/4179528 [00:10<00:05, 261532.98it/s] 68%|██████▊   | 2839231/4179528 [00:10<00:05, 261631.33it/s] 69%|██████▊   | 2866563/4179528 [00:10<00:05, 261721.50it/s] 69%|██████▉   | 2894020/4179528 [00:11<00:04, 261820.79it/s] 70%|██████▉   | 2921596/4179528 [00:11<00:04, 261928.91it/s] 71%|███████   | 2948343/4179528 [00:11<00:04, 261961.40it/s] 71%|███████   | 2974516/4179528 [00:11<00:04, 261943.28it/s] 72%|███████▏  | 3001507/4179528 [00:11<00:04, 261996.46it/s] 72%|███████▏  | 3028657/4179528 [00:11<00:04, 262062.41it/s] 73%|███████▎  | 3056001/4179528 [00:11<00:04, 262144.54it/s] 74%|███████▍  | 3083633/4179528 [00:11<00:04, 262249.63it/s] 74%|███████▍  | 3111181/4179528 [00:11<00:04, 262346.29it/s] 75%|███████▌  | 3139168/4179528 [00:11<00:03, 262477.57it/s] 76%|███████▌  | 3166938/4179528 [00:12<00:03, 262588.81it/s] 76%|███████▋  | 3195084/4179528 [00:12<00:03, 262728.60it/s] 77%|███████▋  | 3223436/4179528 [00:12<00:03, 262881.66it/s] 78%|███████▊  | 3252297/4179528 [00:12<00:03, 263075.47it/s] 79%|███████▊  | 3282699/4179528 [00:12<00:03, 263388.98it/s] 79%|███████▉  | 3311132/4179528 [00:12<00:03, 263540.57it/s] 80%|███████▉  | 3339502/4179528 [00:12<00:03, 263685.42it/s] 81%|████████  | 3367955/4179528 [00:12<00:03, 263833.88it/s] 81%|████████▏ | 3396719/4179528 [00:12<00:02, 264004.87it/s] 82%|████████▏ | 3425809/4179528 [00:12<00:02, 264197.67it/s] 83%|████████▎ | 3455726/4179528 [00:13<00:02, 264451.27it/s] 83%|████████▎ | 3487129/4179528 [00:13<00:02, 264813.34it/s] 84%|████████▍ | 3516369/4179528 [00:13<00:02, 265006.27it/s] 85%|████████▍ | 3546062/4179528 [00:13<00:02, 265231.66it/s] 86%|████████▌ | 3578310/4179528 [00:13<00:02, 265642.78it/s] 86%|████████▋ | 3608682/4179528 [00:13<00:02, 265909.80it/s] 87%|████████▋ | 3639398/4179528 [00:13<00:02, 266197.57it/s] 88%|████████▊ | 3671373/4179528 [00:13<00:01, 266573.10it/s] 89%|████████▊ | 3702548/4179528 [00:13<00:01, 266884.94it/s] 89%|████████▉ | 3736487/4179528 [00:13<00:01, 267390.18it/s] 90%|█████████ | 3770985/4179528 [00:14<00:01, 267928.37it/s] 91%|█████████ | 3803669/4179528 [00:14<00:01, 268330.33it/s] 92%|█████████▏| 3838898/4179528 [00:14<00:01, 268905.49it/s] 93%|█████████▎| 3875343/4179528 [00:14<00:01, 269557.02it/s] 94%|█████████▎| 3913537/4179528 [00:14<00:00, 270319.98it/s] 95%|█████████▍| 3952272/4179528 [00:14<00:00, 271109.46it/s] 96%|█████████▌| 3993518/4179528 [00:14<00:00, 272059.18it/s] 97%|█████████▋| 4036802/4179528 [00:14<00:00, 273134.33it/s] 98%|█████████▊| 4084171/4179528 [00:14<00:00, 274468.99it/s] 99%|█████████▉| 4140037/4179528 [00:14<00:00, 276353.01it/s]100%|██████████| 4179528/4179528 [00:15<00:00, 277981.23it/s]100%|██████████| 4179528/4179528 [00:15<00:00, 277975.36it/s]100%|██████████| 4179528/4179528 [00:15<00:00, 277972.61it/s]
Time to calculate C_TT with l_max=20 and c_l_ratio=0.99: 15.036242008209229 seconds with Numba
Power spectrum ratio: [0.98904003 0.83184344 1.15740724 0.85344566 1.17205968 0.88846893
 1.10081814 0.90474459 1.0687135  0.9178147  1.05698221 0.9277409
 1.04798041 0.93582104 1.04071935 0.94247137 1.03452208 0.94815389
 1.0293106 ]

Calculating covariance matrix
  0%|          | 0/1 [00:00<?, ?it/s]100%|██████████| 1/1 [01:04<00:00, 64.32s/it]100%|██████████| 1/1 [01:04<00:00, 64.33s/it]
Calculating KL divergence

Calculating covariance matrix
Process Process-1001:
Process Process-1012:
Process Process-1007:
Process Process-1024:
Process Process-999:
Process Process-1003:
Process Process-1010:
Process Process-998:
Process Process-1006:
Process Process-1011:
Process Process-997:
Process Process-1004:
Process Process-1015:
Traceback (most recent call last):
Traceback (most recent call last):
  File "/home/conda/envs/topology/lib/python3.10/multiprocessing/process.py", line 314, in _bootstrap
    self.run()
  File "/home/conda/envs/topology/lib/python3.10/multiprocessing/process.py", line 108, in run
    self._target(*self._args, **self._kwargs)
  File "/home/jnoltmann/topology/src/E2.py", line 136, in get_c_lmlpmp_per_process
    return_dict[process_i] = E2_E3_E4_E5_get_c_lmlpmp(
  File "<string>", line 2, in __setitem__
  File "/home/conda/envs/topology/lib/python3.10/multiprocessing/managers.py", line 818, in _callmethod
    kind, result = conn.recv()
  File "/home/conda/envs/topology/lib/python3.10/multiprocessing/connection.py", line 250, in recv
    buf = self._recv_bytes()
  File "/home/conda/envs/topology/lib/python3.10/multiprocessing/connection.py", line 414, in _recv_bytes
    buf = self._recv(4)
  File "/home/conda/envs/topology/lib/python3.10/multiprocessing/connection.py", line 383, in _recv
    raise EOFError
EOFError
  File "/home/conda/envs/topology/lib/python3.10/multiprocessing/process.py", line 314, in _bootstrap
    self.run()
  File "/home/conda/envs/topology/lib/python3.10/multiprocessing/process.py", line 108, in run
    self._target(*self._args, **self._kwargs)
  File "/home/jnoltmann/topology/src/E2.py", line 136, in get_c_lmlpmp_per_process
    return_dict[process_i] = E2_E3_E4_E5_get_c_lmlpmp(
  File "<string>", line 2, in __setitem__
  File "/home/conda/envs/topology/lib/python3.10/multiprocessing/managers.py", line 817, in _callmethod
    conn.send((self._id, methodname, args, kwds))
  File "/home/conda/envs/topology/lib/python3.10/multiprocessing/connection.py", line 206, in send
    self._send_bytes(_ForkingPickler.dumps(obj))
  File "/home/conda/envs/topology/lib/python3.10/multiprocessing/connection.py", line 405, in _send_bytes
    self._send(buf)
  File "/home/conda/envs/topology/lib/python3.10/multiprocessing/connection.py", line 368, in _send
    n = write(self._handle, buf)
BrokenPipeError: [Errno 32] Broken pipe
Traceback (most recent call last):
  File "/home/conda/envs/topology/lib/python3.10/multiprocessing/managers.py", line 810, in _callmethod
    conn = self._tls.connection
AttributeError: 'ForkAwareLocal' object has no attribute 'connection'

During handling of the above exception, another exception occurred:

Traceback (most recent call last):
  File "/home/conda/envs/topology/lib/python3.10/multiprocessing/process.py", line 314, in _bootstrap
    self.run()
  File "/home/conda/envs/topology/lib/python3.10/multiprocessing/process.py", line 108, in run
    self._target(*self._args, **self._kwargs)
  File "/home/jnoltmann/topology/src/E2.py", line 136, in get_c_lmlpmp_per_process
    return_dict[process_i] = E2_E3_E4_E5_get_c_lmlpmp(
  File "<string>", line 2, in __setitem__
  File "/home/conda/envs/topology/lib/python3.10/multiprocessing/managers.py", line 814, in _callmethod
    self._connect()
  File "/home/conda/envs/topology/lib/python3.10/multiprocessing/managers.py", line 801, in _connect
    conn = self._Client(self._token.address, authkey=self._authkey)
  File "/home/conda/envs/topology/lib/python3.10/multiprocessing/connection.py", line 508, in Client
    answer_challenge(c, authkey)
  File "/home/conda/envs/topology/lib/python3.10/multiprocessing/connection.py", line 752, in answer_challenge
    message = connection.recv_bytes(256)         # reject large message
  File "/home/conda/envs/topology/lib/python3.10/multiprocessing/connection.py", line 216, in recv_bytes
    buf = self._recv_bytes(maxlength)
  File "/home/conda/envs/topology/lib/python3.10/multiprocessing/connection.py", line 414, in _recv_bytes
    buf = self._recv(4)
  File "/home/conda/envs/topology/lib/python3.10/multiprocessing/connection.py", line 379, in _recv
    chunk = read(handle, remaining)
ConnectionResetError: [Errno 104] Connection reset by peer
Traceback (most recent call last):
  File "/home/conda/envs/topology/lib/python3.10/multiprocessing/managers.py", line 810, in _callmethod
    conn = self._tls.connection
AttributeError: 'ForkAwareLocal' object has no attribute 'connection'

During handling of the above exception, another exception occurred:

Traceback (most recent call last):
  File "/home/conda/envs/topology/lib/python3.10/multiprocessing/process.py", line 314, in _bootstrap
    self.run()
  File "/home/conda/envs/topology/lib/python3.10/multiprocessing/process.py", line 108, in run
    self._target(*self._args, **self._kwargs)
  File "/home/jnoltmann/topology/src/E2.py", line 136, in get_c_lmlpmp_per_process
    return_dict[process_i] = E2_E3_E4_E5_get_c_lmlpmp(
  File "<string>", line 2, in __setitem__
  File "/home/conda/envs/topology/lib/python3.10/multiprocessing/managers.py", line 814, in _callmethod
    self._connect()
  File "/home/conda/envs/topology/lib/python3.10/multiprocessing/managers.py", line 801, in _connect
    conn = self._Client(self._token.address, authkey=self._authkey)
  File "/home/conda/envs/topology/lib/python3.10/multiprocessing/connection.py", line 508, in Client
    answer_challenge(c, authkey)
  File "/home/conda/envs/topology/lib/python3.10/multiprocessing/connection.py", line 752, in answer_challenge
    message = connection.recv_bytes(256)         # reject large message
  File "/home/conda/envs/topology/lib/python3.10/multiprocessing/connection.py", line 216, in recv_bytes
    buf = self._recv_bytes(maxlength)
  File "/home/conda/envs/topology/lib/python3.10/multiprocessing/connection.py", line 414, in _recv_bytes
    buf = self._recv(4)
  File "/home/conda/envs/topology/lib/python3.10/multiprocessing/connection.py", line 379, in _recv
    chunk = read(handle, remaining)
ConnectionResetError: [Errno 104] Connection reset by peer
Traceback (most recent call last):
  File "/home/conda/envs/topology/lib/python3.10/multiprocessing/managers.py", line 810, in _callmethod
    conn = self._tls.connection
AttributeError: 'ForkAwareLocal' object has no attribute 'connection'

During handling of the above exception, another exception occurred:

Traceback (most recent call last):
  File "/home/conda/envs/topology/lib/python3.10/multiprocessing/process.py", line 314, in _bootstrap
    self.run()
  File "/home/conda/envs/topology/lib/python3.10/multiprocessing/process.py", line 108, in run
    self._target(*self._args, **self._kwargs)
  File "/home/jnoltmann/topology/src/E2.py", line 136, in get_c_lmlpmp_per_process
    return_dict[process_i] = E2_E3_E4_E5_get_c_lmlpmp(
  File "<string>", line 2, in __setitem__
  File "/home/conda/envs/topology/lib/python3.10/multiprocessing/managers.py", line 814, in _callmethod
    self._connect()
  File "/home/conda/envs/topology/lib/python3.10/multiprocessing/managers.py", line 801, in _connect
    conn = self._Client(self._token.address, authkey=self._authkey)
  File "/home/conda/envs/topology/lib/python3.10/multiprocessing/connection.py", line 508, in Client
    answer_challenge(c, authkey)
  File "/home/conda/envs/topology/lib/python3.10/multiprocessing/connection.py", line 752, in answer_challenge
    message = connection.recv_bytes(256)         # reject large message
  File "/home/conda/envs/topology/lib/python3.10/multiprocessing/connection.py", line 216, in recv_bytes
    buf = self._recv_bytes(maxlength)
  File "/home/conda/envs/topology/lib/python3.10/multiprocessing/connection.py", line 414, in _recv_bytes
    buf = self._recv(4)
  File "/home/conda/envs/topology/lib/python3.10/multiprocessing/connection.py", line 379, in _recv
    chunk = read(handle, remaining)
ConnectionResetError: [Errno 104] Connection reset by peer
Traceback (most recent call last):
  File "/home/conda/envs/topology/lib/python3.10/multiprocessing/managers.py", line 810, in _callmethod
    conn = self._tls.connection
AttributeError: 'ForkAwareLocal' object has no attribute 'connection'

During handling of the above exception, another exception occurred:

Traceback (most recent call last):
  File "/home/conda/envs/topology/lib/python3.10/multiprocessing/process.py", line 314, in _bootstrap
    self.run()
  File "/home/conda/envs/topology/lib/python3.10/multiprocessing/process.py", line 108, in run
    self._target(*self._args, **self._kwargs)
  File "/home/jnoltmann/topology/src/E2.py", line 136, in get_c_lmlpmp_per_process
    return_dict[process_i] = E2_E3_E4_E5_get_c_lmlpmp(
  File "<string>", line 2, in __setitem__
  File "/home/conda/envs/topology/lib/python3.10/multiprocessing/managers.py", line 814, in _callmethod
    self._connect()
  File "/home/conda/envs/topology/lib/python3.10/multiprocessing/managers.py", line 801, in _connect
    conn = self._Client(self._token.address, authkey=self._authkey)
  File "/home/conda/envs/topology/lib/python3.10/multiprocessing/connection.py", line 508, in Client
    answer_challenge(c, authkey)
  File "/home/conda/envs/topology/lib/python3.10/multiprocessing/connection.py", line 757, in answer_challenge
    response = connection.recv_bytes(256)        # reject large message
  File "/home/conda/envs/topology/lib/python3.10/multiprocessing/connection.py", line 216, in recv_bytes
    buf = self._recv_bytes(maxlength)
  File "/home/conda/envs/topology/lib/python3.10/multiprocessing/connection.py", line 414, in _recv_bytes
    buf = self._recv(4)
  File "/home/conda/envs/topology/lib/python3.10/multiprocessing/connection.py", line 379, in _recv
    chunk = read(handle, remaining)
ConnectionResetError: [Errno 104] Connection reset by peer
Traceback (most recent call last):
  File "/home/conda/envs/topology/lib/python3.10/multiprocessing/managers.py", line 810, in _callmethod
    conn = self._tls.connection
AttributeError: 'ForkAwareLocal' object has no attribute 'connection'

During handling of the above exception, another exception occurred:

Traceback (most recent call last):
  File "/home/conda/envs/topology/lib/python3.10/multiprocessing/process.py", line 314, in _bootstrap
    self.run()
  File "/home/conda/envs/topology/lib/python3.10/multiprocessing/process.py", line 108, in run
    self._target(*self._args, **self._kwargs)
  File "/home/jnoltmann/topology/src/E2.py", line 136, in get_c_lmlpmp_per_process
    return_dict[process_i] = E2_E3_E4_E5_get_c_lmlpmp(
  File "<string>", line 2, in __setitem__
  File "/home/conda/envs/topology/lib/python3.10/multiprocessing/managers.py", line 814, in _callmethod
    self._connect()
  File "/home/conda/envs/topology/lib/python3.10/multiprocessing/managers.py", line 801, in _connect
    conn = self._Client(self._token.address, authkey=self._authkey)
  File "/home/conda/envs/topology/lib/python3.10/multiprocessing/connection.py", line 508, in Client
    answer_challenge(c, authkey)
  File "/home/conda/envs/topology/lib/python3.10/multiprocessing/connection.py", line 752, in answer_challenge
    message = connection.recv_bytes(256)         # reject large message
  File "/home/conda/envs/topology/lib/python3.10/multiprocessing/connection.py", line 216, in recv_bytes
    buf = self._recv_bytes(maxlength)
  File "/home/conda/envs/topology/lib/python3.10/multiprocessing/connection.py", line 414, in _recv_bytes
    buf = self._recv(4)
  File "/home/conda/envs/topology/lib/python3.10/multiprocessing/connection.py", line 379, in _recv
    chunk = read(handle, remaining)
ConnectionResetError: [Errno 104] Connection reset by peer
Traceback (most recent call last):
  File "/home/conda/envs/topology/lib/python3.10/multiprocessing/managers.py", line 810, in _callmethod
    conn = self._tls.connection
AttributeError: 'ForkAwareLocal' object has no attribute 'connection'

During handling of the above exception, another exception occurred:

Traceback (most recent call last):
  File "/home/conda/envs/topology/lib/python3.10/multiprocessing/process.py", line 314, in _bootstrap
    self.run()
  File "/home/conda/envs/topology/lib/python3.10/multiprocessing/process.py", line 108, in run
    self._target(*self._args, **self._kwargs)
  File "/home/jnoltmann/topology/src/E2.py", line 136, in get_c_lmlpmp_per_process
    return_dict[process_i] = E2_E3_E4_E5_get_c_lmlpmp(
  File "<string>", line 2, in __setitem__
  File "/home/conda/envs/topology/lib/python3.10/multiprocessing/managers.py", line 814, in _callmethod
    self._connect()
  File "/home/conda/envs/topology/lib/python3.10/multiprocessing/managers.py", line 801, in _connect
    conn = self._Client(self._token.address, authkey=self._authkey)
  File "/home/conda/envs/topology/lib/python3.10/multiprocessing/connection.py", line 508, in Client
    answer_challenge(c, authkey)
  File "/home/conda/envs/topology/lib/python3.10/multiprocessing/connection.py", line 752, in answer_challenge
    message = connection.recv_bytes(256)         # reject large message
  File "/home/conda/envs/topology/lib/python3.10/multiprocessing/connection.py", line 216, in recv_bytes
    buf = self._recv_bytes(maxlength)
  File "/home/conda/envs/topology/lib/python3.10/multiprocessing/connection.py", line 414, in _recv_bytes
    buf = self._recv(4)
  File "/home/conda/envs/topology/lib/python3.10/multiprocessing/connection.py", line 379, in _recv
    chunk = read(handle, remaining)
ConnectionResetError: [Errno 104] Connection reset by peer
Traceback (most recent call last):
  File "/home/conda/envs/topology/lib/python3.10/multiprocessing/process.py", line 314, in _bootstrap
    self.run()
  File "/home/conda/envs/topology/lib/python3.10/multiprocessing/process.py", line 108, in run
    self._target(*self._args, **self._kwargs)
  File "/home/jnoltmann/topology/src/E2.py", line 136, in get_c_lmlpmp_per_process
    return_dict[process_i] = E2_E3_E4_E5_get_c_lmlpmp(
  File "<string>", line 2, in __setitem__
  File "/home/conda/envs/topology/lib/python3.10/multiprocessing/managers.py", line 817, in _callmethod
    conn.send((self._id, methodname, args, kwds))
  File "/home/conda/envs/topology/lib/python3.10/multiprocessing/connection.py", line 206, in send
    self._send_bytes(_ForkingPickler.dumps(obj))
  File "/home/conda/envs/topology/lib/python3.10/multiprocessing/connection.py", line 405, in _send_bytes
    self._send(buf)
  File "/home/conda/envs/topology/lib/python3.10/multiprocessing/connection.py", line 368, in _send
    n = write(self._handle, buf)
BrokenPipeError: [Errno 32] Broken pipe
Traceback (most recent call last):
  File "/home/conda/envs/topology/lib/python3.10/multiprocessing/managers.py", line 810, in _callmethod
    conn = self._tls.connection
AttributeError: 'ForkAwareLocal' object has no attribute 'connection'

During handling of the above exception, another exception occurred:

Traceback (most recent call last):
  File "/home/conda/envs/topology/lib/python3.10/multiprocessing/process.py", line 314, in _bootstrap
    self.run()
  File "/home/conda/envs/topology/lib/python3.10/multiprocessing/process.py", line 108, in run
    self._target(*self._args, **self._kwargs)
  File "/home/jnoltmann/topology/src/E2.py", line 136, in get_c_lmlpmp_per_process
    return_dict[process_i] = E2_E3_E4_E5_get_c_lmlpmp(
  File "<string>", line 2, in __setitem__
  File "/home/conda/envs/topology/lib/python3.10/multiprocessing/managers.py", line 814, in _callmethod
    self._connect()
  File "/home/conda/envs/topology/lib/python3.10/multiprocessing/managers.py", line 801, in _connect
    conn = self._Client(self._token.address, authkey=self._authkey)
  File "/home/conda/envs/topology/lib/python3.10/multiprocessing/connection.py", line 508, in Client
    answer_challenge(c, authkey)
  File "/home/conda/envs/topology/lib/python3.10/multiprocessing/connection.py", line 752, in answer_challenge
    message = connection.recv_bytes(256)         # reject large message
  File "/home/conda/envs/topology/lib/python3.10/multiprocessing/connection.py", line 216, in recv_bytes
    buf = self._recv_bytes(maxlength)
  File "/home/conda/envs/topology/lib/python3.10/multiprocessing/connection.py", line 414, in _recv_bytes
    buf = self._recv(4)
  File "/home/conda/envs/topology/lib/python3.10/multiprocessing/connection.py", line 383, in _recv
    raise EOFError
EOFError
Traceback (most recent call last):
  File "/home/conda/envs/topology/lib/python3.10/multiprocessing/managers.py", line 810, in _callmethod
    conn = self._tls.connection
AttributeError: 'ForkAwareLocal' object has no attribute 'connection'

During handling of the above exception, another exception occurred:

Traceback (most recent call last):
  File "/home/conda/envs/topology/lib/python3.10/multiprocessing/process.py", line 314, in _bootstrap
    self.run()
  File "/home/conda/envs/topology/lib/python3.10/multiprocessing/process.py", line 108, in run
    self._target(*self._args, **self._kwargs)
  File "/home/jnoltmann/topology/src/E2.py", line 136, in get_c_lmlpmp_per_process
    return_dict[process_i] = E2_E3_E4_E5_get_c_lmlpmp(
  File "<string>", line 2, in __setitem__
  File "/home/conda/envs/topology/lib/python3.10/multiprocessing/managers.py", line 814, in _callmethod
    self._connect()
  File "/home/conda/envs/topology/lib/python3.10/multiprocessing/managers.py", line 801, in _connect
    conn = self._Client(self._token.address, authkey=self._authkey)
  File "/home/conda/envs/topology/lib/python3.10/multiprocessing/connection.py", line 508, in Client
    answer_challenge(c, authkey)
  File "/home/conda/envs/topology/lib/python3.10/multiprocessing/connection.py", line 752, in answer_challenge
    message = connection.recv_bytes(256)         # reject large message
  File "/home/conda/envs/topology/lib/python3.10/multiprocessing/connection.py", line 216, in recv_bytes
    buf = self._recv_bytes(maxlength)
Traceback (most recent call last):
  File "/home/conda/envs/topology/lib/python3.10/multiprocessing/connection.py", line 414, in _recv_bytes
    buf = self._recv(4)
  File "/home/conda/envs/topology/lib/python3.10/multiprocessing/connection.py", line 379, in _recv
    chunk = read(handle, remaining)
ConnectionResetError: [Errno 104] Connection reset by peer
  File "/home/conda/envs/topology/lib/python3.10/multiprocessing/managers.py", line 810, in _callmethod
    conn = self._tls.connection
AttributeError: 'ForkAwareLocal' object has no attribute 'connection'

During handling of the above exception, another exception occurred:

Traceback (most recent call last):
  File "/home/conda/envs/topology/lib/python3.10/multiprocessing/process.py", line 314, in _bootstrap
    self.run()
  File "/home/conda/envs/topology/lib/python3.10/multiprocessing/process.py", line 108, in run
    self._target(*self._args, **self._kwargs)
  File "/home/jnoltmann/topology/src/E2.py", line 136, in get_c_lmlpmp_per_process
    return_dict[process_i] = E2_E3_E4_E5_get_c_lmlpmp(
  File "<string>", line 2, in __setitem__
  File "/home/conda/envs/topology/lib/python3.10/multiprocessing/managers.py", line 814, in _callmethod
    self._connect()
  File "/home/conda/envs/topology/lib/python3.10/multiprocessing/managers.py", line 801, in _connect
    conn = self._Client(self._token.address, authkey=self._authkey)
  File "/home/conda/envs/topology/lib/python3.10/multiprocessing/connection.py", line 508, in Client
    answer_challenge(c, authkey)
  File "/home/conda/envs/topology/lib/python3.10/multiprocessing/connection.py", line 752, in answer_challenge
    message = connection.recv_bytes(256)         # reject large message
  File "/home/conda/envs/topology/lib/python3.10/multiprocessing/connection.py", line 216, in recv_bytes
    buf = self._recv_bytes(maxlength)
  File "/home/conda/envs/topology/lib/python3.10/multiprocessing/connection.py", line 414, in _recv_bytes
    buf = self._recv(4)
  File "/home/conda/envs/topology/lib/python3.10/multiprocessing/connection.py", line 379, in _recv
    chunk = read(handle, remaining)
ConnectionResetError: [Errno 104] Connection reset by peer
Traceback (most recent call last):
  File "/home/conda/envs/topology/lib/python3.10/multiprocessing/process.py", line 314, in _bootstrap
    self.run()
  File "/home/conda/envs/topology/lib/python3.10/multiprocessing/process.py", line 108, in run
    self._target(*self._args, **self._kwargs)
  File "/home/jnoltmann/topology/src/E2.py", line 136, in get_c_lmlpmp_per_process
    return_dict[process_i] = E2_E3_E4_E5_get_c_lmlpmp(
  File "<string>", line 2, in __setitem__
  File "/home/conda/envs/topology/lib/python3.10/multiprocessing/managers.py", line 817, in _callmethod
    conn.send((self._id, methodname, args, kwds))
  File "/home/conda/envs/topology/lib/python3.10/multiprocessing/connection.py", line 206, in send
    self._send_bytes(_ForkingPickler.dumps(obj))
  File "/home/conda/envs/topology/lib/python3.10/multiprocessing/connection.py", line 405, in _send_bytes
    self._send(buf)
  File "/home/conda/envs/topology/lib/python3.10/multiprocessing/connection.py", line 368, in _send
    n = write(self._handle, buf)
BrokenPipeError: [Errno 32] Broken pipe
Process Process-1013:
Traceback (most recent call last):
  File "/home/conda/envs/topology/lib/python3.10/multiprocessing/managers.py", line 810, in _callmethod
    conn = self._tls.connection
AttributeError: 'ForkAwareLocal' object has no attribute 'connection'

During handling of the above exception, another exception occurred:

Traceback (most recent call last):
  File "/home/conda/envs/topology/lib/python3.10/multiprocessing/process.py", line 314, in _bootstrap
    self.run()
  File "/home/conda/envs/topology/lib/python3.10/multiprocessing/process.py", line 108, in run
    self._target(*self._args, **self._kwargs)
  File "/home/jnoltmann/topology/src/E2.py", line 136, in get_c_lmlpmp_per_process
    return_dict[process_i] = E2_E3_E4_E5_get_c_lmlpmp(
  File "<string>", line 2, in __setitem__
  File "/home/conda/envs/topology/lib/python3.10/multiprocessing/managers.py", line 814, in _callmethod
    self._connect()
  File "/home/conda/envs/topology/lib/python3.10/multiprocessing/managers.py", line 801, in _connect
    conn = self._Client(self._token.address, authkey=self._authkey)
  File "/home/conda/envs/topology/lib/python3.10/multiprocessing/connection.py", line 502, in Client
    c = SocketClient(address)
  File "/home/conda/envs/topology/lib/python3.10/multiprocessing/connection.py", line 630, in SocketClient
    s.connect(address)
ConnectionRefusedError: [Errno 111] Connection refused
Process Process-1019:
Traceback (most recent call last):
  File "/home/conda/envs/topology/lib/python3.10/multiprocessing/managers.py", line 810, in _callmethod
    conn = self._tls.connection
AttributeError: 'ForkAwareLocal' object has no attribute 'connection'

During handling of the above exception, another exception occurred:

Traceback (most recent call last):
  File "/home/conda/envs/topology/lib/python3.10/multiprocessing/process.py", line 314, in _bootstrap
    self.run()
  File "/home/conda/envs/topology/lib/python3.10/multiprocessing/process.py", line 108, in run
    self._target(*self._args, **self._kwargs)
  File "/home/jnoltmann/topology/src/E2.py", line 136, in get_c_lmlpmp_per_process
    return_dict[process_i] = E2_E3_E4_E5_get_c_lmlpmp(
  File "<string>", line 2, in __setitem__
  File "/home/conda/envs/topology/lib/python3.10/multiprocessing/managers.py", line 814, in _callmethod
    self._connect()
  File "/home/conda/envs/topology/lib/python3.10/multiprocessing/managers.py", line 801, in _connect
    conn = self._Client(self._token.address, authkey=self._authkey)
  File "/home/conda/envs/topology/lib/python3.10/multiprocessing/connection.py", line 502, in Client
    c = SocketClient(address)
  File "/home/conda/envs/topology/lib/python3.10/multiprocessing/connection.py", line 630, in SocketClient
    s.connect(address)
ConnectionRefusedError: [Errno 111] Connection refused
Process Process-1008:
Traceback (most recent call last):
  File "/home/conda/envs/topology/lib/python3.10/multiprocessing/managers.py", line 810, in _callmethod
    conn = self._tls.connection
AttributeError: 'ForkAwareLocal' object has no attribute 'connection'

During handling of the above exception, another exception occurred:

Traceback (most recent call last):
  File "/home/conda/envs/topology/lib/python3.10/multiprocessing/process.py", line 314, in _bootstrap
    self.run()
  File "/home/conda/envs/topology/lib/python3.10/multiprocessing/process.py", line 108, in run
    self._target(*self._args, **self._kwargs)
  File "/home/jnoltmann/topology/src/E2.py", line 136, in get_c_lmlpmp_per_process
    return_dict[process_i] = E2_E3_E4_E5_get_c_lmlpmp(
  File "<string>", line 2, in __setitem__
  File "/home/conda/envs/topology/lib/python3.10/multiprocessing/managers.py", line 814, in _callmethod
    self._connect()
  File "/home/conda/envs/topology/lib/python3.10/multiprocessing/managers.py", line 801, in _connect
    conn = self._Client(self._token.address, authkey=self._authkey)
  File "/home/conda/envs/topology/lib/python3.10/multiprocessing/connection.py", line 502, in Client
    c = SocketClient(address)
  File "/home/conda/envs/topology/lib/python3.10/multiprocessing/connection.py", line 630, in SocketClient
    s.connect(address)
ConnectionRefusedError: [Errno 111] Connection refused
Process Process-1014:
Traceback (most recent call last):
  File "/home/conda/envs/topology/lib/python3.10/multiprocessing/managers.py", line 810, in _callmethod
    conn = self._tls.connection
AttributeError: 'ForkAwareLocal' object has no attribute 'connection'

During handling of the above exception, another exception occurred:

Traceback (most recent call last):
  File "/home/conda/envs/topology/lib/python3.10/multiprocessing/process.py", line 314, in _bootstrap
    self.run()
  File "/home/conda/envs/topology/lib/python3.10/multiprocessing/process.py", line 108, in run
    self._target(*self._args, **self._kwargs)
  File "/home/jnoltmann/topology/src/E2.py", line 136, in get_c_lmlpmp_per_process
    return_dict[process_i] = E2_E3_E4_E5_get_c_lmlpmp(
  File "<string>", line 2, in __setitem__
  File "/home/conda/envs/topology/lib/python3.10/multiprocessing/managers.py", line 814, in _callmethod
    self._connect()
  File "/home/conda/envs/topology/lib/python3.10/multiprocessing/managers.py", line 801, in _connect
    conn = self._Client(self._token.address, authkey=self._authkey)
  File "/home/conda/envs/topology/lib/python3.10/multiprocessing/connection.py", line 502, in Client
    c = SocketClient(address)
  File "/home/conda/envs/topology/lib/python3.10/multiprocessing/connection.py", line 630, in SocketClient
    s.connect(address)
ConnectionRefusedError: [Errno 111] Connection refused
Process Process-1156:
Traceback (most recent call last):
  File "/home/conda/envs/topology/lib/python3.10/multiprocessing/managers.py", line 810, in _callmethod
    conn = self._tls.connection
AttributeError: 'ForkAwareLocal' object has no attribute 'connection'

During handling of the above exception, another exception occurred:

Traceback (most recent call last):
  File "/home/conda/envs/topology/lib/python3.10/multiprocessing/process.py", line 314, in _bootstrap
    self.run()
  File "/home/conda/envs/topology/lib/python3.10/multiprocessing/process.py", line 108, in run
    self._target(*self._args, **self._kwargs)
  File "/home/jnoltmann/topology/src/E2.py", line 136, in get_c_lmlpmp_per_process
    return_dict[process_i] = E2_E3_E4_E5_get_c_lmlpmp(
  File "<string>", line 2, in __setitem__
  File "/home/conda/envs/topology/lib/python3.10/multiprocessing/managers.py", line 814, in _callmethod
    self._connect()
  File "/home/conda/envs/topology/lib/python3.10/multiprocessing/managers.py", line 801, in _connect
    conn = self._Client(self._token.address, authkey=self._authkey)
  File "/home/conda/envs/topology/lib/python3.10/multiprocessing/connection.py", line 502, in Client
    c = SocketClient(address)
  File "/home/conda/envs/topology/lib/python3.10/multiprocessing/connection.py", line 630, in SocketClient
    s.connect(address)
ConnectionRefusedError: [Errno 111] Connection refused
Process Process-1155:
Traceback (most recent call last):
  File "/home/conda/envs/topology/lib/python3.10/multiprocessing/managers.py", line 810, in _callmethod
    conn = self._tls.connection
AttributeError: 'ForkAwareLocal' object has no attribute 'connection'

During handling of the above exception, another exception occurred:

Traceback (most recent call last):
  File "/home/conda/envs/topology/lib/python3.10/multiprocessing/process.py", line 314, in _bootstrap
    self.run()
  File "/home/conda/envs/topology/lib/python3.10/multiprocessing/process.py", line 108, in run
    self._target(*self._args, **self._kwargs)
  File "/home/jnoltmann/topology/src/E2.py", line 136, in get_c_lmlpmp_per_process
    return_dict[process_i] = E2_E3_E4_E5_get_c_lmlpmp(
  File "<string>", line 2, in __setitem__
  File "/home/conda/envs/topology/lib/python3.10/multiprocessing/managers.py", line 814, in _callmethod
    self._connect()
  File "/home/conda/envs/topology/lib/python3.10/multiprocessing/managers.py", line 801, in _connect
    conn = self._Client(self._token.address, authkey=self._authkey)
  File "/home/conda/envs/topology/lib/python3.10/multiprocessing/connection.py", line 502, in Client
    c = SocketClient(address)
  File "/home/conda/envs/topology/lib/python3.10/multiprocessing/connection.py", line 630, in SocketClient
    s.connect(address)
ConnectionRefusedError: [Errno 111] Connection refused
Process Process-1154:
Traceback (most recent call last):
  File "/home/conda/envs/topology/lib/python3.10/multiprocessing/managers.py", line 810, in _callmethod
    conn = self._tls.connection
AttributeError: 'ForkAwareLocal' object has no attribute 'connection'

During handling of the above exception, another exception occurred:

Traceback (most recent call last):
  File "/home/conda/envs/topology/lib/python3.10/multiprocessing/process.py", line 314, in _bootstrap
    self.run()
  File "/home/conda/envs/topology/lib/python3.10/multiprocessing/process.py", line 108, in run
    self._target(*self._args, **self._kwargs)
  File "/home/jnoltmann/topology/src/E2.py", line 136, in get_c_lmlpmp_per_process
    return_dict[process_i] = E2_E3_E4_E5_get_c_lmlpmp(
  File "<string>", line 2, in __setitem__
  File "/home/conda/envs/topology/lib/python3.10/multiprocessing/managers.py", line 814, in _callmethod
    self._connect()
  File "/home/conda/envs/topology/lib/python3.10/multiprocessing/managers.py", line 801, in _connect
    conn = self._Client(self._token.address, authkey=self._authkey)
  File "/home/conda/envs/topology/lib/python3.10/multiprocessing/connection.py", line 502, in Client
    c = SocketClient(address)
  File "/home/conda/envs/topology/lib/python3.10/multiprocessing/connection.py", line 630, in SocketClient
    s.connect(address)
ConnectionRefusedError: [Errno 111] Connection refused
Process Process-1153:
Traceback (most recent call last):
  File "/home/conda/envs/topology/lib/python3.10/multiprocessing/managers.py", line 810, in _callmethod
    conn = self._tls.connection
AttributeError: 'ForkAwareLocal' object has no attribute 'connection'

During handling of the above exception, another exception occurred:

Traceback (most recent call last):
  File "/home/conda/envs/topology/lib/python3.10/multiprocessing/process.py", line 314, in _bootstrap
    self.run()
  File "/home/conda/envs/topology/lib/python3.10/multiprocessing/process.py", line 108, in run
    self._target(*self._args, **self._kwargs)
  File "/home/jnoltmann/topology/src/E2.py", line 136, in get_c_lmlpmp_per_process
    return_dict[process_i] = E2_E3_E4_E5_get_c_lmlpmp(
  File "<string>", line 2, in __setitem__
  File "/home/conda/envs/topology/lib/python3.10/multiprocessing/managers.py", line 814, in _callmethod
    self._connect()
  File "/home/conda/envs/topology/lib/python3.10/multiprocessing/managers.py", line 801, in _connect
    conn = self._Client(self._token.address, authkey=self._authkey)
  File "/home/conda/envs/topology/lib/python3.10/multiprocessing/connection.py", line 502, in Client
    c = SocketClient(address)
  File "/home/conda/envs/topology/lib/python3.10/multiprocessing/connection.py", line 630, in SocketClient
    s.connect(address)
ConnectionRefusedError: [Errno 111] Connection refused
Process Process-1152:
Traceback (most recent call last):
  File "/home/conda/envs/topology/lib/python3.10/multiprocessing/managers.py", line 810, in _callmethod
    conn = self._tls.connection
AttributeError: 'ForkAwareLocal' object has no attribute 'connection'

During handling of the above exception, another exception occurred:

Traceback (most recent call last):
  File "/home/conda/envs/topology/lib/python3.10/multiprocessing/process.py", line 314, in _bootstrap
    self.run()
  File "/home/conda/envs/topology/lib/python3.10/multiprocessing/process.py", line 108, in run
    self._target(*self._args, **self._kwargs)
  File "/home/jnoltmann/topology/src/E2.py", line 136, in get_c_lmlpmp_per_process
    return_dict[process_i] = E2_E3_E4_E5_get_c_lmlpmp(
  File "<string>", line 2, in __setitem__
  File "/home/conda/envs/topology/lib/python3.10/multiprocessing/managers.py", line 814, in _callmethod
    self._connect()
  File "/home/conda/envs/topology/lib/python3.10/multiprocessing/managers.py", line 801, in _connect
    conn = self._Client(self._token.address, authkey=self._authkey)
  File "/home/conda/envs/topology/lib/python3.10/multiprocessing/connection.py", line 502, in Client
    c = SocketClient(address)
  File "/home/conda/envs/topology/lib/python3.10/multiprocessing/connection.py", line 630, in SocketClient
    s.connect(address)
ConnectionRefusedError: [Errno 111] Connection refused
Process Process-1151:
Traceback (most recent call last):
  File "/home/conda/envs/topology/lib/python3.10/multiprocessing/managers.py", line 810, in _callmethod
    conn = self._tls.connection
AttributeError: 'ForkAwareLocal' object has no attribute 'connection'

During handling of the above exception, another exception occurred:

Traceback (most recent call last):
  File "/home/conda/envs/topology/lib/python3.10/multiprocessing/process.py", line 314, in _bootstrap
    self.run()
  File "/home/conda/envs/topology/lib/python3.10/multiprocessing/process.py", line 108, in run
    self._target(*self._args, **self._kwargs)
  File "/home/jnoltmann/topology/src/E2.py", line 136, in get_c_lmlpmp_per_process
    return_dict[process_i] = E2_E3_E4_E5_get_c_lmlpmp(
  File "<string>", line 2, in __setitem__
  File "/home/conda/envs/topology/lib/python3.10/multiprocessing/managers.py", line 814, in _callmethod
    self._connect()
  File "/home/conda/envs/topology/lib/python3.10/multiprocessing/managers.py", line 801, in _connect
    conn = self._Client(self._token.address, authkey=self._authkey)
  File "/home/conda/envs/topology/lib/python3.10/multiprocessing/connection.py", line 502, in Client
    c = SocketClient(address)
  File "/home/conda/envs/topology/lib/python3.10/multiprocessing/connection.py", line 630, in SocketClient
    s.connect(address)
ConnectionRefusedError: [Errno 111] Connection refused
Process Process-1150:
Traceback (most recent call last):
  File "/home/conda/envs/topology/lib/python3.10/multiprocessing/managers.py", line 810, in _callmethod
    conn = self._tls.connection
AttributeError: 'ForkAwareLocal' object has no attribute 'connection'

During handling of the above exception, another exception occurred:

Traceback (most recent call last):
  File "/home/conda/envs/topology/lib/python3.10/multiprocessing/process.py", line 314, in _bootstrap
    self.run()
  File "/home/conda/envs/topology/lib/python3.10/multiprocessing/process.py", line 108, in run
    self._target(*self._args, **self._kwargs)
  File "/home/jnoltmann/topology/src/E2.py", line 136, in get_c_lmlpmp_per_process
    return_dict[process_i] = E2_E3_E4_E5_get_c_lmlpmp(
  File "<string>", line 2, in __setitem__
  File "/home/conda/envs/topology/lib/python3.10/multiprocessing/managers.py", line 814, in _callmethod
    self._connect()
  File "/home/conda/envs/topology/lib/python3.10/multiprocessing/managers.py", line 801, in _connect
    conn = self._Client(self._token.address, authkey=self._authkey)
  File "/home/conda/envs/topology/lib/python3.10/multiprocessing/connection.py", line 502, in Client
    c = SocketClient(address)
  File "/home/conda/envs/topology/lib/python3.10/multiprocessing/connection.py", line 630, in SocketClient
    s.connect(address)
ConnectionRefusedError: [Errno 111] Connection refused
Process Process-1045:
Traceback (most recent call last):
  File "/home/conda/envs/topology/lib/python3.10/multiprocessing/managers.py", line 810, in _callmethod
    conn = self._tls.connection
AttributeError: 'ForkAwareLocal' object has no attribute 'connection'

During handling of the above exception, another exception occurred:

Traceback (most recent call last):
  File "/home/conda/envs/topology/lib/python3.10/multiprocessing/process.py", line 314, in _bootstrap
    self.run()
  File "/home/conda/envs/topology/lib/python3.10/multiprocessing/process.py", line 108, in run
    self._target(*self._args, **self._kwargs)
  File "/home/jnoltmann/topology/src/E2.py", line 136, in get_c_lmlpmp_per_process
    return_dict[process_i] = E2_E3_E4_E5_get_c_lmlpmp(
  File "<string>", line 2, in __setitem__
  File "/home/conda/envs/topology/lib/python3.10/multiprocessing/managers.py", line 814, in _callmethod
    self._connect()
  File "/home/conda/envs/topology/lib/python3.10/multiprocessing/managers.py", line 801, in _connect
    conn = self._Client(self._token.address, authkey=self._authkey)
  File "/home/conda/envs/topology/lib/python3.10/multiprocessing/connection.py", line 502, in Client
    c = SocketClient(address)
  File "/home/conda/envs/topology/lib/python3.10/multiprocessing/connection.py", line 630, in SocketClient
    s.connect(address)
ConnectionRefusedError: [Errno 111] Connection refused
Process Process-1138:
Traceback (most recent call last):
  File "/home/conda/envs/topology/lib/python3.10/multiprocessing/managers.py", line 810, in _callmethod
    conn = self._tls.connection
AttributeError: 'ForkAwareLocal' object has no attribute 'connection'

During handling of the above exception, another exception occurred:

Traceback (most recent call last):
  File "/home/conda/envs/topology/lib/python3.10/multiprocessing/process.py", line 314, in _bootstrap
    self.run()
  File "/home/conda/envs/topology/lib/python3.10/multiprocessing/process.py", line 108, in run
    self._target(*self._args, **self._kwargs)
  File "/home/jnoltmann/topology/src/E2.py", line 136, in get_c_lmlpmp_per_process
    return_dict[process_i] = E2_E3_E4_E5_get_c_lmlpmp(
  File "<string>", line 2, in __setitem__
  File "/home/conda/envs/topology/lib/python3.10/multiprocessing/managers.py", line 814, in _callmethod
    self._connect()
  File "/home/conda/envs/topology/lib/python3.10/multiprocessing/managers.py", line 801, in _connect
    conn = self._Client(self._token.address, authkey=self._authkey)
  File "/home/conda/envs/topology/lib/python3.10/multiprocessing/connection.py", line 502, in Client
    c = SocketClient(address)
  File "/home/conda/envs/topology/lib/python3.10/multiprocessing/connection.py", line 630, in SocketClient
    s.connect(address)
ConnectionRefusedError: [Errno 111] Connection refused
Process Process-1136:
Traceback (most recent call last):
  File "/home/conda/envs/topology/lib/python3.10/multiprocessing/managers.py", line 810, in _callmethod
    conn = self._tls.connection
AttributeError: 'ForkAwareLocal' object has no attribute 'connection'

During handling of the above exception, another exception occurred:

Traceback (most recent call last):
  File "/home/conda/envs/topology/lib/python3.10/multiprocessing/process.py", line 314, in _bootstrap
    self.run()
  File "/home/conda/envs/topology/lib/python3.10/multiprocessing/process.py", line 108, in run
    self._target(*self._args, **self._kwargs)
  File "/home/jnoltmann/topology/src/E2.py", line 136, in get_c_lmlpmp_per_process
    return_dict[process_i] = E2_E3_E4_E5_get_c_lmlpmp(
  File "<string>", line 2, in __setitem__
  File "/home/conda/envs/topology/lib/python3.10/multiprocessing/managers.py", line 814, in _callmethod
    self._connect()
  File "/home/conda/envs/topology/lib/python3.10/multiprocessing/managers.py", line 801, in _connect
    conn = self._Client(self._token.address, authkey=self._authkey)
  File "/home/conda/envs/topology/lib/python3.10/multiprocessing/connection.py", line 502, in Client
    c = SocketClient(address)
  File "/home/conda/envs/topology/lib/python3.10/multiprocessing/connection.py", line 630, in SocketClient
    s.connect(address)
ConnectionRefusedError: [Errno 111] Connection refused
Process Process-1143:
Traceback (most recent call last):
  File "/home/conda/envs/topology/lib/python3.10/multiprocessing/managers.py", line 810, in _callmethod
    conn = self._tls.connection
AttributeError: 'ForkAwareLocal' object has no attribute 'connection'

During handling of the above exception, another exception occurred:

Traceback (most recent call last):
  File "/home/conda/envs/topology/lib/python3.10/multiprocessing/process.py", line 314, in _bootstrap
    self.run()
  File "/home/conda/envs/topology/lib/python3.10/multiprocessing/process.py", line 108, in run
    self._target(*self._args, **self._kwargs)
  File "/home/jnoltmann/topology/src/E2.py", line 136, in get_c_lmlpmp_per_process
    return_dict[process_i] = E2_E3_E4_E5_get_c_lmlpmp(
  File "<string>", line 2, in __setitem__
  File "/home/conda/envs/topology/lib/python3.10/multiprocessing/managers.py", line 814, in _callmethod
    self._connect()
  File "/home/conda/envs/topology/lib/python3.10/multiprocessing/managers.py", line 801, in _connect
    conn = self._Client(self._token.address, authkey=self._authkey)
  File "/home/conda/envs/topology/lib/python3.10/multiprocessing/connection.py", line 502, in Client
    c = SocketClient(address)
  File "/home/conda/envs/topology/lib/python3.10/multiprocessing/connection.py", line 630, in SocketClient
    s.connect(address)
ConnectionRefusedError: [Errno 111] Connection refused
Process Process-1139:
Traceback (most recent call last):
  File "/home/conda/envs/topology/lib/python3.10/multiprocessing/managers.py", line 810, in _callmethod
    conn = self._tls.connection
AttributeError: 'ForkAwareLocal' object has no attribute 'connection'

During handling of the above exception, another exception occurred:

Traceback (most recent call last):
  File "/home/conda/envs/topology/lib/python3.10/multiprocessing/process.py", line 314, in _bootstrap
    self.run()
  File "/home/conda/envs/topology/lib/python3.10/multiprocessing/process.py", line 108, in run
    self._target(*self._args, **self._kwargs)
  File "/home/jnoltmann/topology/src/E2.py", line 136, in get_c_lmlpmp_per_process
    return_dict[process_i] = E2_E3_E4_E5_get_c_lmlpmp(
  File "<string>", line 2, in __setitem__
  File "/home/conda/envs/topology/lib/python3.10/multiprocessing/managers.py", line 814, in _callmethod
    self._connect()
  File "/home/conda/envs/topology/lib/python3.10/multiprocessing/managers.py", line 801, in _connect
    conn = self._Client(self._token.address, authkey=self._authkey)
  File "/home/conda/envs/topology/lib/python3.10/multiprocessing/connection.py", line 502, in Client
    c = SocketClient(address)
  File "/home/conda/envs/topology/lib/python3.10/multiprocessing/connection.py", line 630, in SocketClient
    s.connect(address)
ConnectionRefusedError: [Errno 111] Connection refused
Process Process-1126:
Traceback (most recent call last):
  File "/home/conda/envs/topology/lib/python3.10/multiprocessing/managers.py", line 810, in _callmethod
    conn = self._tls.connection
AttributeError: 'ForkAwareLocal' object has no attribute 'connection'

During handling of the above exception, another exception occurred:

Traceback (most recent call last):
  File "/home/conda/envs/topology/lib/python3.10/multiprocessing/process.py", line 314, in _bootstrap
    self.run()
  File "/home/conda/envs/topology/lib/python3.10/multiprocessing/process.py", line 108, in run
    self._target(*self._args, **self._kwargs)
  File "/home/jnoltmann/topology/src/E2.py", line 136, in get_c_lmlpmp_per_process
    return_dict[process_i] = E2_E3_E4_E5_get_c_lmlpmp(
  File "<string>", line 2, in __setitem__
  File "/home/conda/envs/topology/lib/python3.10/multiprocessing/managers.py", line 814, in _callmethod
    self._connect()
  File "/home/conda/envs/topology/lib/python3.10/multiprocessing/managers.py", line 801, in _connect
    conn = self._Client(self._token.address, authkey=self._authkey)
  File "/home/conda/envs/topology/lib/python3.10/multiprocessing/connection.py", line 502, in Client
    c = SocketClient(address)
  File "/home/conda/envs/topology/lib/python3.10/multiprocessing/connection.py", line 630, in SocketClient
    s.connect(address)
ConnectionRefusedError: [Errno 111] Connection refused
Process Process-1116:
Traceback (most recent call last):
  File "/home/conda/envs/topology/lib/python3.10/multiprocessing/managers.py", line 810, in _callmethod
    conn = self._tls.connection
AttributeError: 'ForkAwareLocal' object has no attribute 'connection'

During handling of the above exception, another exception occurred:

Traceback (most recent call last):
  File "/home/conda/envs/topology/lib/python3.10/multiprocessing/process.py", line 314, in _bootstrap
    self.run()
  File "/home/conda/envs/topology/lib/python3.10/multiprocessing/process.py", line 108, in run
    self._target(*self._args, **self._kwargs)
  File "/home/jnoltmann/topology/src/E2.py", line 136, in get_c_lmlpmp_per_process
    return_dict[process_i] = E2_E3_E4_E5_get_c_lmlpmp(
  File "<string>", line 2, in __setitem__
  File "/home/conda/envs/topology/lib/python3.10/multiprocessing/managers.py", line 814, in _callmethod
    self._connect()
  File "/home/conda/envs/topology/lib/python3.10/multiprocessing/managers.py", line 801, in _connect
    conn = self._Client(self._token.address, authkey=self._authkey)
  File "/home/conda/envs/topology/lib/python3.10/multiprocessing/connection.py", line 502, in Client
    c = SocketClient(address)
  File "/home/conda/envs/topology/lib/python3.10/multiprocessing/connection.py", line 630, in SocketClient
    s.connect(address)
ConnectionRefusedError: [Errno 111] Connection refused
Process Process-1048:
Traceback (most recent call last):
  File "/home/conda/envs/topology/lib/python3.10/multiprocessing/managers.py", line 810, in _callmethod
    conn = self._tls.connection
AttributeError: 'ForkAwareLocal' object has no attribute 'connection'

During handling of the above exception, another exception occurred:

Traceback (most recent call last):
  File "/home/conda/envs/topology/lib/python3.10/multiprocessing/process.py", line 314, in _bootstrap
    self.run()
  File "/home/conda/envs/topology/lib/python3.10/multiprocessing/process.py", line 108, in run
    self._target(*self._args, **self._kwargs)
  File "/home/jnoltmann/topology/src/E2.py", line 136, in get_c_lmlpmp_per_process
    return_dict[process_i] = E2_E3_E4_E5_get_c_lmlpmp(
  File "<string>", line 2, in __setitem__
  File "/home/conda/envs/topology/lib/python3.10/multiprocessing/managers.py", line 814, in _callmethod
    self._connect()
  File "/home/conda/envs/topology/lib/python3.10/multiprocessing/managers.py", line 801, in _connect
    conn = self._Client(self._token.address, authkey=self._authkey)
  File "/home/conda/envs/topology/lib/python3.10/multiprocessing/connection.py", line 502, in Client
    c = SocketClient(address)
  File "/home/conda/envs/topology/lib/python3.10/multiprocessing/connection.py", line 630, in SocketClient
    s.connect(address)
ConnectionRefusedError: [Errno 111] Connection refused
Process Process-1051:
Traceback (most recent call last):
  File "/home/conda/envs/topology/lib/python3.10/multiprocessing/managers.py", line 810, in _callmethod
    conn = self._tls.connection
AttributeError: 'ForkAwareLocal' object has no attribute 'connection'

During handling of the above exception, another exception occurred:

Traceback (most recent call last):
  File "/home/conda/envs/topology/lib/python3.10/multiprocessing/process.py", line 314, in _bootstrap
    self.run()
  File "/home/conda/envs/topology/lib/python3.10/multiprocessing/process.py", line 108, in run
    self._target(*self._args, **self._kwargs)
  File "/home/jnoltmann/topology/src/E2.py", line 136, in get_c_lmlpmp_per_process
    return_dict[process_i] = E2_E3_E4_E5_get_c_lmlpmp(
  File "<string>", line 2, in __setitem__
  File "/home/conda/envs/topology/lib/python3.10/multiprocessing/managers.py", line 814, in _callmethod
    self._connect()
  File "/home/conda/envs/topology/lib/python3.10/multiprocessing/managers.py", line 801, in _connect
    conn = self._Client(self._token.address, authkey=self._authkey)
  File "/home/conda/envs/topology/lib/python3.10/multiprocessing/connection.py", line 502, in Client
    c = SocketClient(address)
  File "/home/conda/envs/topology/lib/python3.10/multiprocessing/connection.py", line 630, in SocketClient
    s.connect(address)
ConnectionRefusedError: [Errno 111] Connection refused
Process Process-1056:
Traceback (most recent call last):
  File "/home/conda/envs/topology/lib/python3.10/multiprocessing/managers.py", line 810, in _callmethod
    conn = self._tls.connection
AttributeError: 'ForkAwareLocal' object has no attribute 'connection'

During handling of the above exception, another exception occurred:

Traceback (most recent call last):
  File "/home/conda/envs/topology/lib/python3.10/multiprocessing/process.py", line 314, in _bootstrap
    self.run()
  File "/home/conda/envs/topology/lib/python3.10/multiprocessing/process.py", line 108, in run
    self._target(*self._args, **self._kwargs)
  File "/home/jnoltmann/topology/src/E2.py", line 136, in get_c_lmlpmp_per_process
    return_dict[process_i] = E2_E3_E4_E5_get_c_lmlpmp(
  File "<string>", line 2, in __setitem__
  File "/home/conda/envs/topology/lib/python3.10/multiprocessing/managers.py", line 814, in _callmethod
    self._connect()
  File "/home/conda/envs/topology/lib/python3.10/multiprocessing/managers.py", line 801, in _connect
    conn = self._Client(self._token.address, authkey=self._authkey)
  File "/home/conda/envs/topology/lib/python3.10/multiprocessing/connection.py", line 502, in Client
    c = SocketClient(address)
  File "/home/conda/envs/topology/lib/python3.10/multiprocessing/connection.py", line 630, in SocketClient
    s.connect(address)
ConnectionRefusedError: [Errno 111] Connection refused
Process Process-1083:
Traceback (most recent call last):
  File "/home/conda/envs/topology/lib/python3.10/multiprocessing/managers.py", line 810, in _callmethod
    conn = self._tls.connection
AttributeError: 'ForkAwareLocal' object has no attribute 'connection'

During handling of the above exception, another exception occurred:

Traceback (most recent call last):
  File "/home/conda/envs/topology/lib/python3.10/multiprocessing/process.py", line 314, in _bootstrap
    self.run()
  File "/home/conda/envs/topology/lib/python3.10/multiprocessing/process.py", line 108, in run
    self._target(*self._args, **self._kwargs)
  File "/home/jnoltmann/topology/src/E2.py", line 136, in get_c_lmlpmp_per_process
    return_dict[process_i] = E2_E3_E4_E5_get_c_lmlpmp(
  File "<string>", line 2, in __setitem__
  File "/home/conda/envs/topology/lib/python3.10/multiprocessing/managers.py", line 814, in _callmethod
    self._connect()
  File "/home/conda/envs/topology/lib/python3.10/multiprocessing/managers.py", line 801, in _connect
    conn = self._Client(self._token.address, authkey=self._authkey)
  File "/home/conda/envs/topology/lib/python3.10/multiprocessing/connection.py", line 502, in Client
    c = SocketClient(address)
  File "/home/conda/envs/topology/lib/python3.10/multiprocessing/connection.py", line 630, in SocketClient
    s.connect(address)
ConnectionRefusedError: [Errno 111] Connection refused
Process Process-1086:
Traceback (most recent call last):
  File "/home/conda/envs/topology/lib/python3.10/multiprocessing/managers.py", line 810, in _callmethod
    conn = self._tls.connection
AttributeError: 'ForkAwareLocal' object has no attribute 'connection'

During handling of the above exception, another exception occurred:

Traceback (most recent call last):
  File "/home/conda/envs/topology/lib/python3.10/multiprocessing/process.py", line 314, in _bootstrap
    self.run()
  File "/home/conda/envs/topology/lib/python3.10/multiprocessing/process.py", line 108, in run
    self._target(*self._args, **self._kwargs)
  File "/home/jnoltmann/topology/src/E2.py", line 136, in get_c_lmlpmp_per_process
    return_dict[process_i] = E2_E3_E4_E5_get_c_lmlpmp(
  File "<string>", line 2, in __setitem__
  File "/home/conda/envs/topology/lib/python3.10/multiprocessing/managers.py", line 814, in _callmethod
    self._connect()
  File "/home/conda/envs/topology/lib/python3.10/multiprocessing/managers.py", line 801, in _connect
    conn = self._Client(self._token.address, authkey=self._authkey)
  File "/home/conda/envs/topology/lib/python3.10/multiprocessing/connection.py", line 502, in Client
    c = SocketClient(address)
  File "/home/conda/envs/topology/lib/python3.10/multiprocessing/connection.py", line 630, in SocketClient
    s.connect(address)
ConnectionRefusedError: [Errno 111] Connection refused
Process Process-1066:
Traceback (most recent call last):
  File "/home/conda/envs/topology/lib/python3.10/multiprocessing/managers.py", line 810, in _callmethod
    conn = self._tls.connection
AttributeError: 'ForkAwareLocal' object has no attribute 'connection'

During handling of the above exception, another exception occurred:

Traceback (most recent call last):
  File "/home/conda/envs/topology/lib/python3.10/multiprocessing/process.py", line 314, in _bootstrap
    self.run()
  File "/home/conda/envs/topology/lib/python3.10/multiprocessing/process.py", line 108, in run
    self._target(*self._args, **self._kwargs)
  File "/home/jnoltmann/topology/src/E2.py", line 136, in get_c_lmlpmp_per_process
    return_dict[process_i] = E2_E3_E4_E5_get_c_lmlpmp(
  File "<string>", line 2, in __setitem__
  File "/home/conda/envs/topology/lib/python3.10/multiprocessing/managers.py", line 814, in _callmethod
    self._connect()
  File "/home/conda/envs/topology/lib/python3.10/multiprocessing/managers.py", line 801, in _connect
    conn = self._Client(self._token.address, authkey=self._authkey)
  File "/home/conda/envs/topology/lib/python3.10/multiprocessing/connection.py", line 502, in Client
    c = SocketClient(address)
  File "/home/conda/envs/topology/lib/python3.10/multiprocessing/connection.py", line 630, in SocketClient
    s.connect(address)
ConnectionRefusedError: [Errno 111] Connection refused
Process Process-1082:
Traceback (most recent call last):
  File "/home/conda/envs/topology/lib/python3.10/multiprocessing/managers.py", line 810, in _callmethod
    conn = self._tls.connection
AttributeError: 'ForkAwareLocal' object has no attribute 'connection'

During handling of the above exception, another exception occurred:

Traceback (most recent call last):
  File "/home/conda/envs/topology/lib/python3.10/multiprocessing/process.py", line 314, in _bootstrap
    self.run()
  File "/home/conda/envs/topology/lib/python3.10/multiprocessing/process.py", line 108, in run
    self._target(*self._args, **self._kwargs)
  File "/home/jnoltmann/topology/src/E2.py", line 136, in get_c_lmlpmp_per_process
    return_dict[process_i] = E2_E3_E4_E5_get_c_lmlpmp(
  File "<string>", line 2, in __setitem__
  File "/home/conda/envs/topology/lib/python3.10/multiprocessing/managers.py", line 814, in _callmethod
    self._connect()
  File "/home/conda/envs/topology/lib/python3.10/multiprocessing/managers.py", line 801, in _connect
    conn = self._Client(self._token.address, authkey=self._authkey)
  File "/home/conda/envs/topology/lib/python3.10/multiprocessing/connection.py", line 502, in Client
    c = SocketClient(address)
  File "/home/conda/envs/topology/lib/python3.10/multiprocessing/connection.py", line 630, in SocketClient
    s.connect(address)
ConnectionRefusedError: [Errno 111] Connection refused
Process Process-1144:
Traceback (most recent call last):
  File "/home/conda/envs/topology/lib/python3.10/multiprocessing/managers.py", line 810, in _callmethod
    conn = self._tls.connection
AttributeError: 'ForkAwareLocal' object has no attribute 'connection'

During handling of the above exception, another exception occurred:

Traceback (most recent call last):
  File "/home/conda/envs/topology/lib/python3.10/multiprocessing/process.py", line 314, in _bootstrap
    self.run()
  File "/home/conda/envs/topology/lib/python3.10/multiprocessing/process.py", line 108, in run
    self._target(*self._args, **self._kwargs)
  File "/home/jnoltmann/topology/src/E2.py", line 136, in get_c_lmlpmp_per_process
    return_dict[process_i] = E2_E3_E4_E5_get_c_lmlpmp(
  File "<string>", line 2, in __setitem__
  File "/home/conda/envs/topology/lib/python3.10/multiprocessing/managers.py", line 814, in _callmethod
    self._connect()
  File "/home/conda/envs/topology/lib/python3.10/multiprocessing/managers.py", line 801, in _connect
    conn = self._Client(self._token.address, authkey=self._authkey)
  File "/home/conda/envs/topology/lib/python3.10/multiprocessing/connection.py", line 502, in Client
    c = SocketClient(address)
  File "/home/conda/envs/topology/lib/python3.10/multiprocessing/connection.py", line 630, in SocketClient
    s.connect(address)
ConnectionRefusedError: [Errno 111] Connection refused
Process Process-1135:
Traceback (most recent call last):
  File "/home/conda/envs/topology/lib/python3.10/multiprocessing/managers.py", line 810, in _callmethod
    conn = self._tls.connection
AttributeError: 'ForkAwareLocal' object has no attribute 'connection'

During handling of the above exception, another exception occurred:

Traceback (most recent call last):
  File "/home/conda/envs/topology/lib/python3.10/multiprocessing/process.py", line 314, in _bootstrap
    self.run()
  File "/home/conda/envs/topology/lib/python3.10/multiprocessing/process.py", line 108, in run
    self._target(*self._args, **self._kwargs)
  File "/home/jnoltmann/topology/src/E2.py", line 136, in get_c_lmlpmp_per_process
    return_dict[process_i] = E2_E3_E4_E5_get_c_lmlpmp(
  File "<string>", line 2, in __setitem__
  File "/home/conda/envs/topology/lib/python3.10/multiprocessing/managers.py", line 814, in _callmethod
    self._connect()
  File "/home/conda/envs/topology/lib/python3.10/multiprocessing/managers.py", line 801, in _connect
    conn = self._Client(self._token.address, authkey=self._authkey)
  File "/home/conda/envs/topology/lib/python3.10/multiprocessing/connection.py", line 502, in Client
    c = SocketClient(address)
  File "/home/conda/envs/topology/lib/python3.10/multiprocessing/connection.py", line 630, in SocketClient
    s.connect(address)
ConnectionRefusedError: [Errno 111] Connection refused
Process Process-1075:
Traceback (most recent call last):
  File "/home/conda/envs/topology/lib/python3.10/multiprocessing/managers.py", line 810, in _callmethod
    conn = self._tls.connection
AttributeError: 'ForkAwareLocal' object has no attribute 'connection'

During handling of the above exception, another exception occurred:

Traceback (most recent call last):
  File "/home/conda/envs/topology/lib/python3.10/multiprocessing/process.py", line 314, in _bootstrap
    self.run()
  File "/home/conda/envs/topology/lib/python3.10/multiprocessing/process.py", line 108, in run
    self._target(*self._args, **self._kwargs)
  File "/home/jnoltmann/topology/src/E2.py", line 136, in get_c_lmlpmp_per_process
    return_dict[process_i] = E2_E3_E4_E5_get_c_lmlpmp(
  File "<string>", line 2, in __setitem__
  File "/home/conda/envs/topology/lib/python3.10/multiprocessing/managers.py", line 814, in _callmethod
    self._connect()
  File "/home/conda/envs/topology/lib/python3.10/multiprocessing/managers.py", line 801, in _connect
    conn = self._Client(self._token.address, authkey=self._authkey)
  File "/home/conda/envs/topology/lib/python3.10/multiprocessing/connection.py", line 502, in Client
    c = SocketClient(address)
  File "/home/conda/envs/topology/lib/python3.10/multiprocessing/connection.py", line 630, in SocketClient
    s.connect(address)
ConnectionRefusedError: [Errno 111] Connection refused
Process Process-1110:
Traceback (most recent call last):
  File "/home/conda/envs/topology/lib/python3.10/multiprocessing/managers.py", line 810, in _callmethod
    conn = self._tls.connection
AttributeError: 'ForkAwareLocal' object has no attribute 'connection'

During handling of the above exception, another exception occurred:

Traceback (most recent call last):
  File "/home/conda/envs/topology/lib/python3.10/multiprocessing/process.py", line 314, in _bootstrap
    self.run()
  File "/home/conda/envs/topology/lib/python3.10/multiprocessing/process.py", line 108, in run
    self._target(*self._args, **self._kwargs)
  File "/home/jnoltmann/topology/src/E2.py", line 136, in get_c_lmlpmp_per_process
    return_dict[process_i] = E2_E3_E4_E5_get_c_lmlpmp(
  File "<string>", line 2, in __setitem__
  File "/home/conda/envs/topology/lib/python3.10/multiprocessing/managers.py", line 814, in _callmethod
    self._connect()
  File "/home/conda/envs/topology/lib/python3.10/multiprocessing/managers.py", line 801, in _connect
    conn = self._Client(self._token.address, authkey=self._authkey)
  File "/home/conda/envs/topology/lib/python3.10/multiprocessing/connection.py", line 502, in Client
    c = SocketClient(address)
  File "/home/conda/envs/topology/lib/python3.10/multiprocessing/connection.py", line 630, in SocketClient
    s.connect(address)
ConnectionRefusedError: [Errno 111] Connection refused
Process Process-1059:
Traceback (most recent call last):
  File "/home/conda/envs/topology/lib/python3.10/multiprocessing/managers.py", line 810, in _callmethod
    conn = self._tls.connection
AttributeError: 'ForkAwareLocal' object has no attribute 'connection'

During handling of the above exception, another exception occurred:

Traceback (most recent call last):
  File "/home/conda/envs/topology/lib/python3.10/multiprocessing/process.py", line 314, in _bootstrap
    self.run()
  File "/home/conda/envs/topology/lib/python3.10/multiprocessing/process.py", line 108, in run
    self._target(*self._args, **self._kwargs)
  File "/home/jnoltmann/topology/src/E2.py", line 136, in get_c_lmlpmp_per_process
    return_dict[process_i] = E2_E3_E4_E5_get_c_lmlpmp(
  File "<string>", line 2, in __setitem__
  File "/home/conda/envs/topology/lib/python3.10/multiprocessing/managers.py", line 814, in _callmethod
    self._connect()
  File "/home/conda/envs/topology/lib/python3.10/multiprocessing/managers.py", line 801, in _connect
    conn = self._Client(self._token.address, authkey=self._authkey)
  File "/home/conda/envs/topology/lib/python3.10/multiprocessing/connection.py", line 502, in Client
    c = SocketClient(address)
  File "/home/conda/envs/topology/lib/python3.10/multiprocessing/connection.py", line 630, in SocketClient
    s.connect(address)
ConnectionRefusedError: [Errno 111] Connection refused
Process Process-1080:
Traceback (most recent call last):
  File "/home/conda/envs/topology/lib/python3.10/multiprocessing/managers.py", line 810, in _callmethod
    conn = self._tls.connection
AttributeError: 'ForkAwareLocal' object has no attribute 'connection'

During handling of the above exception, another exception occurred:

Traceback (most recent call last):
  File "/home/conda/envs/topology/lib/python3.10/multiprocessing/process.py", line 314, in _bootstrap
    self.run()
  File "/home/conda/envs/topology/lib/python3.10/multiprocessing/process.py", line 108, in run
    self._target(*self._args, **self._kwargs)
  File "/home/jnoltmann/topology/src/E2.py", line 136, in get_c_lmlpmp_per_process
    return_dict[process_i] = E2_E3_E4_E5_get_c_lmlpmp(
  File "<string>", line 2, in __setitem__
  File "/home/conda/envs/topology/lib/python3.10/multiprocessing/managers.py", line 814, in _callmethod
    self._connect()
  File "/home/conda/envs/topology/lib/python3.10/multiprocessing/managers.py", line 801, in _connect
    conn = self._Client(self._token.address, authkey=self._authkey)
  File "/home/conda/envs/topology/lib/python3.10/multiprocessing/connection.py", line 502, in Client
    c = SocketClient(address)
  File "/home/conda/envs/topology/lib/python3.10/multiprocessing/connection.py", line 630, in SocketClient
    s.connect(address)
ConnectionRefusedError: [Errno 111] Connection refused
Process Process-1129:
Traceback (most recent call last):
  File "/home/conda/envs/topology/lib/python3.10/multiprocessing/managers.py", line 810, in _callmethod
    conn = self._tls.connection
AttributeError: 'ForkAwareLocal' object has no attribute 'connection'

During handling of the above exception, another exception occurred:

Traceback (most recent call last):
  File "/home/conda/envs/topology/lib/python3.10/multiprocessing/process.py", line 314, in _bootstrap
    self.run()
  File "/home/conda/envs/topology/lib/python3.10/multiprocessing/process.py", line 108, in run
    self._target(*self._args, **self._kwargs)
  File "/home/jnoltmann/topology/src/E2.py", line 136, in get_c_lmlpmp_per_process
    return_dict[process_i] = E2_E3_E4_E5_get_c_lmlpmp(
  File "<string>", line 2, in __setitem__
  File "/home/conda/envs/topology/lib/python3.10/multiprocessing/managers.py", line 814, in _callmethod
    self._connect()
  File "/home/conda/envs/topology/lib/python3.10/multiprocessing/managers.py", line 801, in _connect
    conn = self._Client(self._token.address, authkey=self._authkey)
  File "/home/conda/envs/topology/lib/python3.10/multiprocessing/connection.py", line 502, in Client
    c = SocketClient(address)
  File "/home/conda/envs/topology/lib/python3.10/multiprocessing/connection.py", line 630, in SocketClient
    s.connect(address)
ConnectionRefusedError: [Errno 111] Connection refused
Process Process-1131:
Traceback (most recent call last):
  File "/home/conda/envs/topology/lib/python3.10/multiprocessing/managers.py", line 810, in _callmethod
    conn = self._tls.connection
AttributeError: 'ForkAwareLocal' object has no attribute 'connection'

During handling of the above exception, another exception occurred:

Traceback (most recent call last):
  File "/home/conda/envs/topology/lib/python3.10/multiprocessing/process.py", line 314, in _bootstrap
    self.run()
  File "/home/conda/envs/topology/lib/python3.10/multiprocessing/process.py", line 108, in run
    self._target(*self._args, **self._kwargs)
  File "/home/jnoltmann/topology/src/E2.py", line 136, in get_c_lmlpmp_per_process
    return_dict[process_i] = E2_E3_E4_E5_get_c_lmlpmp(
  File "<string>", line 2, in __setitem__
  File "/home/conda/envs/topology/lib/python3.10/multiprocessing/managers.py", line 814, in _callmethod
    self._connect()
  File "/home/conda/envs/topology/lib/python3.10/multiprocessing/managers.py", line 801, in _connect
    conn = self._Client(self._token.address, authkey=self._authkey)
  File "/home/conda/envs/topology/lib/python3.10/multiprocessing/connection.py", line 502, in Client
    c = SocketClient(address)
  File "/home/conda/envs/topology/lib/python3.10/multiprocessing/connection.py", line 630, in SocketClient
    s.connect(address)
ConnectionRefusedError: [Errno 111] Connection refused
Process Process-1147:
Traceback (most recent call last):
  File "/home/conda/envs/topology/lib/python3.10/multiprocessing/managers.py", line 810, in _callmethod
    conn = self._tls.connection
AttributeError: 'ForkAwareLocal' object has no attribute 'connection'

During handling of the above exception, another exception occurred:

Traceback (most recent call last):
  File "/home/conda/envs/topology/lib/python3.10/multiprocessing/process.py", line 314, in _bootstrap
    self.run()
  File "/home/conda/envs/topology/lib/python3.10/multiprocessing/process.py", line 108, in run
    self._target(*self._args, **self._kwargs)
  File "/home/jnoltmann/topology/src/E2.py", line 136, in get_c_lmlpmp_per_process
    return_dict[process_i] = E2_E3_E4_E5_get_c_lmlpmp(
  File "<string>", line 2, in __setitem__
  File "/home/conda/envs/topology/lib/python3.10/multiprocessing/managers.py", line 814, in _callmethod
    self._connect()
  File "/home/conda/envs/topology/lib/python3.10/multiprocessing/managers.py", line 801, in _connect
    conn = self._Client(self._token.address, authkey=self._authkey)
  File "/home/conda/envs/topology/lib/python3.10/multiprocessing/connection.py", line 502, in Client
    c = SocketClient(address)
  File "/home/conda/envs/topology/lib/python3.10/multiprocessing/connection.py", line 630, in SocketClient
    s.connect(address)
ConnectionRefusedError: [Errno 111] Connection refused
Process Process-1062:
Traceback (most recent call last):
  File "/home/conda/envs/topology/lib/python3.10/multiprocessing/managers.py", line 810, in _callmethod
    conn = self._tls.connection
AttributeError: 'ForkAwareLocal' object has no attribute 'connection'

During handling of the above exception, another exception occurred:

Traceback (most recent call last):
  File "/home/conda/envs/topology/lib/python3.10/multiprocessing/process.py", line 314, in _bootstrap
    self.run()
  File "/home/conda/envs/topology/lib/python3.10/multiprocessing/process.py", line 108, in run
    self._target(*self._args, **self._kwargs)
  File "/home/jnoltmann/topology/src/E2.py", line 136, in get_c_lmlpmp_per_process
    return_dict[process_i] = E2_E3_E4_E5_get_c_lmlpmp(
  File "<string>", line 2, in __setitem__
  File "/home/conda/envs/topology/lib/python3.10/multiprocessing/managers.py", line 814, in _callmethod
    self._connect()
  File "/home/conda/envs/topology/lib/python3.10/multiprocessing/managers.py", line 801, in _connect
    conn = self._Client(self._token.address, authkey=self._authkey)
  File "/home/conda/envs/topology/lib/python3.10/multiprocessing/connection.py", line 502, in Client
    c = SocketClient(address)
  File "/home/conda/envs/topology/lib/python3.10/multiprocessing/connection.py", line 630, in SocketClient
    s.connect(address)
ConnectionRefusedError: [Errno 111] Connection refused
Process Process-1145:
Traceback (most recent call last):
  File "/home/conda/envs/topology/lib/python3.10/multiprocessing/managers.py", line 810, in _callmethod
    conn = self._tls.connection
AttributeError: 'ForkAwareLocal' object has no attribute 'connection'

During handling of the above exception, another exception occurred:

Traceback (most recent call last):
  File "/home/conda/envs/topology/lib/python3.10/multiprocessing/process.py", line 314, in _bootstrap
    self.run()
  File "/home/conda/envs/topology/lib/python3.10/multiprocessing/process.py", line 108, in run
    self._target(*self._args, **self._kwargs)
  File "/home/jnoltmann/topology/src/E2.py", line 136, in get_c_lmlpmp_per_process
    return_dict[process_i] = E2_E3_E4_E5_get_c_lmlpmp(
  File "<string>", line 2, in __setitem__
  File "/home/conda/envs/topology/lib/python3.10/multiprocessing/managers.py", line 814, in _callmethod
    self._connect()
  File "/home/conda/envs/topology/lib/python3.10/multiprocessing/managers.py", line 801, in _connect
    conn = self._Client(self._token.address, authkey=self._authkey)
  File "/home/conda/envs/topology/lib/python3.10/multiprocessing/connection.py", line 502, in Client
    c = SocketClient(address)
  File "/home/conda/envs/topology/lib/python3.10/multiprocessing/connection.py", line 630, in SocketClient
    s.connect(address)
ConnectionRefusedError: [Errno 111] Connection refused
Process Process-1140:
Traceback (most recent call last):
  File "/home/conda/envs/topology/lib/python3.10/multiprocessing/managers.py", line 810, in _callmethod
    conn = self._tls.connection
AttributeError: 'ForkAwareLocal' object has no attribute 'connection'

During handling of the above exception, another exception occurred:

Traceback (most recent call last):
  File "/home/conda/envs/topology/lib/python3.10/multiprocessing/process.py", line 314, in _bootstrap
    self.run()
  File "/home/conda/envs/topology/lib/python3.10/multiprocessing/process.py", line 108, in run
    self._target(*self._args, **self._kwargs)
  File "/home/jnoltmann/topology/src/E2.py", line 136, in get_c_lmlpmp_per_process
    return_dict[process_i] = E2_E3_E4_E5_get_c_lmlpmp(
  File "<string>", line 2, in __setitem__
  File "/home/conda/envs/topology/lib/python3.10/multiprocessing/managers.py", line 814, in _callmethod
    self._connect()
  File "/home/conda/envs/topology/lib/python3.10/multiprocessing/managers.py", line 801, in _connect
    conn = self._Client(self._token.address, authkey=self._authkey)
  File "/home/conda/envs/topology/lib/python3.10/multiprocessing/connection.py", line 502, in Client
    c = SocketClient(address)
  File "/home/conda/envs/topology/lib/python3.10/multiprocessing/connection.py", line 630, in SocketClient
    s.connect(address)
ConnectionRefusedError: [Errno 111] Connection refused
Process Process-1141:
Traceback (most recent call last):
  File "/home/conda/envs/topology/lib/python3.10/multiprocessing/managers.py", line 810, in _callmethod
    conn = self._tls.connection
AttributeError: 'ForkAwareLocal' object has no attribute 'connection'

During handling of the above exception, another exception occurred:

Traceback (most recent call last):
  File "/home/conda/envs/topology/lib/python3.10/multiprocessing/process.py", line 314, in _bootstrap
    self.run()
  File "/home/conda/envs/topology/lib/python3.10/multiprocessing/process.py", line 108, in run
    self._target(*self._args, **self._kwargs)
  File "/home/jnoltmann/topology/src/E2.py", line 136, in get_c_lmlpmp_per_process
    return_dict[process_i] = E2_E3_E4_E5_get_c_lmlpmp(
  File "<string>", line 2, in __setitem__
  File "/home/conda/envs/topology/lib/python3.10/multiprocessing/managers.py", line 814, in _callmethod
    self._connect()
  File "/home/conda/envs/topology/lib/python3.10/multiprocessing/managers.py", line 801, in _connect
    conn = self._Client(self._token.address, authkey=self._authkey)
  File "/home/conda/envs/topology/lib/python3.10/multiprocessing/connection.py", line 502, in Client
    c = SocketClient(address)
  File "/home/conda/envs/topology/lib/python3.10/multiprocessing/connection.py", line 630, in SocketClient
    s.connect(address)
ConnectionRefusedError: [Errno 111] Connection refused
Process Process-1097:
Traceback (most recent call last):
  File "/home/conda/envs/topology/lib/python3.10/multiprocessing/managers.py", line 810, in _callmethod
    conn = self._tls.connection
AttributeError: 'ForkAwareLocal' object has no attribute 'connection'

During handling of the above exception, another exception occurred:

Traceback (most recent call last):
  File "/home/conda/envs/topology/lib/python3.10/multiprocessing/process.py", line 314, in _bootstrap
    self.run()
  File "/home/conda/envs/topology/lib/python3.10/multiprocessing/process.py", line 108, in run
    self._target(*self._args, **self._kwargs)
  File "/home/jnoltmann/topology/src/E2.py", line 136, in get_c_lmlpmp_per_process
    return_dict[process_i] = E2_E3_E4_E5_get_c_lmlpmp(
  File "<string>", line 2, in __setitem__
  File "/home/conda/envs/topology/lib/python3.10/multiprocessing/managers.py", line 814, in _callmethod
    self._connect()
  File "/home/conda/envs/topology/lib/python3.10/multiprocessing/managers.py", line 801, in _connect
    conn = self._Client(self._token.address, authkey=self._authkey)
  File "/home/conda/envs/topology/lib/python3.10/multiprocessing/connection.py", line 502, in Client
    c = SocketClient(address)
  File "/home/conda/envs/topology/lib/python3.10/multiprocessing/connection.py", line 630, in SocketClient
    s.connect(address)
ConnectionRefusedError: [Errno 111] Connection refused
Process Process-1106:
Traceback (most recent call last):
  File "/home/conda/envs/topology/lib/python3.10/multiprocessing/managers.py", line 810, in _callmethod
    conn = self._tls.connection
AttributeError: 'ForkAwareLocal' object has no attribute 'connection'

During handling of the above exception, another exception occurred:

Traceback (most recent call last):
  File "/home/conda/envs/topology/lib/python3.10/multiprocessing/process.py", line 314, in _bootstrap
    self.run()
  File "/home/conda/envs/topology/lib/python3.10/multiprocessing/process.py", line 108, in run
    self._target(*self._args, **self._kwargs)
  File "/home/jnoltmann/topology/src/E2.py", line 136, in get_c_lmlpmp_per_process
    return_dict[process_i] = E2_E3_E4_E5_get_c_lmlpmp(
  File "<string>", line 2, in __setitem__
  File "/home/conda/envs/topology/lib/python3.10/multiprocessing/managers.py", line 814, in _callmethod
    self._connect()
  File "/home/conda/envs/topology/lib/python3.10/multiprocessing/managers.py", line 801, in _connect
    conn = self._Client(self._token.address, authkey=self._authkey)
  File "/home/conda/envs/topology/lib/python3.10/multiprocessing/connection.py", line 502, in Client
    c = SocketClient(address)
  File "/home/conda/envs/topology/lib/python3.10/multiprocessing/connection.py", line 630, in SocketClient
    s.connect(address)
ConnectionRefusedError: [Errno 111] Connection refused
Process Process-1105:
Traceback (most recent call last):
  File "/home/conda/envs/topology/lib/python3.10/multiprocessing/managers.py", line 810, in _callmethod
    conn = self._tls.connection
AttributeError: 'ForkAwareLocal' object has no attribute 'connection'

During handling of the above exception, another exception occurred:

Traceback (most recent call last):
  File "/home/conda/envs/topology/lib/python3.10/multiprocessing/process.py", line 314, in _bootstrap
    self.run()
  File "/home/conda/envs/topology/lib/python3.10/multiprocessing/process.py", line 108, in run
    self._target(*self._args, **self._kwargs)
  File "/home/jnoltmann/topology/src/E2.py", line 136, in get_c_lmlpmp_per_process
    return_dict[process_i] = E2_E3_E4_E5_get_c_lmlpmp(
  File "<string>", line 2, in __setitem__
  File "/home/conda/envs/topology/lib/python3.10/multiprocessing/managers.py", line 814, in _callmethod
    self._connect()
  File "/home/conda/envs/topology/lib/python3.10/multiprocessing/managers.py", line 801, in _connect
    conn = self._Client(self._token.address, authkey=self._authkey)
  File "/home/conda/envs/topology/lib/python3.10/multiprocessing/connection.py", line 502, in Client
    c = SocketClient(address)
  File "/home/conda/envs/topology/lib/python3.10/multiprocessing/connection.py", line 630, in SocketClient
    s.connect(address)
ConnectionRefusedError: [Errno 111] Connection refused
Process Process-1104:
Traceback (most recent call last):
  File "/home/conda/envs/topology/lib/python3.10/multiprocessing/managers.py", line 810, in _callmethod
    conn = self._tls.connection
AttributeError: 'ForkAwareLocal' object has no attribute 'connection'

During handling of the above exception, another exception occurred:

Traceback (most recent call last):
  File "/home/conda/envs/topology/lib/python3.10/multiprocessing/process.py", line 314, in _bootstrap
    self.run()
  File "/home/conda/envs/topology/lib/python3.10/multiprocessing/process.py", line 108, in run
    self._target(*self._args, **self._kwargs)
  File "/home/jnoltmann/topology/src/E2.py", line 136, in get_c_lmlpmp_per_process
    return_dict[process_i] = E2_E3_E4_E5_get_c_lmlpmp(
  File "<string>", line 2, in __setitem__
  File "/home/conda/envs/topology/lib/python3.10/multiprocessing/managers.py", line 814, in _callmethod
    self._connect()
  File "/home/conda/envs/topology/lib/python3.10/multiprocessing/managers.py", line 801, in _connect
    conn = self._Client(self._token.address, authkey=self._authkey)
  File "/home/conda/envs/topology/lib/python3.10/multiprocessing/connection.py", line 502, in Client
    c = SocketClient(address)
  File "/home/conda/envs/topology/lib/python3.10/multiprocessing/connection.py", line 630, in SocketClient
    s.connect(address)
ConnectionRefusedError: [Errno 111] Connection refused
Process Process-1108:
Traceback (most recent call last):
  File "/home/conda/envs/topology/lib/python3.10/multiprocessing/managers.py", line 810, in _callmethod
    conn = self._tls.connection
AttributeError: 'ForkAwareLocal' object has no attribute 'connection'

During handling of the above exception, another exception occurred:

Traceback (most recent call last):
  File "/home/conda/envs/topology/lib/python3.10/multiprocessing/process.py", line 314, in _bootstrap
    self.run()
  File "/home/conda/envs/topology/lib/python3.10/multiprocessing/process.py", line 108, in run
    self._target(*self._args, **self._kwargs)
  File "/home/jnoltmann/topology/src/E2.py", line 136, in get_c_lmlpmp_per_process
    return_dict[process_i] = E2_E3_E4_E5_get_c_lmlpmp(
  File "<string>", line 2, in __setitem__
  File "/home/conda/envs/topology/lib/python3.10/multiprocessing/managers.py", line 814, in _callmethod
    self._connect()
  File "/home/conda/envs/topology/lib/python3.10/multiprocessing/managers.py", line 801, in _connect
    conn = self._Client(self._token.address, authkey=self._authkey)
  File "/home/conda/envs/topology/lib/python3.10/multiprocessing/connection.py", line 502, in Client
    c = SocketClient(address)
  File "/home/conda/envs/topology/lib/python3.10/multiprocessing/connection.py", line 630, in SocketClient
    s.connect(address)
ConnectionRefusedError: [Errno 111] Connection refused
Process Process-1073:
Traceback (most recent call last):
  File "/home/conda/envs/topology/lib/python3.10/multiprocessing/managers.py", line 810, in _callmethod
    conn = self._tls.connection
AttributeError: 'ForkAwareLocal' object has no attribute 'connection'

During handling of the above exception, another exception occurred:

Traceback (most recent call last):
  File "/home/conda/envs/topology/lib/python3.10/multiprocessing/process.py", line 314, in _bootstrap
    self.run()
  File "/home/conda/envs/topology/lib/python3.10/multiprocessing/process.py", line 108, in run
    self._target(*self._args, **self._kwargs)
  File "/home/jnoltmann/topology/src/E2.py", line 136, in get_c_lmlpmp_per_process
    return_dict[process_i] = E2_E3_E4_E5_get_c_lmlpmp(
  File "<string>", line 2, in __setitem__
  File "/home/conda/envs/topology/lib/python3.10/multiprocessing/managers.py", line 814, in _callmethod
    self._connect()
  File "/home/conda/envs/topology/lib/python3.10/multiprocessing/managers.py", line 801, in _connect
    conn = self._Client(self._token.address, authkey=self._authkey)
  File "/home/conda/envs/topology/lib/python3.10/multiprocessing/connection.py", line 502, in Client
    c = SocketClient(address)
  File "/home/conda/envs/topology/lib/python3.10/multiprocessing/connection.py", line 630, in SocketClient
    s.connect(address)
ConnectionRefusedError: [Errno 111] Connection refused
Process Process-1079:
Traceback (most recent call last):
  File "/home/conda/envs/topology/lib/python3.10/multiprocessing/managers.py", line 810, in _callmethod
    conn = self._tls.connection
AttributeError: 'ForkAwareLocal' object has no attribute 'connection'

During handling of the above exception, another exception occurred:

Traceback (most recent call last):
  File "/home/conda/envs/topology/lib/python3.10/multiprocessing/process.py", line 314, in _bootstrap
    self.run()
  File "/home/conda/envs/topology/lib/python3.10/multiprocessing/process.py", line 108, in run
    self._target(*self._args, **self._kwargs)
  File "/home/jnoltmann/topology/src/E2.py", line 136, in get_c_lmlpmp_per_process
    return_dict[process_i] = E2_E3_E4_E5_get_c_lmlpmp(
  File "<string>", line 2, in __setitem__
  File "/home/conda/envs/topology/lib/python3.10/multiprocessing/managers.py", line 814, in _callmethod
    self._connect()
  File "/home/conda/envs/topology/lib/python3.10/multiprocessing/managers.py", line 801, in _connect
    conn = self._Client(self._token.address, authkey=self._authkey)
  File "/home/conda/envs/topology/lib/python3.10/multiprocessing/connection.py", line 502, in Client
    c = SocketClient(address)
  File "/home/conda/envs/topology/lib/python3.10/multiprocessing/connection.py", line 630, in SocketClient
    s.connect(address)
ConnectionRefusedError: [Errno 111] Connection refused
Process Process-1118:
Traceback (most recent call last):
  File "/home/conda/envs/topology/lib/python3.10/multiprocessing/managers.py", line 810, in _callmethod
    conn = self._tls.connection
AttributeError: 'ForkAwareLocal' object has no attribute 'connection'

During handling of the above exception, another exception occurred:

Traceback (most recent call last):
  File "/home/conda/envs/topology/lib/python3.10/multiprocessing/process.py", line 314, in _bootstrap
    self.run()
  File "/home/conda/envs/topology/lib/python3.10/multiprocessing/process.py", line 108, in run
    self._target(*self._args, **self._kwargs)
  File "/home/jnoltmann/topology/src/E2.py", line 136, in get_c_lmlpmp_per_process
    return_dict[process_i] = E2_E3_E4_E5_get_c_lmlpmp(
  File "<string>", line 2, in __setitem__
  File "/home/conda/envs/topology/lib/python3.10/multiprocessing/managers.py", line 814, in _callmethod
    self._connect()
  File "/home/conda/envs/topology/lib/python3.10/multiprocessing/managers.py", line 801, in _connect
    conn = self._Client(self._token.address, authkey=self._authkey)
  File "/home/conda/envs/topology/lib/python3.10/multiprocessing/connection.py", line 502, in Client
    c = SocketClient(address)
  File "/home/conda/envs/topology/lib/python3.10/multiprocessing/connection.py", line 630, in SocketClient
    s.connect(address)
ConnectionRefusedError: [Errno 111] Connection refused
Process Process-1117:
Traceback (most recent call last):
  File "/home/conda/envs/topology/lib/python3.10/multiprocessing/managers.py", line 810, in _callmethod
    conn = self._tls.connection
AttributeError: 'ForkAwareLocal' object has no attribute 'connection'

During handling of the above exception, another exception occurred:

Traceback (most recent call last):
  File "/home/conda/envs/topology/lib/python3.10/multiprocessing/process.py", line 314, in _bootstrap
    self.run()
  File "/home/conda/envs/topology/lib/python3.10/multiprocessing/process.py", line 108, in run
    self._target(*self._args, **self._kwargs)
  File "/home/jnoltmann/topology/src/E2.py", line 136, in get_c_lmlpmp_per_process
    return_dict[process_i] = E2_E3_E4_E5_get_c_lmlpmp(
  File "<string>", line 2, in __setitem__
  File "/home/conda/envs/topology/lib/python3.10/multiprocessing/managers.py", line 814, in _callmethod
    self._connect()
  File "/home/conda/envs/topology/lib/python3.10/multiprocessing/managers.py", line 801, in _connect
    conn = self._Client(self._token.address, authkey=self._authkey)
  File "/home/conda/envs/topology/lib/python3.10/multiprocessing/connection.py", line 502, in Client
    c = SocketClient(address)
  File "/home/conda/envs/topology/lib/python3.10/multiprocessing/connection.py", line 630, in SocketClient
    s.connect(address)
ConnectionRefusedError: [Errno 111] Connection refused
Process Process-1102:
Traceback (most recent call last):
  File "/home/conda/envs/topology/lib/python3.10/multiprocessing/managers.py", line 810, in _callmethod
    conn = self._tls.connection
AttributeError: 'ForkAwareLocal' object has no attribute 'connection'

During handling of the above exception, another exception occurred:

Traceback (most recent call last):
  File "/home/conda/envs/topology/lib/python3.10/multiprocessing/process.py", line 314, in _bootstrap
    self.run()
  File "/home/conda/envs/topology/lib/python3.10/multiprocessing/process.py", line 108, in run
    self._target(*self._args, **self._kwargs)
  File "/home/jnoltmann/topology/src/E2.py", line 136, in get_c_lmlpmp_per_process
    return_dict[process_i] = E2_E3_E4_E5_get_c_lmlpmp(
  File "<string>", line 2, in __setitem__
  File "/home/conda/envs/topology/lib/python3.10/multiprocessing/managers.py", line 814, in _callmethod
    self._connect()
  File "/home/conda/envs/topology/lib/python3.10/multiprocessing/managers.py", line 801, in _connect
    conn = self._Client(self._token.address, authkey=self._authkey)
  File "/home/conda/envs/topology/lib/python3.10/multiprocessing/connection.py", line 502, in Client
    c = SocketClient(address)
  File "/home/conda/envs/topology/lib/python3.10/multiprocessing/connection.py", line 630, in SocketClient
    s.connect(address)
ConnectionRefusedError: [Errno 111] Connection refused
Process Process-1137:
Traceback (most recent call last):
  File "/home/conda/envs/topology/lib/python3.10/multiprocessing/managers.py", line 810, in _callmethod
    conn = self._tls.connection
AttributeError: 'ForkAwareLocal' object has no attribute 'connection'

During handling of the above exception, another exception occurred:

Traceback (most recent call last):
  File "/home/conda/envs/topology/lib/python3.10/multiprocessing/process.py", line 314, in _bootstrap
    self.run()
  File "/home/conda/envs/topology/lib/python3.10/multiprocessing/process.py", line 108, in run
    self._target(*self._args, **self._kwargs)
  File "/home/jnoltmann/topology/src/E2.py", line 136, in get_c_lmlpmp_per_process
    return_dict[process_i] = E2_E3_E4_E5_get_c_lmlpmp(
  File "<string>", line 2, in __setitem__
  File "/home/conda/envs/topology/lib/python3.10/multiprocessing/managers.py", line 814, in _callmethod
    self._connect()
  File "/home/conda/envs/topology/lib/python3.10/multiprocessing/managers.py", line 801, in _connect
    conn = self._Client(self._token.address, authkey=self._authkey)
  File "/home/conda/envs/topology/lib/python3.10/multiprocessing/connection.py", line 502, in Client
    c = SocketClient(address)
  File "/home/conda/envs/topology/lib/python3.10/multiprocessing/connection.py", line 630, in SocketClient
    s.connect(address)
ConnectionRefusedError: [Errno 111] Connection refused
Process Process-1070:
Traceback (most recent call last):
  File "/home/conda/envs/topology/lib/python3.10/multiprocessing/managers.py", line 810, in _callmethod
    conn = self._tls.connection
AttributeError: 'ForkAwareLocal' object has no attribute 'connection'

During handling of the above exception, another exception occurred:

Traceback (most recent call last):
  File "/home/conda/envs/topology/lib/python3.10/multiprocessing/process.py", line 314, in _bootstrap
    self.run()
  File "/home/conda/envs/topology/lib/python3.10/multiprocessing/process.py", line 108, in run
    self._target(*self._args, **self._kwargs)
  File "/home/jnoltmann/topology/src/E2.py", line 136, in get_c_lmlpmp_per_process
    return_dict[process_i] = E2_E3_E4_E5_get_c_lmlpmp(
  File "<string>", line 2, in __setitem__
  File "/home/conda/envs/topology/lib/python3.10/multiprocessing/managers.py", line 814, in _callmethod
    self._connect()
  File "/home/conda/envs/topology/lib/python3.10/multiprocessing/managers.py", line 801, in _connect
    conn = self._Client(self._token.address, authkey=self._authkey)
  File "/home/conda/envs/topology/lib/python3.10/multiprocessing/connection.py", line 502, in Client
    c = SocketClient(address)
  File "/home/conda/envs/topology/lib/python3.10/multiprocessing/connection.py", line 630, in SocketClient
    s.connect(address)
ConnectionRefusedError: [Errno 111] Connection refused
Process Process-1132:
Traceback (most recent call last):
  File "/home/conda/envs/topology/lib/python3.10/multiprocessing/managers.py", line 810, in _callmethod
    conn = self._tls.connection
AttributeError: 'ForkAwareLocal' object has no attribute 'connection'

During handling of the above exception, another exception occurred:

Traceback (most recent call last):
  File "/home/conda/envs/topology/lib/python3.10/multiprocessing/process.py", line 314, in _bootstrap
    self.run()
  File "/home/conda/envs/topology/lib/python3.10/multiprocessing/process.py", line 108, in run
    self._target(*self._args, **self._kwargs)
  File "/home/jnoltmann/topology/src/E2.py", line 136, in get_c_lmlpmp_per_process
    return_dict[process_i] = E2_E3_E4_E5_get_c_lmlpmp(
  File "<string>", line 2, in __setitem__
  File "/home/conda/envs/topology/lib/python3.10/multiprocessing/managers.py", line 814, in _callmethod
    self._connect()
  File "/home/conda/envs/topology/lib/python3.10/multiprocessing/managers.py", line 801, in _connect
    conn = self._Client(self._token.address, authkey=self._authkey)
  File "/home/conda/envs/topology/lib/python3.10/multiprocessing/connection.py", line 502, in Client
    c = SocketClient(address)
  File "/home/conda/envs/topology/lib/python3.10/multiprocessing/connection.py", line 630, in SocketClient
    s.connect(address)
ConnectionRefusedError: [Errno 111] Connection refused
Process Process-1064:
Traceback (most recent call last):
  File "/home/conda/envs/topology/lib/python3.10/multiprocessing/managers.py", line 810, in _callmethod
    conn = self._tls.connection
AttributeError: 'ForkAwareLocal' object has no attribute 'connection'

During handling of the above exception, another exception occurred:

Traceback (most recent call last):
  File "/home/conda/envs/topology/lib/python3.10/multiprocessing/process.py", line 314, in _bootstrap
    self.run()
  File "/home/conda/envs/topology/lib/python3.10/multiprocessing/process.py", line 108, in run
    self._target(*self._args, **self._kwargs)
  File "/home/jnoltmann/topology/src/E2.py", line 136, in get_c_lmlpmp_per_process
    return_dict[process_i] = E2_E3_E4_E5_get_c_lmlpmp(
  File "<string>", line 2, in __setitem__
  File "/home/conda/envs/topology/lib/python3.10/multiprocessing/managers.py", line 814, in _callmethod
    self._connect()
  File "/home/conda/envs/topology/lib/python3.10/multiprocessing/managers.py", line 801, in _connect
    conn = self._Client(self._token.address, authkey=self._authkey)
  File "/home/conda/envs/topology/lib/python3.10/multiprocessing/connection.py", line 502, in Client
    c = SocketClient(address)
  File "/home/conda/envs/topology/lib/python3.10/multiprocessing/connection.py", line 630, in SocketClient
    s.connect(address)
ConnectionRefusedError: [Errno 111] Connection refused
Process Process-1095:
Traceback (most recent call last):
  File "/home/conda/envs/topology/lib/python3.10/multiprocessing/managers.py", line 810, in _callmethod
    conn = self._tls.connection
AttributeError: 'ForkAwareLocal' object has no attribute 'connection'

During handling of the above exception, another exception occurred:

Traceback (most recent call last):
  File "/home/conda/envs/topology/lib/python3.10/multiprocessing/process.py", line 314, in _bootstrap
    self.run()
  File "/home/conda/envs/topology/lib/python3.10/multiprocessing/process.py", line 108, in run
    self._target(*self._args, **self._kwargs)
  File "/home/jnoltmann/topology/src/E2.py", line 136, in get_c_lmlpmp_per_process
    return_dict[process_i] = E2_E3_E4_E5_get_c_lmlpmp(
  File "<string>", line 2, in __setitem__
  File "/home/conda/envs/topology/lib/python3.10/multiprocessing/managers.py", line 814, in _callmethod
    self._connect()
  File "/home/conda/envs/topology/lib/python3.10/multiprocessing/managers.py", line 801, in _connect
    conn = self._Client(self._token.address, authkey=self._authkey)
  File "/home/conda/envs/topology/lib/python3.10/multiprocessing/connection.py", line 502, in Client
    c = SocketClient(address)
  File "/home/conda/envs/topology/lib/python3.10/multiprocessing/connection.py", line 630, in SocketClient
    s.connect(address)
ConnectionRefusedError: [Errno 111] Connection refused
Process Process-1128:
Traceback (most recent call last):
  File "/home/conda/envs/topology/lib/python3.10/multiprocessing/managers.py", line 810, in _callmethod
    conn = self._tls.connection
AttributeError: 'ForkAwareLocal' object has no attribute 'connection'

During handling of the above exception, another exception occurred:

Traceback (most recent call last):
  File "/home/conda/envs/topology/lib/python3.10/multiprocessing/process.py", line 314, in _bootstrap
    self.run()
  File "/home/conda/envs/topology/lib/python3.10/multiprocessing/process.py", line 108, in run
    self._target(*self._args, **self._kwargs)
  File "/home/jnoltmann/topology/src/E2.py", line 136, in get_c_lmlpmp_per_process
    return_dict[process_i] = E2_E3_E4_E5_get_c_lmlpmp(
  File "<string>", line 2, in __setitem__
  File "/home/conda/envs/topology/lib/python3.10/multiprocessing/managers.py", line 814, in _callmethod
    self._connect()
  File "/home/conda/envs/topology/lib/python3.10/multiprocessing/managers.py", line 801, in _connect
    conn = self._Client(self._token.address, authkey=self._authkey)
  File "/home/conda/envs/topology/lib/python3.10/multiprocessing/connection.py", line 502, in Client
    c = SocketClient(address)
  File "/home/conda/envs/topology/lib/python3.10/multiprocessing/connection.py", line 630, in SocketClient
    s.connect(address)
ConnectionRefusedError: [Errno 111] Connection refused
Process Process-1081:
Traceback (most recent call last):
  File "/home/conda/envs/topology/lib/python3.10/multiprocessing/managers.py", line 810, in _callmethod
    conn = self._tls.connection
AttributeError: 'ForkAwareLocal' object has no attribute 'connection'

During handling of the above exception, another exception occurred:

Traceback (most recent call last):
  File "/home/conda/envs/topology/lib/python3.10/multiprocessing/process.py", line 314, in _bootstrap
    self.run()
  File "/home/conda/envs/topology/lib/python3.10/multiprocessing/process.py", line 108, in run
    self._target(*self._args, **self._kwargs)
  File "/home/jnoltmann/topology/src/E2.py", line 136, in get_c_lmlpmp_per_process
    return_dict[process_i] = E2_E3_E4_E5_get_c_lmlpmp(
  File "<string>", line 2, in __setitem__
  File "/home/conda/envs/topology/lib/python3.10/multiprocessing/managers.py", line 814, in _callmethod
    self._connect()
  File "/home/conda/envs/topology/lib/python3.10/multiprocessing/managers.py", line 801, in _connect
    conn = self._Client(self._token.address, authkey=self._authkey)
  File "/home/conda/envs/topology/lib/python3.10/multiprocessing/connection.py", line 502, in Client
    c = SocketClient(address)
  File "/home/conda/envs/topology/lib/python3.10/multiprocessing/connection.py", line 630, in SocketClient
    s.connect(address)
ConnectionRefusedError: [Errno 111] Connection refused
Process Process-1123:
Traceback (most recent call last):
  File "/home/conda/envs/topology/lib/python3.10/multiprocessing/managers.py", line 810, in _callmethod
    conn = self._tls.connection
AttributeError: 'ForkAwareLocal' object has no attribute 'connection'

During handling of the above exception, another exception occurred:

Traceback (most recent call last):
  File "/home/conda/envs/topology/lib/python3.10/multiprocessing/process.py", line 314, in _bootstrap
    self.run()
  File "/home/conda/envs/topology/lib/python3.10/multiprocessing/process.py", line 108, in run
    self._target(*self._args, **self._kwargs)
  File "/home/jnoltmann/topology/src/E2.py", line 136, in get_c_lmlpmp_per_process
    return_dict[process_i] = E2_E3_E4_E5_get_c_lmlpmp(
  File "<string>", line 2, in __setitem__
  File "/home/conda/envs/topology/lib/python3.10/multiprocessing/managers.py", line 814, in _callmethod
    self._connect()
  File "/home/conda/envs/topology/lib/python3.10/multiprocessing/managers.py", line 801, in _connect
    conn = self._Client(self._token.address, authkey=self._authkey)
  File "/home/conda/envs/topology/lib/python3.10/multiprocessing/connection.py", line 502, in Client
    c = SocketClient(address)
  File "/home/conda/envs/topology/lib/python3.10/multiprocessing/connection.py", line 630, in SocketClient
    s.connect(address)
ConnectionRefusedError: [Errno 111] Connection refused
Process Process-1121:
Traceback (most recent call last):
  File "/home/conda/envs/topology/lib/python3.10/multiprocessing/managers.py", line 810, in _callmethod
    conn = self._tls.connection
AttributeError: 'ForkAwareLocal' object has no attribute 'connection'

During handling of the above exception, another exception occurred:

Traceback (most recent call last):
  File "/home/conda/envs/topology/lib/python3.10/multiprocessing/process.py", line 314, in _bootstrap
    self.run()
  File "/home/conda/envs/topology/lib/python3.10/multiprocessing/process.py", line 108, in run
    self._target(*self._args, **self._kwargs)
  File "/home/jnoltmann/topology/src/E2.py", line 136, in get_c_lmlpmp_per_process
    return_dict[process_i] = E2_E3_E4_E5_get_c_lmlpmp(
  File "<string>", line 2, in __setitem__
  File "/home/conda/envs/topology/lib/python3.10/multiprocessing/managers.py", line 814, in _callmethod
    self._connect()
  File "/home/conda/envs/topology/lib/python3.10/multiprocessing/managers.py", line 801, in _connect
    conn = self._Client(self._token.address, authkey=self._authkey)
  File "/home/conda/envs/topology/lib/python3.10/multiprocessing/connection.py", line 502, in Client
    c = SocketClient(address)
  File "/home/conda/envs/topology/lib/python3.10/multiprocessing/connection.py", line 630, in SocketClient
    s.connect(address)
ConnectionRefusedError: [Errno 111] Connection refused
Process Process-1113:
Traceback (most recent call last):
  File "/home/conda/envs/topology/lib/python3.10/multiprocessing/managers.py", line 810, in _callmethod
    conn = self._tls.connection
AttributeError: 'ForkAwareLocal' object has no attribute 'connection'

During handling of the above exception, another exception occurred:

Traceback (most recent call last):
  File "/home/conda/envs/topology/lib/python3.10/multiprocessing/process.py", line 314, in _bootstrap
    self.run()
  File "/home/conda/envs/topology/lib/python3.10/multiprocessing/process.py", line 108, in run
    self._target(*self._args, **self._kwargs)
  File "/home/jnoltmann/topology/src/E2.py", line 136, in get_c_lmlpmp_per_process
    return_dict[process_i] = E2_E3_E4_E5_get_c_lmlpmp(
  File "<string>", line 2, in __setitem__
  File "/home/conda/envs/topology/lib/python3.10/multiprocessing/managers.py", line 814, in _callmethod
    self._connect()
  File "/home/conda/envs/topology/lib/python3.10/multiprocessing/managers.py", line 801, in _connect
    conn = self._Client(self._token.address, authkey=self._authkey)
  File "/home/conda/envs/topology/lib/python3.10/multiprocessing/connection.py", line 502, in Client
    c = SocketClient(address)
  File "/home/conda/envs/topology/lib/python3.10/multiprocessing/connection.py", line 630, in SocketClient
    s.connect(address)
ConnectionRefusedError: [Errno 111] Connection refused
Process Process-1125:
Traceback (most recent call last):
  File "/home/conda/envs/topology/lib/python3.10/multiprocessing/managers.py", line 810, in _callmethod
    conn = self._tls.connection
AttributeError: 'ForkAwareLocal' object has no attribute 'connection'

During handling of the above exception, another exception occurred:

Traceback (most recent call last):
  File "/home/conda/envs/topology/lib/python3.10/multiprocessing/process.py", line 314, in _bootstrap
    self.run()
  File "/home/conda/envs/topology/lib/python3.10/multiprocessing/process.py", line 108, in run
    self._target(*self._args, **self._kwargs)
  File "/home/jnoltmann/topology/src/E2.py", line 136, in get_c_lmlpmp_per_process
    return_dict[process_i] = E2_E3_E4_E5_get_c_lmlpmp(
  File "<string>", line 2, in __setitem__
  File "/home/conda/envs/topology/lib/python3.10/multiprocessing/managers.py", line 814, in _callmethod
    self._connect()
  File "/home/conda/envs/topology/lib/python3.10/multiprocessing/managers.py", line 801, in _connect
    conn = self._Client(self._token.address, authkey=self._authkey)
  File "/home/conda/envs/topology/lib/python3.10/multiprocessing/connection.py", line 502, in Client
    c = SocketClient(address)
  File "/home/conda/envs/topology/lib/python3.10/multiprocessing/connection.py", line 630, in SocketClient
    s.connect(address)
ConnectionRefusedError: [Errno 111] Connection refused
Process Process-1130:
Traceback (most recent call last):
  File "/home/conda/envs/topology/lib/python3.10/multiprocessing/managers.py", line 810, in _callmethod
    conn = self._tls.connection
AttributeError: 'ForkAwareLocal' object has no attribute 'connection'

During handling of the above exception, another exception occurred:

Traceback (most recent call last):
  File "/home/conda/envs/topology/lib/python3.10/multiprocessing/process.py", line 314, in _bootstrap
    self.run()
  File "/home/conda/envs/topology/lib/python3.10/multiprocessing/process.py", line 108, in run
    self._target(*self._args, **self._kwargs)
  File "/home/jnoltmann/topology/src/E2.py", line 136, in get_c_lmlpmp_per_process
    return_dict[process_i] = E2_E3_E4_E5_get_c_lmlpmp(
  File "<string>", line 2, in __setitem__
  File "/home/conda/envs/topology/lib/python3.10/multiprocessing/managers.py", line 814, in _callmethod
    self._connect()
  File "/home/conda/envs/topology/lib/python3.10/multiprocessing/managers.py", line 801, in _connect
    conn = self._Client(self._token.address, authkey=self._authkey)
  File "/home/conda/envs/topology/lib/python3.10/multiprocessing/connection.py", line 502, in Client
    c = SocketClient(address)
  File "/home/conda/envs/topology/lib/python3.10/multiprocessing/connection.py", line 630, in SocketClient
    s.connect(address)
ConnectionRefusedError: [Errno 111] Connection refused
Process Process-1093:
Traceback (most recent call last):
  File "/home/conda/envs/topology/lib/python3.10/multiprocessing/managers.py", line 810, in _callmethod
    conn = self._tls.connection
AttributeError: 'ForkAwareLocal' object has no attribute 'connection'

During handling of the above exception, another exception occurred:

Traceback (most recent call last):
  File "/home/conda/envs/topology/lib/python3.10/multiprocessing/process.py", line 314, in _bootstrap
    self.run()
  File "/home/conda/envs/topology/lib/python3.10/multiprocessing/process.py", line 108, in run
    self._target(*self._args, **self._kwargs)
  File "/home/jnoltmann/topology/src/E2.py", line 136, in get_c_lmlpmp_per_process
    return_dict[process_i] = E2_E3_E4_E5_get_c_lmlpmp(
  File "<string>", line 2, in __setitem__
  File "/home/conda/envs/topology/lib/python3.10/multiprocessing/managers.py", line 814, in _callmethod
    self._connect()
  File "/home/conda/envs/topology/lib/python3.10/multiprocessing/managers.py", line 801, in _connect
    conn = self._Client(self._token.address, authkey=self._authkey)
  File "/home/conda/envs/topology/lib/python3.10/multiprocessing/connection.py", line 502, in Client
    c = SocketClient(address)
  File "/home/conda/envs/topology/lib/python3.10/multiprocessing/connection.py", line 630, in SocketClient
    s.connect(address)
ConnectionRefusedError: [Errno 111] Connection refused
Process Process-1133:
Traceback (most recent call last):
  File "/home/conda/envs/topology/lib/python3.10/multiprocessing/managers.py", line 810, in _callmethod
    conn = self._tls.connection
AttributeError: 'ForkAwareLocal' object has no attribute 'connection'

During handling of the above exception, another exception occurred:

Traceback (most recent call last):
  File "/home/conda/envs/topology/lib/python3.10/multiprocessing/process.py", line 314, in _bootstrap
    self.run()
  File "/home/conda/envs/topology/lib/python3.10/multiprocessing/process.py", line 108, in run
    self._target(*self._args, **self._kwargs)
  File "/home/jnoltmann/topology/src/E2.py", line 136, in get_c_lmlpmp_per_process
    return_dict[process_i] = E2_E3_E4_E5_get_c_lmlpmp(
  File "<string>", line 2, in __setitem__
  File "/home/conda/envs/topology/lib/python3.10/multiprocessing/managers.py", line 814, in _callmethod
    self._connect()
  File "/home/conda/envs/topology/lib/python3.10/multiprocessing/managers.py", line 801, in _connect
    conn = self._Client(self._token.address, authkey=self._authkey)
  File "/home/conda/envs/topology/lib/python3.10/multiprocessing/connection.py", line 502, in Client
    c = SocketClient(address)
  File "/home/conda/envs/topology/lib/python3.10/multiprocessing/connection.py", line 630, in SocketClient
    s.connect(address)
ConnectionRefusedError: [Errno 111] Connection refused
Process Process-1100:
Traceback (most recent call last):
  File "/home/conda/envs/topology/lib/python3.10/multiprocessing/managers.py", line 810, in _callmethod
    conn = self._tls.connection
AttributeError: 'ForkAwareLocal' object has no attribute 'connection'

During handling of the above exception, another exception occurred:

Traceback (most recent call last):
  File "/home/conda/envs/topology/lib/python3.10/multiprocessing/process.py", line 314, in _bootstrap
    self.run()
  File "/home/conda/envs/topology/lib/python3.10/multiprocessing/process.py", line 108, in run
    self._target(*self._args, **self._kwargs)
  File "/home/jnoltmann/topology/src/E2.py", line 136, in get_c_lmlpmp_per_process
    return_dict[process_i] = E2_E3_E4_E5_get_c_lmlpmp(
  File "<string>", line 2, in __setitem__
  File "/home/conda/envs/topology/lib/python3.10/multiprocessing/managers.py", line 814, in _callmethod
    self._connect()
  File "/home/conda/envs/topology/lib/python3.10/multiprocessing/managers.py", line 801, in _connect
    conn = self._Client(self._token.address, authkey=self._authkey)
  File "/home/conda/envs/topology/lib/python3.10/multiprocessing/connection.py", line 502, in Client
    c = SocketClient(address)
  File "/home/conda/envs/topology/lib/python3.10/multiprocessing/connection.py", line 630, in SocketClient
    s.connect(address)
ConnectionRefusedError: [Errno 111] Connection refused
Process Process-1114:
Traceback (most recent call last):
  File "/home/conda/envs/topology/lib/python3.10/multiprocessing/managers.py", line 810, in _callmethod
    conn = self._tls.connection
AttributeError: 'ForkAwareLocal' object has no attribute 'connection'

During handling of the above exception, another exception occurred:

Traceback (most recent call last):
  File "/home/conda/envs/topology/lib/python3.10/multiprocessing/process.py", line 314, in _bootstrap
    self.run()
  File "/home/conda/envs/topology/lib/python3.10/multiprocessing/process.py", line 108, in run
    self._target(*self._args, **self._kwargs)
  File "/home/jnoltmann/topology/src/E2.py", line 136, in get_c_lmlpmp_per_process
    return_dict[process_i] = E2_E3_E4_E5_get_c_lmlpmp(
  File "<string>", line 2, in __setitem__
  File "/home/conda/envs/topology/lib/python3.10/multiprocessing/managers.py", line 814, in _callmethod
    self._connect()
  File "/home/conda/envs/topology/lib/python3.10/multiprocessing/managers.py", line 801, in _connect
    conn = self._Client(self._token.address, authkey=self._authkey)
  File "/home/conda/envs/topology/lib/python3.10/multiprocessing/connection.py", line 502, in Client
    c = SocketClient(address)
  File "/home/conda/envs/topology/lib/python3.10/multiprocessing/connection.py", line 630, in SocketClient
    s.connect(address)
ConnectionRefusedError: [Errno 111] Connection refused
Process Process-1124:
Traceback (most recent call last):
  File "/home/conda/envs/topology/lib/python3.10/multiprocessing/managers.py", line 810, in _callmethod
    conn = self._tls.connection
AttributeError: 'ForkAwareLocal' object has no attribute 'connection'

During handling of the above exception, another exception occurred:

Traceback (most recent call last):
  File "/home/conda/envs/topology/lib/python3.10/multiprocessing/process.py", line 314, in _bootstrap
    self.run()
  File "/home/conda/envs/topology/lib/python3.10/multiprocessing/process.py", line 108, in run
    self._target(*self._args, **self._kwargs)
  File "/home/jnoltmann/topology/src/E2.py", line 136, in get_c_lmlpmp_per_process
    return_dict[process_i] = E2_E3_E4_E5_get_c_lmlpmp(
  File "<string>", line 2, in __setitem__
  File "/home/conda/envs/topology/lib/python3.10/multiprocessing/managers.py", line 814, in _callmethod
    self._connect()
  File "/home/conda/envs/topology/lib/python3.10/multiprocessing/managers.py", line 801, in _connect
    conn = self._Client(self._token.address, authkey=self._authkey)
  File "/home/conda/envs/topology/lib/python3.10/multiprocessing/connection.py", line 502, in Client
    c = SocketClient(address)
  File "/home/conda/envs/topology/lib/python3.10/multiprocessing/connection.py", line 630, in SocketClient
    s.connect(address)
ConnectionRefusedError: [Errno 111] Connection refused
Process Process-1134:
Traceback (most recent call last):
  File "/home/conda/envs/topology/lib/python3.10/multiprocessing/managers.py", line 810, in _callmethod
    conn = self._tls.connection
AttributeError: 'ForkAwareLocal' object has no attribute 'connection'

During handling of the above exception, another exception occurred:

Traceback (most recent call last):
  File "/home/conda/envs/topology/lib/python3.10/multiprocessing/process.py", line 314, in _bootstrap
    self.run()
  File "/home/conda/envs/topology/lib/python3.10/multiprocessing/process.py", line 108, in run
    self._target(*self._args, **self._kwargs)
  File "/home/jnoltmann/topology/src/E2.py", line 136, in get_c_lmlpmp_per_process
    return_dict[process_i] = E2_E3_E4_E5_get_c_lmlpmp(
  File "<string>", line 2, in __setitem__
  File "/home/conda/envs/topology/lib/python3.10/multiprocessing/managers.py", line 814, in _callmethod
    self._connect()
  File "/home/conda/envs/topology/lib/python3.10/multiprocessing/managers.py", line 801, in _connect
    conn = self._Client(self._token.address, authkey=self._authkey)
  File "/home/conda/envs/topology/lib/python3.10/multiprocessing/connection.py", line 502, in Client
    c = SocketClient(address)
  File "/home/conda/envs/topology/lib/python3.10/multiprocessing/connection.py", line 630, in SocketClient
    s.connect(address)
ConnectionRefusedError: [Errno 111] Connection refused
Process Process-1109:
Traceback (most recent call last):
  File "/home/conda/envs/topology/lib/python3.10/multiprocessing/managers.py", line 810, in _callmethod
    conn = self._tls.connection
AttributeError: 'ForkAwareLocal' object has no attribute 'connection'

During handling of the above exception, another exception occurred:

Traceback (most recent call last):
  File "/home/conda/envs/topology/lib/python3.10/multiprocessing/process.py", line 314, in _bootstrap
    self.run()
  File "/home/conda/envs/topology/lib/python3.10/multiprocessing/process.py", line 108, in run
    self._target(*self._args, **self._kwargs)
  File "/home/jnoltmann/topology/src/E2.py", line 136, in get_c_lmlpmp_per_process
    return_dict[process_i] = E2_E3_E4_E5_get_c_lmlpmp(
  File "<string>", line 2, in __setitem__
  File "/home/conda/envs/topology/lib/python3.10/multiprocessing/managers.py", line 814, in _callmethod
    self._connect()
  File "/home/conda/envs/topology/lib/python3.10/multiprocessing/managers.py", line 801, in _connect
    conn = self._Client(self._token.address, authkey=self._authkey)
  File "/home/conda/envs/topology/lib/python3.10/multiprocessing/connection.py", line 502, in Client
    c = SocketClient(address)
  File "/home/conda/envs/topology/lib/python3.10/multiprocessing/connection.py", line 630, in SocketClient
    s.connect(address)
ConnectionRefusedError: [Errno 111] Connection refused
Process Process-1115:
Traceback (most recent call last):
  File "/home/conda/envs/topology/lib/python3.10/multiprocessing/managers.py", line 810, in _callmethod
    conn = self._tls.connection
AttributeError: 'ForkAwareLocal' object has no attribute 'connection'

During handling of the above exception, another exception occurred:

Traceback (most recent call last):
  File "/home/conda/envs/topology/lib/python3.10/multiprocessing/process.py", line 314, in _bootstrap
    self.run()
  File "/home/conda/envs/topology/lib/python3.10/multiprocessing/process.py", line 108, in run
    self._target(*self._args, **self._kwargs)
  File "/home/jnoltmann/topology/src/E2.py", line 136, in get_c_lmlpmp_per_process
    return_dict[process_i] = E2_E3_E4_E5_get_c_lmlpmp(
  File "<string>", line 2, in __setitem__
  File "/home/conda/envs/topology/lib/python3.10/multiprocessing/managers.py", line 814, in _callmethod
    self._connect()
  File "/home/conda/envs/topology/lib/python3.10/multiprocessing/managers.py", line 801, in _connect
    conn = self._Client(self._token.address, authkey=self._authkey)
  File "/home/conda/envs/topology/lib/python3.10/multiprocessing/connection.py", line 502, in Client
    c = SocketClient(address)
  File "/home/conda/envs/topology/lib/python3.10/multiprocessing/connection.py", line 630, in SocketClient
    s.connect(address)
ConnectionRefusedError: [Errno 111] Connection refused
Process Process-1122:
Traceback (most recent call last):
  File "/home/conda/envs/topology/lib/python3.10/multiprocessing/managers.py", line 810, in _callmethod
    conn = self._tls.connection
AttributeError: 'ForkAwareLocal' object has no attribute 'connection'

During handling of the above exception, another exception occurred:

Traceback (most recent call last):
  File "/home/conda/envs/topology/lib/python3.10/multiprocessing/process.py", line 314, in _bootstrap
    self.run()
  File "/home/conda/envs/topology/lib/python3.10/multiprocessing/process.py", line 108, in run
    self._target(*self._args, **self._kwargs)
  File "/home/jnoltmann/topology/src/E2.py", line 136, in get_c_lmlpmp_per_process
    return_dict[process_i] = E2_E3_E4_E5_get_c_lmlpmp(
  File "<string>", line 2, in __setitem__
  File "/home/conda/envs/topology/lib/python3.10/multiprocessing/managers.py", line 814, in _callmethod
    self._connect()
  File "/home/conda/envs/topology/lib/python3.10/multiprocessing/managers.py", line 801, in _connect
    conn = self._Client(self._token.address, authkey=self._authkey)
  File "/home/conda/envs/topology/lib/python3.10/multiprocessing/connection.py", line 502, in Client
    c = SocketClient(address)
  File "/home/conda/envs/topology/lib/python3.10/multiprocessing/connection.py", line 630, in SocketClient
    s.connect(address)
ConnectionRefusedError: [Errno 111] Connection refused
Process Process-1127:
Traceback (most recent call last):
  File "/home/conda/envs/topology/lib/python3.10/multiprocessing/managers.py", line 810, in _callmethod
    conn = self._tls.connection
AttributeError: 'ForkAwareLocal' object has no attribute 'connection'

During handling of the above exception, another exception occurred:

Traceback (most recent call last):
  File "/home/conda/envs/topology/lib/python3.10/multiprocessing/process.py", line 314, in _bootstrap
    self.run()
  File "/home/conda/envs/topology/lib/python3.10/multiprocessing/process.py", line 108, in run
    self._target(*self._args, **self._kwargs)
  File "/home/jnoltmann/topology/src/E2.py", line 136, in get_c_lmlpmp_per_process
    return_dict[process_i] = E2_E3_E4_E5_get_c_lmlpmp(
  File "<string>", line 2, in __setitem__
  File "/home/conda/envs/topology/lib/python3.10/multiprocessing/managers.py", line 814, in _callmethod
    self._connect()
  File "/home/conda/envs/topology/lib/python3.10/multiprocessing/managers.py", line 801, in _connect
    conn = self._Client(self._token.address, authkey=self._authkey)
  File "/home/conda/envs/topology/lib/python3.10/multiprocessing/connection.py", line 502, in Client
    c = SocketClient(address)
  File "/home/conda/envs/topology/lib/python3.10/multiprocessing/connection.py", line 630, in SocketClient
    s.connect(address)
ConnectionRefusedError: [Errno 111] Connection refused
Process Process-1120:
Traceback (most recent call last):
  File "/home/conda/envs/topology/lib/python3.10/multiprocessing/managers.py", line 810, in _callmethod
    conn = self._tls.connection
AttributeError: 'ForkAwareLocal' object has no attribute 'connection'

During handling of the above exception, another exception occurred:

Traceback (most recent call last):
  File "/home/conda/envs/topology/lib/python3.10/multiprocessing/process.py", line 314, in _bootstrap
    self.run()
  File "/home/conda/envs/topology/lib/python3.10/multiprocessing/process.py", line 108, in run
    self._target(*self._args, **self._kwargs)
  File "/home/jnoltmann/topology/src/E2.py", line 136, in get_c_lmlpmp_per_process
    return_dict[process_i] = E2_E3_E4_E5_get_c_lmlpmp(
  File "<string>", line 2, in __setitem__
  File "/home/conda/envs/topology/lib/python3.10/multiprocessing/managers.py", line 814, in _callmethod
    self._connect()
  File "/home/conda/envs/topology/lib/python3.10/multiprocessing/managers.py", line 801, in _connect
    conn = self._Client(self._token.address, authkey=self._authkey)
  File "/home/conda/envs/topology/lib/python3.10/multiprocessing/connection.py", line 502, in Client
    c = SocketClient(address)
  File "/home/conda/envs/topology/lib/python3.10/multiprocessing/connection.py", line 630, in SocketClient
    s.connect(address)
ConnectionRefusedError: [Errno 111] Connection refused
Process Process-1119:
Traceback (most recent call last):
  File "/home/conda/envs/topology/lib/python3.10/multiprocessing/managers.py", line 810, in _callmethod
    conn = self._tls.connection
AttributeError: 'ForkAwareLocal' object has no attribute 'connection'

During handling of the above exception, another exception occurred:

Traceback (most recent call last):
  File "/home/conda/envs/topology/lib/python3.10/multiprocessing/process.py", line 314, in _bootstrap
    self.run()
  File "/home/conda/envs/topology/lib/python3.10/multiprocessing/process.py", line 108, in run
    self._target(*self._args, **self._kwargs)
  File "/home/jnoltmann/topology/src/E2.py", line 136, in get_c_lmlpmp_per_process
    return_dict[process_i] = E2_E3_E4_E5_get_c_lmlpmp(
  File "<string>", line 2, in __setitem__
  File "/home/conda/envs/topology/lib/python3.10/multiprocessing/managers.py", line 814, in _callmethod
    self._connect()
  File "/home/conda/envs/topology/lib/python3.10/multiprocessing/managers.py", line 801, in _connect
    conn = self._Client(self._token.address, authkey=self._authkey)
  File "/home/conda/envs/topology/lib/python3.10/multiprocessing/connection.py", line 502, in Client
    c = SocketClient(address)
  File "/home/conda/envs/topology/lib/python3.10/multiprocessing/connection.py", line 630, in SocketClient
    s.connect(address)
ConnectionRefusedError: [Errno 111] Connection refused
Process Process-1063:
Traceback (most recent call last):
  File "/home/conda/envs/topology/lib/python3.10/multiprocessing/managers.py", line 810, in _callmethod
    conn = self._tls.connection
AttributeError: 'ForkAwareLocal' object has no attribute 'connection'

During handling of the above exception, another exception occurred:

Traceback (most recent call last):
  File "/home/conda/envs/topology/lib/python3.10/multiprocessing/process.py", line 314, in _bootstrap
    self.run()
  File "/home/conda/envs/topology/lib/python3.10/multiprocessing/process.py", line 108, in run
    self._target(*self._args, **self._kwargs)
  File "/home/jnoltmann/topology/src/E2.py", line 136, in get_c_lmlpmp_per_process
    return_dict[process_i] = E2_E3_E4_E5_get_c_lmlpmp(
  File "<string>", line 2, in __setitem__
  File "/home/conda/envs/topology/lib/python3.10/multiprocessing/managers.py", line 814, in _callmethod
    self._connect()
  File "/home/conda/envs/topology/lib/python3.10/multiprocessing/managers.py", line 801, in _connect
    conn = self._Client(self._token.address, authkey=self._authkey)
  File "/home/conda/envs/topology/lib/python3.10/multiprocessing/connection.py", line 502, in Client
    c = SocketClient(address)
  File "/home/conda/envs/topology/lib/python3.10/multiprocessing/connection.py", line 630, in SocketClient
    s.connect(address)
ConnectionRefusedError: [Errno 111] Connection refused
Process Process-1112:
Traceback (most recent call last):
  File "/home/conda/envs/topology/lib/python3.10/multiprocessing/managers.py", line 810, in _callmethod
    conn = self._tls.connection
AttributeError: 'ForkAwareLocal' object has no attribute 'connection'

During handling of the above exception, another exception occurred:

Traceback (most recent call last):
  File "/home/conda/envs/topology/lib/python3.10/multiprocessing/process.py", line 314, in _bootstrap
    self.run()
  File "/home/conda/envs/topology/lib/python3.10/multiprocessing/process.py", line 108, in run
    self._target(*self._args, **self._kwargs)
  File "/home/jnoltmann/topology/src/E2.py", line 136, in get_c_lmlpmp_per_process
    return_dict[process_i] = E2_E3_E4_E5_get_c_lmlpmp(
  File "<string>", line 2, in __setitem__
  File "/home/conda/envs/topology/lib/python3.10/multiprocessing/managers.py", line 814, in _callmethod
    self._connect()
  File "/home/conda/envs/topology/lib/python3.10/multiprocessing/managers.py", line 801, in _connect
    conn = self._Client(self._token.address, authkey=self._authkey)
  File "/home/conda/envs/topology/lib/python3.10/multiprocessing/connection.py", line 502, in Client
    c = SocketClient(address)
  File "/home/conda/envs/topology/lib/python3.10/multiprocessing/connection.py", line 630, in SocketClient
    s.connect(address)
ConnectionRefusedError: [Errno 111] Connection refused
Process Process-1090:
Traceback (most recent call last):
  File "/home/conda/envs/topology/lib/python3.10/multiprocessing/managers.py", line 810, in _callmethod
    conn = self._tls.connection
AttributeError: 'ForkAwareLocal' object has no attribute 'connection'

During handling of the above exception, another exception occurred:

Traceback (most recent call last):
  File "/home/conda/envs/topology/lib/python3.10/multiprocessing/process.py", line 314, in _bootstrap
    self.run()
  File "/home/conda/envs/topology/lib/python3.10/multiprocessing/process.py", line 108, in run
    self._target(*self._args, **self._kwargs)
  File "/home/jnoltmann/topology/src/E2.py", line 136, in get_c_lmlpmp_per_process
    return_dict[process_i] = E2_E3_E4_E5_get_c_lmlpmp(
  File "<string>", line 2, in __setitem__
  File "/home/conda/envs/topology/lib/python3.10/multiprocessing/managers.py", line 814, in _callmethod
    self._connect()
  File "/home/conda/envs/topology/lib/python3.10/multiprocessing/managers.py", line 801, in _connect
    conn = self._Client(self._token.address, authkey=self._authkey)
  File "/home/conda/envs/topology/lib/python3.10/multiprocessing/connection.py", line 502, in Client
    c = SocketClient(address)
  File "/home/conda/envs/topology/lib/python3.10/multiprocessing/connection.py", line 630, in SocketClient
    s.connect(address)
ConnectionRefusedError: [Errno 111] Connection refused
Process Process-1099:
Traceback (most recent call last):
  File "/home/conda/envs/topology/lib/python3.10/multiprocessing/managers.py", line 810, in _callmethod
    conn = self._tls.connection
AttributeError: 'ForkAwareLocal' object has no attribute 'connection'

During handling of the above exception, another exception occurred:

Traceback (most recent call last):
  File "/home/conda/envs/topology/lib/python3.10/multiprocessing/process.py", line 314, in _bootstrap
    self.run()
  File "/home/conda/envs/topology/lib/python3.10/multiprocessing/process.py", line 108, in run
    self._target(*self._args, **self._kwargs)
  File "/home/jnoltmann/topology/src/E2.py", line 136, in get_c_lmlpmp_per_process
    return_dict[process_i] = E2_E3_E4_E5_get_c_lmlpmp(
  File "<string>", line 2, in __setitem__
  File "/home/conda/envs/topology/lib/python3.10/multiprocessing/managers.py", line 814, in _callmethod
    self._connect()
  File "/home/conda/envs/topology/lib/python3.10/multiprocessing/managers.py", line 801, in _connect
    conn = self._Client(self._token.address, authkey=self._authkey)
  File "/home/conda/envs/topology/lib/python3.10/multiprocessing/connection.py", line 502, in Client
    c = SocketClient(address)
  File "/home/conda/envs/topology/lib/python3.10/multiprocessing/connection.py", line 630, in SocketClient
    s.connect(address)
ConnectionRefusedError: [Errno 111] Connection refused
Process Process-1078:
Traceback (most recent call last):
  File "/home/conda/envs/topology/lib/python3.10/multiprocessing/managers.py", line 810, in _callmethod
    conn = self._tls.connection
AttributeError: 'ForkAwareLocal' object has no attribute 'connection'

During handling of the above exception, another exception occurred:

Traceback (most recent call last):
  File "/home/conda/envs/topology/lib/python3.10/multiprocessing/process.py", line 314, in _bootstrap
    self.run()
  File "/home/conda/envs/topology/lib/python3.10/multiprocessing/process.py", line 108, in run
    self._target(*self._args, **self._kwargs)
  File "/home/jnoltmann/topology/src/E2.py", line 136, in get_c_lmlpmp_per_process
    return_dict[process_i] = E2_E3_E4_E5_get_c_lmlpmp(
  File "<string>", line 2, in __setitem__
  File "/home/conda/envs/topology/lib/python3.10/multiprocessing/managers.py", line 814, in _callmethod
    self._connect()
  File "/home/conda/envs/topology/lib/python3.10/multiprocessing/managers.py", line 801, in _connect
    conn = self._Client(self._token.address, authkey=self._authkey)
  File "/home/conda/envs/topology/lib/python3.10/multiprocessing/connection.py", line 502, in Client
    c = SocketClient(address)
  File "/home/conda/envs/topology/lib/python3.10/multiprocessing/connection.py", line 630, in SocketClient
    s.connect(address)
ConnectionRefusedError: [Errno 111] Connection refused
Process Process-1098:
Traceback (most recent call last):
  File "/home/conda/envs/topology/lib/python3.10/multiprocessing/managers.py", line 810, in _callmethod
    conn = self._tls.connection
AttributeError: 'ForkAwareLocal' object has no attribute 'connection'

During handling of the above exception, another exception occurred:

Traceback (most recent call last):
  File "/home/conda/envs/topology/lib/python3.10/multiprocessing/process.py", line 314, in _bootstrap
    self.run()
  File "/home/conda/envs/topology/lib/python3.10/multiprocessing/process.py", line 108, in run
    self._target(*self._args, **self._kwargs)
  File "/home/jnoltmann/topology/src/E2.py", line 136, in get_c_lmlpmp_per_process
    return_dict[process_i] = E2_E3_E4_E5_get_c_lmlpmp(
  File "<string>", line 2, in __setitem__
  File "/home/conda/envs/topology/lib/python3.10/multiprocessing/managers.py", line 814, in _callmethod
    self._connect()
  File "/home/conda/envs/topology/lib/python3.10/multiprocessing/managers.py", line 801, in _connect
    conn = self._Client(self._token.address, authkey=self._authkey)
  File "/home/conda/envs/topology/lib/python3.10/multiprocessing/connection.py", line 502, in Client
    c = SocketClient(address)
  File "/home/conda/envs/topology/lib/python3.10/multiprocessing/connection.py", line 630, in SocketClient
    s.connect(address)
ConnectionRefusedError: [Errno 111] Connection refused
Process Process-1107:
Traceback (most recent call last):
  File "/home/conda/envs/topology/lib/python3.10/multiprocessing/managers.py", line 810, in _callmethod
    conn = self._tls.connection
AttributeError: 'ForkAwareLocal' object has no attribute 'connection'

During handling of the above exception, another exception occurred:

Traceback (most recent call last):
  File "/home/conda/envs/topology/lib/python3.10/multiprocessing/process.py", line 314, in _bootstrap
    self.run()
  File "/home/conda/envs/topology/lib/python3.10/multiprocessing/process.py", line 108, in run
    self._target(*self._args, **self._kwargs)
  File "/home/jnoltmann/topology/src/E2.py", line 136, in get_c_lmlpmp_per_process
    return_dict[process_i] = E2_E3_E4_E5_get_c_lmlpmp(
  File "<string>", line 2, in __setitem__
  File "/home/conda/envs/topology/lib/python3.10/multiprocessing/managers.py", line 814, in _callmethod
    self._connect()
  File "/home/conda/envs/topology/lib/python3.10/multiprocessing/managers.py", line 801, in _connect
    conn = self._Client(self._token.address, authkey=self._authkey)
  File "/home/conda/envs/topology/lib/python3.10/multiprocessing/connection.py", line 502, in Client
    c = SocketClient(address)
  File "/home/conda/envs/topology/lib/python3.10/multiprocessing/connection.py", line 630, in SocketClient
    s.connect(address)
ConnectionRefusedError: [Errno 111] Connection refused
Process Process-1096:
Traceback (most recent call last):
  File "/home/conda/envs/topology/lib/python3.10/multiprocessing/managers.py", line 810, in _callmethod
    conn = self._tls.connection
AttributeError: 'ForkAwareLocal' object has no attribute 'connection'

During handling of the above exception, another exception occurred:

Traceback (most recent call last):
  File "/home/conda/envs/topology/lib/python3.10/multiprocessing/process.py", line 314, in _bootstrap
    self.run()
  File "/home/conda/envs/topology/lib/python3.10/multiprocessing/process.py", line 108, in run
    self._target(*self._args, **self._kwargs)
  File "/home/jnoltmann/topology/src/E2.py", line 136, in get_c_lmlpmp_per_process
    return_dict[process_i] = E2_E3_E4_E5_get_c_lmlpmp(
  File "<string>", line 2, in __setitem__
  File "/home/conda/envs/topology/lib/python3.10/multiprocessing/managers.py", line 814, in _callmethod
    self._connect()
  File "/home/conda/envs/topology/lib/python3.10/multiprocessing/managers.py", line 801, in _connect
    conn = self._Client(self._token.address, authkey=self._authkey)
  File "/home/conda/envs/topology/lib/python3.10/multiprocessing/connection.py", line 502, in Client
    c = SocketClient(address)
  File "/home/conda/envs/topology/lib/python3.10/multiprocessing/connection.py", line 630, in SocketClient
    s.connect(address)
ConnectionRefusedError: [Errno 111] Connection refused
Process Process-1076:
Traceback (most recent call last):
  File "/home/conda/envs/topology/lib/python3.10/multiprocessing/managers.py", line 810, in _callmethod
    conn = self._tls.connection
AttributeError: 'ForkAwareLocal' object has no attribute 'connection'

During handling of the above exception, another exception occurred:

Traceback (most recent call last):
  File "/home/conda/envs/topology/lib/python3.10/multiprocessing/process.py", line 314, in _bootstrap
    self.run()
  File "/home/conda/envs/topology/lib/python3.10/multiprocessing/process.py", line 108, in run
    self._target(*self._args, **self._kwargs)
  File "/home/jnoltmann/topology/src/E2.py", line 136, in get_c_lmlpmp_per_process
    return_dict[process_i] = E2_E3_E4_E5_get_c_lmlpmp(
  File "<string>", line 2, in __setitem__
  File "/home/conda/envs/topology/lib/python3.10/multiprocessing/managers.py", line 814, in _callmethod
    self._connect()
  File "/home/conda/envs/topology/lib/python3.10/multiprocessing/managers.py", line 801, in _connect
    conn = self._Client(self._token.address, authkey=self._authkey)
  File "/home/conda/envs/topology/lib/python3.10/multiprocessing/connection.py", line 502, in Client
    c = SocketClient(address)
  File "/home/conda/envs/topology/lib/python3.10/multiprocessing/connection.py", line 630, in SocketClient
    s.connect(address)
ConnectionRefusedError: [Errno 111] Connection refused
Process Process-1101:
Traceback (most recent call last):
  File "/home/conda/envs/topology/lib/python3.10/multiprocessing/managers.py", line 810, in _callmethod
    conn = self._tls.connection
AttributeError: 'ForkAwareLocal' object has no attribute 'connection'

During handling of the above exception, another exception occurred:

Traceback (most recent call last):
  File "/home/conda/envs/topology/lib/python3.10/multiprocessing/process.py", line 314, in _bootstrap
    self.run()
  File "/home/conda/envs/topology/lib/python3.10/multiprocessing/process.py", line 108, in run
    self._target(*self._args, **self._kwargs)
  File "/home/jnoltmann/topology/src/E2.py", line 136, in get_c_lmlpmp_per_process
    return_dict[process_i] = E2_E3_E4_E5_get_c_lmlpmp(
  File "<string>", line 2, in __setitem__
  File "/home/conda/envs/topology/lib/python3.10/multiprocessing/managers.py", line 814, in _callmethod
    self._connect()
  File "/home/conda/envs/topology/lib/python3.10/multiprocessing/managers.py", line 801, in _connect
    conn = self._Client(self._token.address, authkey=self._authkey)
  File "/home/conda/envs/topology/lib/python3.10/multiprocessing/connection.py", line 502, in Client
    c = SocketClient(address)
  File "/home/conda/envs/topology/lib/python3.10/multiprocessing/connection.py", line 630, in SocketClient
    s.connect(address)
ConnectionRefusedError: [Errno 111] Connection refused
Process Process-1092:
Traceback (most recent call last):
  File "/home/conda/envs/topology/lib/python3.10/multiprocessing/managers.py", line 810, in _callmethod
    conn = self._tls.connection
AttributeError: 'ForkAwareLocal' object has no attribute 'connection'

During handling of the above exception, another exception occurred:

Traceback (most recent call last):
  File "/home/conda/envs/topology/lib/python3.10/multiprocessing/process.py", line 314, in _bootstrap
    self.run()
  File "/home/conda/envs/topology/lib/python3.10/multiprocessing/process.py", line 108, in run
    self._target(*self._args, **self._kwargs)
  File "/home/jnoltmann/topology/src/E2.py", line 136, in get_c_lmlpmp_per_process
    return_dict[process_i] = E2_E3_E4_E5_get_c_lmlpmp(
  File "<string>", line 2, in __setitem__
  File "/home/conda/envs/topology/lib/python3.10/multiprocessing/managers.py", line 814, in _callmethod
    self._connect()
  File "/home/conda/envs/topology/lib/python3.10/multiprocessing/managers.py", line 801, in _connect
    conn = self._Client(self._token.address, authkey=self._authkey)
  File "/home/conda/envs/topology/lib/python3.10/multiprocessing/connection.py", line 502, in Client
    c = SocketClient(address)
  File "/home/conda/envs/topology/lib/python3.10/multiprocessing/connection.py", line 630, in SocketClient
    s.connect(address)
ConnectionRefusedError: [Errno 111] Connection refused
Process Process-1077:
Traceback (most recent call last):
  File "/home/conda/envs/topology/lib/python3.10/multiprocessing/managers.py", line 810, in _callmethod
    conn = self._tls.connection
AttributeError: 'ForkAwareLocal' object has no attribute 'connection'

During handling of the above exception, another exception occurred:

Traceback (most recent call last):
  File "/home/conda/envs/topology/lib/python3.10/multiprocessing/process.py", line 314, in _bootstrap
    self.run()
  File "/home/conda/envs/topology/lib/python3.10/multiprocessing/process.py", line 108, in run
    self._target(*self._args, **self._kwargs)
  File "/home/jnoltmann/topology/src/E2.py", line 136, in get_c_lmlpmp_per_process
    return_dict[process_i] = E2_E3_E4_E5_get_c_lmlpmp(
  File "<string>", line 2, in __setitem__
  File "/home/conda/envs/topology/lib/python3.10/multiprocessing/managers.py", line 814, in _callmethod
    self._connect()
  File "/home/conda/envs/topology/lib/python3.10/multiprocessing/managers.py", line 801, in _connect
    conn = self._Client(self._token.address, authkey=self._authkey)
  File "/home/conda/envs/topology/lib/python3.10/multiprocessing/connection.py", line 502, in Client
    c = SocketClient(address)
  File "/home/conda/envs/topology/lib/python3.10/multiprocessing/connection.py", line 630, in SocketClient
    s.connect(address)
ConnectionRefusedError: [Errno 111] Connection refused
Process Process-1069:
Traceback (most recent call last):
  File "/home/conda/envs/topology/lib/python3.10/multiprocessing/managers.py", line 810, in _callmethod
    conn = self._tls.connection
AttributeError: 'ForkAwareLocal' object has no attribute 'connection'

During handling of the above exception, another exception occurred:

Traceback (most recent call last):
  File "/home/conda/envs/topology/lib/python3.10/multiprocessing/process.py", line 314, in _bootstrap
    self.run()
  File "/home/conda/envs/topology/lib/python3.10/multiprocessing/process.py", line 108, in run
    self._target(*self._args, **self._kwargs)
  File "/home/jnoltmann/topology/src/E2.py", line 136, in get_c_lmlpmp_per_process
    return_dict[process_i] = E2_E3_E4_E5_get_c_lmlpmp(
  File "<string>", line 2, in __setitem__
  File "/home/conda/envs/topology/lib/python3.10/multiprocessing/managers.py", line 814, in _callmethod
    self._connect()
  File "/home/conda/envs/topology/lib/python3.10/multiprocessing/managers.py", line 801, in _connect
    conn = self._Client(self._token.address, authkey=self._authkey)
  File "/home/conda/envs/topology/lib/python3.10/multiprocessing/connection.py", line 502, in Client
    c = SocketClient(address)
  File "/home/conda/envs/topology/lib/python3.10/multiprocessing/connection.py", line 630, in SocketClient
    s.connect(address)
ConnectionRefusedError: [Errno 111] Connection refused
Process Process-1089:
Traceback (most recent call last):
  File "/home/conda/envs/topology/lib/python3.10/multiprocessing/managers.py", line 810, in _callmethod
    conn = self._tls.connection
AttributeError: 'ForkAwareLocal' object has no attribute 'connection'

During handling of the above exception, another exception occurred:

Traceback (most recent call last):
  File "/home/conda/envs/topology/lib/python3.10/multiprocessing/process.py", line 314, in _bootstrap
    self.run()
  File "/home/conda/envs/topology/lib/python3.10/multiprocessing/process.py", line 108, in run
    self._target(*self._args, **self._kwargs)
  File "/home/jnoltmann/topology/src/E2.py", line 136, in get_c_lmlpmp_per_process
    return_dict[process_i] = E2_E3_E4_E5_get_c_lmlpmp(
  File "<string>", line 2, in __setitem__
  File "/home/conda/envs/topology/lib/python3.10/multiprocessing/managers.py", line 814, in _callmethod
    self._connect()
  File "/home/conda/envs/topology/lib/python3.10/multiprocessing/managers.py", line 801, in _connect
    conn = self._Client(self._token.address, authkey=self._authkey)
  File "/home/conda/envs/topology/lib/python3.10/multiprocessing/connection.py", line 502, in Client
    c = SocketClient(address)
  File "/home/conda/envs/topology/lib/python3.10/multiprocessing/connection.py", line 630, in SocketClient
    s.connect(address)
ConnectionRefusedError: [Errno 111] Connection refused
Process Process-1111:
Traceback (most recent call last):
  File "/home/conda/envs/topology/lib/python3.10/multiprocessing/managers.py", line 810, in _callmethod
    conn = self._tls.connection
AttributeError: 'ForkAwareLocal' object has no attribute 'connection'

During handling of the above exception, another exception occurred:

Traceback (most recent call last):
  File "/home/conda/envs/topology/lib/python3.10/multiprocessing/process.py", line 314, in _bootstrap
    self.run()
  File "/home/conda/envs/topology/lib/python3.10/multiprocessing/process.py", line 108, in run
    self._target(*self._args, **self._kwargs)
  File "/home/jnoltmann/topology/src/E2.py", line 136, in get_c_lmlpmp_per_process
    return_dict[process_i] = E2_E3_E4_E5_get_c_lmlpmp(
  File "<string>", line 2, in __setitem__
  File "/home/conda/envs/topology/lib/python3.10/multiprocessing/managers.py", line 814, in _callmethod
    self._connect()
  File "/home/conda/envs/topology/lib/python3.10/multiprocessing/managers.py", line 801, in _connect
    conn = self._Client(self._token.address, authkey=self._authkey)
  File "/home/conda/envs/topology/lib/python3.10/multiprocessing/connection.py", line 502, in Client
    c = SocketClient(address)
  File "/home/conda/envs/topology/lib/python3.10/multiprocessing/connection.py", line 630, in SocketClient
    s.connect(address)
ConnectionRefusedError: [Errno 111] Connection refused
Process Process-1094:
Traceback (most recent call last):
  File "/home/conda/envs/topology/lib/python3.10/multiprocessing/managers.py", line 810, in _callmethod
    conn = self._tls.connection
AttributeError: 'ForkAwareLocal' object has no attribute 'connection'

During handling of the above exception, another exception occurred:

Traceback (most recent call last):
  File "/home/conda/envs/topology/lib/python3.10/multiprocessing/process.py", line 314, in _bootstrap
    self.run()
  File "/home/conda/envs/topology/lib/python3.10/multiprocessing/process.py", line 108, in run
    self._target(*self._args, **self._kwargs)
  File "/home/jnoltmann/topology/src/E2.py", line 136, in get_c_lmlpmp_per_process
    return_dict[process_i] = E2_E3_E4_E5_get_c_lmlpmp(
  File "<string>", line 2, in __setitem__
  File "/home/conda/envs/topology/lib/python3.10/multiprocessing/managers.py", line 814, in _callmethod
    self._connect()
  File "/home/conda/envs/topology/lib/python3.10/multiprocessing/managers.py", line 801, in _connect
    conn = self._Client(self._token.address, authkey=self._authkey)
  File "/home/conda/envs/topology/lib/python3.10/multiprocessing/connection.py", line 502, in Client
    c = SocketClient(address)
  File "/home/conda/envs/topology/lib/python3.10/multiprocessing/connection.py", line 630, in SocketClient
    s.connect(address)
ConnectionRefusedError: [Errno 111] Connection refused
Process Process-1068:
Traceback (most recent call last):
  File "/home/conda/envs/topology/lib/python3.10/multiprocessing/managers.py", line 810, in _callmethod
    conn = self._tls.connection
AttributeError: 'ForkAwareLocal' object has no attribute 'connection'

During handling of the above exception, another exception occurred:

Traceback (most recent call last):
  File "/home/conda/envs/topology/lib/python3.10/multiprocessing/process.py", line 314, in _bootstrap
    self.run()
  File "/home/conda/envs/topology/lib/python3.10/multiprocessing/process.py", line 108, in run
    self._target(*self._args, **self._kwargs)
  File "/home/jnoltmann/topology/src/E2.py", line 136, in get_c_lmlpmp_per_process
    return_dict[process_i] = E2_E3_E4_E5_get_c_lmlpmp(
  File "<string>", line 2, in __setitem__
  File "/home/conda/envs/topology/lib/python3.10/multiprocessing/managers.py", line 814, in _callmethod
    self._connect()
  File "/home/conda/envs/topology/lib/python3.10/multiprocessing/managers.py", line 801, in _connect
    conn = self._Client(self._token.address, authkey=self._authkey)
  File "/home/conda/envs/topology/lib/python3.10/multiprocessing/connection.py", line 502, in Client
    c = SocketClient(address)
  File "/home/conda/envs/topology/lib/python3.10/multiprocessing/connection.py", line 630, in SocketClient
    s.connect(address)
ConnectionRefusedError: [Errno 111] Connection refused
Process Process-1085:
Traceback (most recent call last):
  File "/home/conda/envs/topology/lib/python3.10/multiprocessing/managers.py", line 810, in _callmethod
    conn = self._tls.connection
AttributeError: 'ForkAwareLocal' object has no attribute 'connection'

During handling of the above exception, another exception occurred:

Traceback (most recent call last):
  File "/home/conda/envs/topology/lib/python3.10/multiprocessing/process.py", line 314, in _bootstrap
    self.run()
  File "/home/conda/envs/topology/lib/python3.10/multiprocessing/process.py", line 108, in run
    self._target(*self._args, **self._kwargs)
  File "/home/jnoltmann/topology/src/E2.py", line 136, in get_c_lmlpmp_per_process
    return_dict[process_i] = E2_E3_E4_E5_get_c_lmlpmp(
  File "<string>", line 2, in __setitem__
  File "/home/conda/envs/topology/lib/python3.10/multiprocessing/managers.py", line 814, in _callmethod
    self._connect()
  File "/home/conda/envs/topology/lib/python3.10/multiprocessing/managers.py", line 801, in _connect
    conn = self._Client(self._token.address, authkey=self._authkey)
  File "/home/conda/envs/topology/lib/python3.10/multiprocessing/connection.py", line 502, in Client
    c = SocketClient(address)
  File "/home/conda/envs/topology/lib/python3.10/multiprocessing/connection.py", line 630, in SocketClient
    s.connect(address)
ConnectionRefusedError: [Errno 111] Connection refused
Process Process-1087:
Traceback (most recent call last):
  File "/home/conda/envs/topology/lib/python3.10/multiprocessing/managers.py", line 810, in _callmethod
    conn = self._tls.connection
AttributeError: 'ForkAwareLocal' object has no attribute 'connection'

During handling of the above exception, another exception occurred:

Traceback (most recent call last):
  File "/home/conda/envs/topology/lib/python3.10/multiprocessing/process.py", line 314, in _bootstrap
    self.run()
  File "/home/conda/envs/topology/lib/python3.10/multiprocessing/process.py", line 108, in run
    self._target(*self._args, **self._kwargs)
  File "/home/jnoltmann/topology/src/E2.py", line 136, in get_c_lmlpmp_per_process
    return_dict[process_i] = E2_E3_E4_E5_get_c_lmlpmp(
  File "<string>", line 2, in __setitem__
  File "/home/conda/envs/topology/lib/python3.10/multiprocessing/managers.py", line 814, in _callmethod
    self._connect()
  File "/home/conda/envs/topology/lib/python3.10/multiprocessing/managers.py", line 801, in _connect
    conn = self._Client(self._token.address, authkey=self._authkey)
  File "/home/conda/envs/topology/lib/python3.10/multiprocessing/connection.py", line 502, in Client
    c = SocketClient(address)
  File "/home/conda/envs/topology/lib/python3.10/multiprocessing/connection.py", line 630, in SocketClient
    s.connect(address)
ConnectionRefusedError: [Errno 111] Connection refused
Process Process-1072:
Traceback (most recent call last):
  File "/home/conda/envs/topology/lib/python3.10/multiprocessing/managers.py", line 810, in _callmethod
    conn = self._tls.connection
AttributeError: 'ForkAwareLocal' object has no attribute 'connection'

During handling of the above exception, another exception occurred:

Traceback (most recent call last):
  File "/home/conda/envs/topology/lib/python3.10/multiprocessing/process.py", line 314, in _bootstrap
    self.run()
  File "/home/conda/envs/topology/lib/python3.10/multiprocessing/process.py", line 108, in run
    self._target(*self._args, **self._kwargs)
  File "/home/jnoltmann/topology/src/E2.py", line 136, in get_c_lmlpmp_per_process
    return_dict[process_i] = E2_E3_E4_E5_get_c_lmlpmp(
  File "<string>", line 2, in __setitem__
  File "/home/conda/envs/topology/lib/python3.10/multiprocessing/managers.py", line 814, in _callmethod
    self._connect()
  File "/home/conda/envs/topology/lib/python3.10/multiprocessing/managers.py", line 801, in _connect
    conn = self._Client(self._token.address, authkey=self._authkey)
  File "/home/conda/envs/topology/lib/python3.10/multiprocessing/connection.py", line 502, in Client
    c = SocketClient(address)
  File "/home/conda/envs/topology/lib/python3.10/multiprocessing/connection.py", line 630, in SocketClient
    s.connect(address)
ConnectionRefusedError: [Errno 111] Connection refused
Process Process-1088:
Traceback (most recent call last):
  File "/home/conda/envs/topology/lib/python3.10/multiprocessing/managers.py", line 810, in _callmethod
    conn = self._tls.connection
AttributeError: 'ForkAwareLocal' object has no attribute 'connection'

During handling of the above exception, another exception occurred:

Traceback (most recent call last):
  File "/home/conda/envs/topology/lib/python3.10/multiprocessing/process.py", line 314, in _bootstrap
    self.run()
  File "/home/conda/envs/topology/lib/python3.10/multiprocessing/process.py", line 108, in run
    self._target(*self._args, **self._kwargs)
  File "/home/jnoltmann/topology/src/E2.py", line 136, in get_c_lmlpmp_per_process
    return_dict[process_i] = E2_E3_E4_E5_get_c_lmlpmp(
  File "<string>", line 2, in __setitem__
  File "/home/conda/envs/topology/lib/python3.10/multiprocessing/managers.py", line 814, in _callmethod
    self._connect()
  File "/home/conda/envs/topology/lib/python3.10/multiprocessing/managers.py", line 801, in _connect
    conn = self._Client(self._token.address, authkey=self._authkey)
  File "/home/conda/envs/topology/lib/python3.10/multiprocessing/connection.py", line 502, in Client
    c = SocketClient(address)
  File "/home/conda/envs/topology/lib/python3.10/multiprocessing/connection.py", line 630, in SocketClient
    s.connect(address)
ConnectionRefusedError: [Errno 111] Connection refused
Process Process-1103:
Traceback (most recent call last):
  File "/home/conda/envs/topology/lib/python3.10/multiprocessing/managers.py", line 810, in _callmethod
    conn = self._tls.connection
AttributeError: 'ForkAwareLocal' object has no attribute 'connection'

During handling of the above exception, another exception occurred:

Traceback (most recent call last):
  File "/home/conda/envs/topology/lib/python3.10/multiprocessing/process.py", line 314, in _bootstrap
    self.run()
  File "/home/conda/envs/topology/lib/python3.10/multiprocessing/process.py", line 108, in run
    self._target(*self._args, **self._kwargs)
  File "/home/jnoltmann/topology/src/E2.py", line 136, in get_c_lmlpmp_per_process
    return_dict[process_i] = E2_E3_E4_E5_get_c_lmlpmp(
  File "<string>", line 2, in __setitem__
  File "/home/conda/envs/topology/lib/python3.10/multiprocessing/managers.py", line 814, in _callmethod
    self._connect()
  File "/home/conda/envs/topology/lib/python3.10/multiprocessing/managers.py", line 801, in _connect
    conn = self._Client(self._token.address, authkey=self._authkey)
  File "/home/conda/envs/topology/lib/python3.10/multiprocessing/connection.py", line 502, in Client
    c = SocketClient(address)
  File "/home/conda/envs/topology/lib/python3.10/multiprocessing/connection.py", line 630, in SocketClient
    s.connect(address)
ConnectionRefusedError: [Errno 111] Connection refused
Process Process-1067:
Traceback (most recent call last):
  File "/home/conda/envs/topology/lib/python3.10/multiprocessing/managers.py", line 810, in _callmethod
    conn = self._tls.connection
AttributeError: 'ForkAwareLocal' object has no attribute 'connection'

During handling of the above exception, another exception occurred:

Traceback (most recent call last):
  File "/home/conda/envs/topology/lib/python3.10/multiprocessing/process.py", line 314, in _bootstrap
    self.run()
  File "/home/conda/envs/topology/lib/python3.10/multiprocessing/process.py", line 108, in run
    self._target(*self._args, **self._kwargs)
  File "/home/jnoltmann/topology/src/E2.py", line 136, in get_c_lmlpmp_per_process
    return_dict[process_i] = E2_E3_E4_E5_get_c_lmlpmp(
  File "<string>", line 2, in __setitem__
  File "/home/conda/envs/topology/lib/python3.10/multiprocessing/managers.py", line 814, in _callmethod
    self._connect()
  File "/home/conda/envs/topology/lib/python3.10/multiprocessing/managers.py", line 801, in _connect
    conn = self._Client(self._token.address, authkey=self._authkey)
  File "/home/conda/envs/topology/lib/python3.10/multiprocessing/connection.py", line 502, in Client
    c = SocketClient(address)
  File "/home/conda/envs/topology/lib/python3.10/multiprocessing/connection.py", line 630, in SocketClient
    s.connect(address)
ConnectionRefusedError: [Errno 111] Connection refused
Process Process-1091:
Traceback (most recent call last):
  File "/home/conda/envs/topology/lib/python3.10/multiprocessing/managers.py", line 810, in _callmethod
    conn = self._tls.connection
AttributeError: 'ForkAwareLocal' object has no attribute 'connection'

During handling of the above exception, another exception occurred:

Traceback (most recent call last):
  File "/home/conda/envs/topology/lib/python3.10/multiprocessing/process.py", line 314, in _bootstrap
    self.run()
  File "/home/conda/envs/topology/lib/python3.10/multiprocessing/process.py", line 108, in run
    self._target(*self._args, **self._kwargs)
  File "/home/jnoltmann/topology/src/E2.py", line 136, in get_c_lmlpmp_per_process
    return_dict[process_i] = E2_E3_E4_E5_get_c_lmlpmp(
  File "<string>", line 2, in __setitem__
  File "/home/conda/envs/topology/lib/python3.10/multiprocessing/managers.py", line 814, in _callmethod
    self._connect()
  File "/home/conda/envs/topology/lib/python3.10/multiprocessing/managers.py", line 801, in _connect
    conn = self._Client(self._token.address, authkey=self._authkey)
  File "/home/conda/envs/topology/lib/python3.10/multiprocessing/connection.py", line 502, in Client
    c = SocketClient(address)
  File "/home/conda/envs/topology/lib/python3.10/multiprocessing/connection.py", line 630, in SocketClient
    s.connect(address)
ConnectionRefusedError: [Errno 111] Connection refused
Process Process-1084:
Traceback (most recent call last):
  File "/home/conda/envs/topology/lib/python3.10/multiprocessing/managers.py", line 810, in _callmethod
    conn = self._tls.connection
AttributeError: 'ForkAwareLocal' object has no attribute 'connection'

During handling of the above exception, another exception occurred:

Traceback (most recent call last):
  File "/home/conda/envs/topology/lib/python3.10/multiprocessing/process.py", line 314, in _bootstrap
    self.run()
  File "/home/conda/envs/topology/lib/python3.10/multiprocessing/process.py", line 108, in run
    self._target(*self._args, **self._kwargs)
  File "/home/jnoltmann/topology/src/E2.py", line 136, in get_c_lmlpmp_per_process
    return_dict[process_i] = E2_E3_E4_E5_get_c_lmlpmp(
  File "<string>", line 2, in __setitem__
  File "/home/conda/envs/topology/lib/python3.10/multiprocessing/managers.py", line 814, in _callmethod
    self._connect()
  File "/home/conda/envs/topology/lib/python3.10/multiprocessing/managers.py", line 801, in _connect
    conn = self._Client(self._token.address, authkey=self._authkey)
  File "/home/conda/envs/topology/lib/python3.10/multiprocessing/connection.py", line 502, in Client
    c = SocketClient(address)
  File "/home/conda/envs/topology/lib/python3.10/multiprocessing/connection.py", line 630, in SocketClient
    s.connect(address)
ConnectionRefusedError: [Errno 111] Connection refused
Process Process-1074:
Traceback (most recent call last):
  File "/home/conda/envs/topology/lib/python3.10/multiprocessing/managers.py", line 810, in _callmethod
    conn = self._tls.connection
AttributeError: 'ForkAwareLocal' object has no attribute 'connection'

During handling of the above exception, another exception occurred:

Traceback (most recent call last):
  File "/home/conda/envs/topology/lib/python3.10/multiprocessing/process.py", line 314, in _bootstrap
    self.run()
  File "/home/conda/envs/topology/lib/python3.10/multiprocessing/process.py", line 108, in run
    self._target(*self._args, **self._kwargs)
  File "/home/jnoltmann/topology/src/E2.py", line 136, in get_c_lmlpmp_per_process
    return_dict[process_i] = E2_E3_E4_E5_get_c_lmlpmp(
  File "<string>", line 2, in __setitem__
  File "/home/conda/envs/topology/lib/python3.10/multiprocessing/managers.py", line 814, in _callmethod
    self._connect()
  File "/home/conda/envs/topology/lib/python3.10/multiprocessing/managers.py", line 801, in _connect
    conn = self._Client(self._token.address, authkey=self._authkey)
  File "/home/conda/envs/topology/lib/python3.10/multiprocessing/connection.py", line 502, in Client
    c = SocketClient(address)
  File "/home/conda/envs/topology/lib/python3.10/multiprocessing/connection.py", line 630, in SocketClient
    s.connect(address)
ConnectionRefusedError: [Errno 111] Connection refused
Traceback (most recent call last):
  File "/home/conda/envs/topology/lib/python3.10/multiprocessing/managers.py", line 810, in _callmethod
    conn = self._tls.connection
AttributeError: 'ForkAwareLocal' object has no attribute 'connection'

During handling of the above exception, another exception occurred:

Traceback (most recent call last):
  File "/home/jnoltmann/topology/run_topology.py", line 56, in <module>
    cur_kl, _, _ = a.calculate_exact_kl_divergence()
  File "/home/jnoltmann/topology/src/topology.py", line 439, in calculate_exact_kl_divergence
    c_lmlpmp_ordered = self.calculate_c_lmlpmp(only_diag=False, normalize=False, plotting = False)
  File "/home/jnoltmann/topology/src/topology.py", line 280, in calculate_c_lmlpmp
    C_TT_lmlpmp = self.get_c_lmlpmp_multiprocessing(
  File "/home/jnoltmann/topology/src/topology.py", line 876, in get_c_lmlpmp_multiprocessing
    c_lmlpmp = sum(return_dict.values())
  File "<string>", line 2, in values
  File "/home/conda/envs/topology/lib/python3.10/multiprocessing/managers.py", line 814, in _callmethod
    self._connect()
  File "/home/conda/envs/topology/lib/python3.10/multiprocessing/managers.py", line 801, in _connect
    conn = self._Client(self._token.address, authkey=self._authkey)
  File "/home/conda/envs/topology/lib/python3.10/multiprocessing/connection.py", line 502, in Client
    c = SocketClient(address)
  File "/home/conda/envs/topology/lib/python3.10/multiprocessing/connection.py", line 630, in SocketClient
    s.connect(address)
ConnectionRefusedError: [Errno 111] Connection refused
slurmstepd: error: Detected 93 oom-kill event(s) in StepId=47725.batch cgroup. Some of your processes may have been killed by the cgroup out-of-memory handler.
